Workbook

Sheet 入居者
A1: 居室 | B1: 利用者名
A2: 2A | B2: 椎雅彦
A3: 2B | B3: 笠岡康志
A4: 2E
A5: 5B | B5: 中込和人
A6: 5C | B6: 上田清江
A7: 6A
A8: 6B | B8: 小山美由紀
A9: 6C | B9: 宮本浩行
A10: 6D | B10: 民徳正人
A11: 6E | B11: 岡村三男
A12: 6E

Sheet すまい請求書
A1: ええすまい請求書
A2: {=VLOOKUP(F$4,INDIRECT(M$2&"!A3:U109"),2,FALSE)} -> 小山美由紀 | E2: 様 | H2: 発行日： | J2: 46056 | L2: 当月 | M2: R8.1 | O2: 前月 | P2: R7.12
M3: 翌月 | N3: 2 | O3: 当月 | P3: 1 | Q3: 前月 | R3: 12
A4: ルネッサンス塚本（ええすまい） | F4: 6B | G4: 号室 | H4: 株式会社AA 代表取締役 大石佐智子
M5: ※分割払いの管理
A6: ご請求金額 | C6: =I33-I32 -> 62000 | H6: 大阪市西淀川区柏里2-9-3-102
A9: 内 容 | C9: 単 価 | E9: 数量 | G9: 小計 | I9: 備考
A10: {=INDIRECT(M$2&"!D2")} -> 家賃 | C10: {=VLOOKUP(F$4,INDIRECT(M$2&"!A3:U109"),4,FALSE)} -> 40000 | E10: 1か月 | G10: =C10 -> 40000 | I10: =N3 -> 2
A11: {=INDIRECT(M$2&"!E2")} -> 管理費 | C11: {=VLOOKUP(F$4,INDIRECT(M$2&"!A3:U109"),5,FALSE)} -> 5000 | E11: 1か月 | G11: =C11 -> 5000 | I11: =N3 -> 2
A12: {=INDIRECT(M$2&"!F2")} -> 共益費 | C12: {=VLOOKUP(F$4,INDIRECT(M$2&"!A3:U109"),6,FALSE)} -> 5000 | E12: 1か月 | G12: =C12 -> 5000 | I12: =N3 -> 2
A13: {=INDIRECT(M$2&"!G2")} -> 水道料金 | C13: {=VLOOKUP(F$4,INDIRECT(M$2&"!A3:U109"),7,FALSE)} -> 2000 | E13: 1か月 | G13: =C13 -> 2000 | I13: =N3 -> 2
A14: {=INDIRECT(M$2&"!H2")} -> 定額光熱費 | C14: {=VLOOKUP(F$4,INDIRECT(M$2&"!A3:U109"),8,FALSE)} -> 10000 | E14: 1か月 | G14: =C14 -> 10000 | I14: =N3 -> 2
A15: {=INDIRECT(M$2&"!I2")} -> 食事 | C15: {=VLOOKUP(F$4,INDIRECT(M$2&"!A3:U109"),9,FALSE)} | E15: 1か月 | G15: =C15 | I15: =P3 -> 1
A16: {=INDIRECT(M$2&"!J2")} -> 調整額 | C16: {=VLOOKUP(F$4,INDIRECT(M$2&"!A3:U109"),10,FALSE)} | E16: 1か月 | G16: =C16 | I16: =P3 -> 1
A17: {=INDIRECT(M$2&"!K2")} -> オムツ | C17: {=VLOOKUP(F$4,INDIRECT(M$2&"!A3:U109"),11,FALSE)} | E17: 1か月 | G17: =C17 | I17: =P3 -> 1
A18: {=INDIRECT(M$2&"!L2")} -> 日用品 | C18: {=VLOOKUP(F$4,INDIRECT(M$2&"!A3:U109"),12,FALSE)} | E18: 1か月 | G18: =C18 | I18: =P3 -> 1
A19: {=INDIRECT(M$2&"!M2")} -> 分割支払い | C19: {=VLOOKUP(F$4,INDIRECT(M$2&"!A3:U109"),13,FALSE)} | E19: 1か月 | G19: =C19 | I19: =P3 -> 1
A20: {=INDIRECT(M$2&"!N2")} -> 事務手数料 | C20: {=VLOOKUP(F$4,INDIRECT(M$2&"!A3:U109"),14,FALSE)} | E20: 1か月 | G20: =C20 | I20: =P3 -> 1
A21: {=INDIRECT(M$2&"!O2")} -> デイサービス | C21: {=VLOOKUP(F$4,INDIRECT(M$2&"!A3:U109"),15,FALSE)} | E21: 1か月 | G21: =C21 | I21: =R3 -> 12
A22: {=INDIRECT(M$2&"!P2")} -> 福祉用具 | C22: {=VLOOKUP(F$4,INDIRECT(M$2&"!A3:U109"),16,FALSE)} | E22: 1か月 | G22: =C22 | I22: =R3 -> 12
A23: {=INDIRECT(M$2&"!Q2")} -> しろくま薬局 | C23: {=VLOOKUP(F$4,INDIRECT(M$2&"!A3:U109"),17,FALSE)} | E23: 1か月 | G23: =C23 | I23: =R3 -> 12
A24: {=INDIRECT(M$2&"!R2")} -> 往診診療費 | C24: {=VLOOKUP(F$4,INDIRECT(M$2&"!A3:U109"),18,FALSE)} | E24: 1か月 | G24: =C24 | I24: =R3 -> 12
A25: {=INDIRECT(M$2&"!S2")} -> サポート費 | C25: {=VLOOKUP(F$4,INDIRECT(M$2&"!A3:U109"),19,FALSE)} | E25: 1か月 | G25: =C25 | I25: =R3 -> 12
A26: {=INDIRECT(M$2&"!T2")} -> その他 | C26: {=VLOOKUP(F$4,INDIRECT(M$2&"!A3:U109"),20,FALSE)} | E26: 1か月 | G26: =C26 | I26: =R3 -> 12
A27: {=INDIRECT(M$2&"!U2")} | C27: {=VLOOKUP(F$4,INDIRECT(M$2&"!A3:U109"),21,FALSE)} | E27: 1か月 | G27: =C27
A28: {=INDIRECT(M$2&"!V2")} | G28: =C28
A29: ご請求額合計 | G29: =SUM(G10:H28) -> 62000
A30: ※家賃、共益費、管理費、光熱費は消費税不要
A32: 8%対象 合計 | C32: 0 | G32: 未収・前払金 | I32: {=VLOOKUP(F$4,INDIRECT(P$2&"!A3:AE109"),31,FALSE)}
A33: 10％対象 合計 | C33: 0 | G33: 今月請求分合計額 | I33: =G29 -> 62000

Sheet 領収書（自動）
B1: 領 収 書
E3: 受領日
B4: ='すまい請求書'!A2 -> 小山美由紀 | D4: 様
C6: ='すまい請求書'!C6 -> 62000
B7: 但し 家賃、共益費、管理費、水道代、自費分として
C8: 上記の金額正に受領いたしました
C9: 株式会社AA
C10: 〒555-0022
C11: 大阪市西淀川区柏里2-9-3-102
C12: TEL・FAX 06-4400-2901

Sheet 領収書（手入力）
B1: 領 収 書
E3: 受領日 | G3: 45950
B4: 上田 清江 | D4: 様
C6: 200000
B7: 但し 家賃、共益費、管理費、水道代、自費分として
C8: 上記の金額正に受領いたしました
C9: 株式会社AA
C10: 〒555-0022
C11: 大阪市西淀川区柏里2-9-3-102
C12: TEL・FAX 06-4400-2901

Sheet 合算明細書
A1: ご利用金額のお知らせ
A2: {=VLOOKUP(F$4,INDIRECT(M$2&"!A3:U109"),2,FALSE)} -> 中込和人 | E2: 様 | F2: 発行日： | H2: 46055 | M2: R7.12
A4: ルネッサンス塚本（ええすまい） | F4: 5B | G4: 号室
B7: 合計金額 | D7: =SUM(C10:C12) -> 64313
A9: 内 容 | C9: 請求金額 | E9: お支払期限 | G9: 備考
A10: ええすまい | C10: {=VLOOKUP(F$4,INDIRECT(M$2&"!A3:Y109"),23,FALSE)} -> 64313 | E10: =H2+20 -> 46075 | G10: 請求書別紙
A11: ええかいご | C11: {=VLOOKUP(F$4,INDIRECT(M$2&"!A3:Y109"),24,FALSE)} | E11: =H2+20 -> 46075 | G11: 請求書別紙
A12: ええかんご | C12: {=VLOOKUP(F$4,INDIRECT(M$2&"!A3:Y109"),25,FALSE)} | E12: =H2+20 -> 46075 | G12: 請求書別紙
A14: お支払につきましては下記口座へお願いいたします。
A15: 振込手数料につきましてはお客様ご負担にてお願い申し上げます。
A17: ■振込先
A18: 銀行名： | C18: 住信ＳＢＩネット銀行（金融機関コード0038）
A19: 支店名： | C19: 法人第一支店（支店コード106）
A20: 口座番号： | C20: 普通 2555848
A21: 口座名義： | C21: 株式会社AA ええすまい塚本
C22: カ）エーエー

Sheet R8.1
A1: 46053 | C1: 請求 | D1: D | E1: E | F1: F | G1: G | H1: H | I1: I | J1: J | K1: K | L1: L | M1: M | N1: N | O1: O | P1: P | Q1: Q | R1: R | S1: S | T1: T | U1: U | V1: V | W1: W | X1: X | Y1: Y | Z1: Z | AA1: AA | AB1: AB
A2: 居室 | B2: 利用者名 | C2: 分納残 | D2: 家賃 | E2: 管理費 | F2: 共益費 | G2: 水道料金 | H2: 定額光熱費 | I2: 食事 | J2: 調整額 | K2: オムツ | L2: 日用品 | M2: 分割支払い | N2: 事務手数料 | O2: デイサービス | P2: 福祉用具 | Q2: しろくま薬局 | R2: 往診診療費 | S2: サポート費 | T2: その他 | W2: 計 | X2: 一部負担(介護) | Y2: 一部負担(看護) | Z2: 合計 | AA2: 備考 | AB2: 請求書 | AC2: 分割残高 | AD2: 入金額 | AE2: 過不足
A3: 2A | B3: 椎雅彦 | C3: ='R7.11'!AC3 -> 0 | D3: 40000 | E3: 5000 | F3: 5000 | G3: 2000 | H3: 10000 | I3: 39380 | L3: 2263 | O3: 7350 | W3: =SUM(D3:V3) -> 110993 | Z3: =SUM(W3:Y3) -> 110993 | AA3: 生保予定 | AB3: 未作成 | AC3: =C3-M3 -> 0
A4: 2B | B4: 笠岡康志 | C4: ='R7.11'!AC4 -> 0 | D4: 40000 | E4: 5000 | F4: 5000 | G4: 2000 | H4: 10000 | W4: =SUM(D4:V4) -> 62000 | Z4: =SUM(W4:Y4) -> 62000 | AA4: 通常請求 | AB4: 未作成 | AC4: =C4-M4 -> 0
A5: 2E | C5: ='R7.11'!AC5 -> 72000 | W5: =SUM(D5:V5) -> 0 | Z5: =SUM(W5:Y5) -> 0 | AA5: 110000 | AB5: 未作成 | AC5: =C5-M5 -> 72000
A6: 5B | B6: 中込和人 | C6: ='R7.11'!AC6 -> 0 | D6: 40000 | E6: 5000 | F6: 5000 | G6: 2000 | H6: 10000 | L6: 2263 | Q6: 100 | W6: =SUM(D6:V6) -> 64363 | Z6: =SUM(W6:Y6) -> 64363 | AA6: 通常請求 | AB6: 未作成 | AC6: =C6-M6 -> 0
A7: 5C | B7: 上田清江 | C7: ='R7.11'!AC7 -> 20000 | D7: 40000 | E7: 5000 | F7: 5000 | G7: 2000 | H7: 10000 | I7: 41580 | J7: -46485 | L7: 2263 | M7: 10000 | O7: 8623 | Q7: 3336 | V7: ='R7.12'!AE7 -> -540000 | W7: =SUM(D7:U7)-V7 -> 621317 | X7: 26183 | Y7: 2500 | Z7: =SUM(W7:Y7) -> 650000 | AA7: 110000 | AB7: 未作成 | AC7: =C7-M7 -> 10000 | AE7: =AD7-Z7 -> -650000
A8: 6A | C8: ='R7.11'!AC8 -> 0 | W8: =SUM(D8:V8) -> 0 | Z8: =SUM(W8:Y8) -> 0 | AB8: 未作成 | AC8: =C8-M8 -> 0
A9: 6B | B9: 小山美由紀 | C9: ='R7.11'!AC9 -> 0 | D9: 40000 | E9: 5000 | F9: 5000 | G9: 2000 | H9: 10000 | W9: =SUM(D9:V9) -> 62000 | Z9: =SUM(W9:Y9) -> 62000 | AA9: 通常請求 | AB9: 未作成 | AC9: =C9-M9 -> 0
A10: 6C | B10: 宮本浩行 | C10: ='R7.11'!AC10 -> 0 | D10: 40000 | E10: 5000 | F10: 5000 | G10: 2000 | H10: 10000 | I10: 44330 | L10: 2263 | W10: =SUM(D10:V10) -> 108593 | Z10: =SUM(W10:Y10) -> 108593 | AA10: 通常請求 | AB10: 未作成 | AC10: =C10-M10 -> 0
A11: 6D | B11: 民徳正人 | C11: ='R7.11'!AC11 -> 0 | D11: 40000 | E11: 5000 | F11: 5000 | G11: 2000 | H11: 10000 | L11: 2263 | W11: =SUM(D11:V11) -> 64263 | Z11: =SUM(W11:Y11) -> 64263 | AB11: 未作成 | AC11: =C11-M11 -> 0
C12: ='R7.11'!AC12 -> 0 | W12: =SUM(D12:V12) -> 0 | Z12: =SUM(W12:Y12) -> 0 | AA12: 通常請求 | AB12: 未作成 | AC12: =C12-M12 -> 0
C13: ='R7.11'!AC13 -> 0 | W13: =SUM(D13:V13) -> 0 | Z13: =SUM(W13:Y13) -> 0 | AB13: 未作成 | AC13: =C13-M13 -> 0
C14: ='R7.11'!AC14 -> 0 | W14: =SUM(D14:V14) -> 0 | Z14: =SUM(W14:Y14) -> 0 | AC14: =C14-M14 -> 0
C15: ='R7.11'!AC15 -> 0 | W15: =SUM(D15:V15) -> 0 | Z15: =SUM(W15:Y15) -> 0 | AC15: =C15-M15 -> 0
C16: ='R7.9'!AC16 -> 0 | W16: =SUM(D16:V16) -> 0 | Z16: =SUM(W16:Y16) -> 0 | AC16: =C16-M16 -> 0
C17: ='R7.9'!AC17 -> 0 | W17: =SUM(D17:V17) -> 0 | Z17: =SUM(W17:Y17) -> 0 | AC17: =C17-M17 -> 0
C18: ='R7.9'!AC18 -> 0 | W18: =SUM(D18:V18) -> 0 | Z18: =SUM(W18:Y18) -> 0 | AC18: =C18-M18 -> 0
C19: ='R7.9'!AC19 -> 0 | W19: =SUM(D19:V19) -> 0 | Z19: =SUM(W19:Y19) -> 0 | AC19: =C19-M19 -> 0
C20: ='R7.9'!AC20 -> 0 | W20: =SUM(D20:V20) -> 0 | Z20: =SUM(W20:Y20) -> 0 | AC20: =C20-M20 -> 0
C21: ='R7.9'!AC21 -> 0 | W21: =SUM(D21:V21) -> 0 | Z21: =SUM(W21:Y21) -> 0 | AC21: =C21-M21 -> 0
C22: ='R7.9'!AC22 -> 0 | W22: =SUM(D22:V22) -> 0 | Z22: =SUM(W22:Y22) -> 0 | AC22: =C22-M22 -> 0
C23: ='R7.9'!AC23 -> 0 | W23: =SUM(D23:V23) -> 0 | Z23: =SUM(W23:Y23) -> 0 | AC23: =C23-M23 -> 0
C24: ='R7.9'!AC24 -> 0 | W24: =SUM(D24:V24) -> 0 | Z24: =SUM(W24:Y24) -> 0 | AC24: =C24-M24 -> 0
C25: ='R7.9'!AC25 -> 0 | W25: =SUM(D25:V25) -> 0 | Z25: =SUM(W25:Y25) -> 0 | AC25: =C25-M25 -> 0
C26: ='R7.9'!AC26 -> 0 | W26: =SUM(D26:V26) -> 0 | Z26: =SUM(W26:Y26) -> 0 | AC26: =C26-M26 -> 0
C27: ='R7.9'!AC27 -> 0 | W27: =SUM(D27:V27) -> 0 | Z27: =SUM(W27:Y27) -> 0 | AC27: =C27-M27 -> 0
... C109: ='R7.9'!AC109 -> 0 | W109: =SUM(D109:V109) -> 0 | Z109: =SUM(W109:Y109) -> 0 | AC109: =C109-M109 -> 0
A110: 合計 | C110: ='R7.9'!AC110 | D110: =SUM(D3:D109) -> 280000 | E110: =SUM(E3:E109) -> 35000 | F110: =SUM(F3:F109) -> 35000 | G110: =SUM(G3:G109) -> 14000 | H110: =SUM(H3:H109) -> 70000 | I110: =SUM(I3:I109) -> 125290 | J110: =SUM(J3:J109) -> -46485 | K110: =SUM(K3:K109) -> 0 | ... V110: =SUM(V3:V109) -> -540000 | W110: =SUM(D110:V110) -> 13529 | X110: =SUM(X3:X109) -> 26183 | Y110: =SUM(Y3:Y109) -> 2500 | Z110: =SUM(W110:Y110) -> 42212
AE111: ↑来月の過不足へ反映
C113: 数式修正 | V113: 数式修正

Sheet R7.12
A1: 46022 | C1: 請求 | D1: D | E1: E | F1: F | G1: G | H1: H | I1: I | J1: J | K1: K | L1: L | M1: M | N1: N | O1: O | P1: P | Q1: Q | R1: R | S1: S | T1: T | U1: U | V1: V | W1: W | X1: X | Y1: Y | Z1: Z | AA1: AA | AB1: AB
A2: 居室 | B2: 利用者名 | C2: 分納残 | D2: 家賃 | E2: 管理費 | F2: 共益費 | G2: 水道料金 | H2: 定額光熱費 | I2: 食事 | J2: 調整額 | K2: オムツ | L2: 日用品 | M2: 分割支払い | N2: 事務手数料 | O2: デイサービス | P2: 福祉用具 | Q2: しろくま薬局 | R2: 往診診療費 | S2: サポート費 | T2: その他 | W2: 計 | X2: 一部負担(介護) | Y2: 一部負担(看護) | Z2: 合計 | AA2: 備考 | AB2: 請求書 | AC2: 分割残高 | AD2: 入金額 | AE2: 過不足
A3: 2A | B3: 椎雅彦 | C3: ='R7.11'!AC3 -> 0 | D3: 40000 | E3: 5000 | F3: 5000 | G3: 2000 | H3: 10000 | I3: 39380 | L3: 2263 | O3: 5200 | W3: =SUM(D3:V3) -> 108843 | Z3: =SUM(W3:Y3) -> 108843 | AA3: 生保予定 | AB3: 未作成 | AC3: =C3-M3 -> 0
A4: 2B | B4: 笠岡康志 | C4: ='R7.11'!AC4 -> 0 | D4: 40000 | E4: 5000 | F4: 5000 | G4: 2000 | H4: 10000 | W4: =SUM(D4:V4) -> 62000 | Z4: =SUM(W4:Y4) -> 62000 | AA4: 通常請求 | AB4: 未作成 | AC4: =C4-M4 -> 0
A5: 2E | C5: ='R7.11'!AC5 -> 72000 | W5: =SUM(D5:V5) -> 0 | Z5: =SUM(W5:Y5) -> 0 | AA5: 110000 | AB5: 未作成 | AC5: =C5-M5 -> 72000
A6: 5B | B6: 中込和人 | C6: ='R7.11'!AC6 -> 0 | D6: 40000 | E6: 5000 | F6: 5000 | G6: 2000 | H6: 10000 | L6: 2263 | Q6: 50 | W6: =SUM(D6:V6) -> 64313 | Z6: =SUM(W6:Y6) -> 64313 | AA6: 通常請求 | AB6: 未作成 | AC6: =C6-M6 -> 0
A7: 5C | B7: 上田清江 | C7: ='R7.11'!AC7 -> 20000 | D7: 40000 | E7: 5000 | F7: 5000 | G7: 2000 | H7: 10000 | I7: 41580 | J7: -44275 | L7: 2263 | M7: 10000 | O7: 6899 | Q7: 2826 | V7: ='R7.11'!AE7 -> -430000 | W7: =SUM(D7:U7)-V7 -> 511293 | X7: 26207 | Y7: 2500 | Z7: =SUM(W7:Y7) -> 540000 | AA7: 110000 | AB7: 未作成 | AC7: =C7-M7 -> 10000 | AE7: =AD7-Z7 -> -540000
A8: 6A | C8: ='R7.11'!AC8 -> 0 | W8: =SUM(D8:V8) -> 0 | Z8: =SUM(W8:Y8) -> 0 | AB8: 未作成 | AC8: =C8-M8 -> 0
A9: 6B | B9: 小山美由紀 | C9: ='R7.11'!AC9 -> 0 | D9: 40000 | E9: 5000 | F9: 5000 | G9: 2000 | H9: 10000 | W9: =SUM(D9:V9) -> 62000 | Z9: =SUM(W9:Y9) -> 62000 | AA9: 通常請求 | AB9: 未作成 | AC9: =C9-M9 -> 0
A10: 6C | B10: 宮本浩行 | C10: ='R7.11'!AC10 -> 0 | D10: 40000 | E10: 5000 | F10: 5000 | G10: 2000 | H10: 10000 | I10: 44330 | L10: 2263 | W10: =SUM(D10:V10) -> 108593 | Z10: =SUM(W10:Y10) -> 108593 | AA10: 通常請求 | AB10: 未作成 | AC10: =C10-M10 -> 0
A11: 6D | B11: 民徳正人 | C11: ='R7.11'!AC11 -> 0 | D11: 40000 | E11: 5000 | F11: 5000 | G11: 2000 | H11: 10000 | L11: 2263 | W11: =SUM(D11:V11) -> 64263 | Z11: =SUM(W11:Y11) -> 64263 | AB11: 未作成 | AC11: =C11-M11 -> 0
C12: ='R7.11'!AC12 -> 0 | W12: =SUM(D12:V12) -> 0 | Z12: =SUM(W12:Y12) -> 0 | AA12: 通常請求 | AB12: 未作成 | AC12: =C12-M12 -> 0
C13: ='R7.11'!AC13 -> 0 | W13: =SUM(D13:V13) -> 0 | Z13: =SUM(W13:Y13) -> 0 | AB13: 未作成 | AC13: =C13-M13 -> 0
C14: ='R7.11'!AC14 -> 0 | W14: =SUM(D14:V14) -> 0 | Z14: =SUM(W14:Y14) -> 0 | AC14: =C14-M14 -> 0
C15: ='R7.11'!AC15 -> 0 | W15: =SUM(D15:V15) -> 0 | Z15: =SUM(W15:Y15) -> 0 | AC15: =C15-M15 -> 0
C16: ='R7.9'!AC16 -> 0 | W16: =SUM(D16:V16) -> 0 | Z16: =SUM(W16:Y16) -> 0 | AC16: =C16-M16 -> 0
C17: ='R7.9'!AC17 -> 0 | W17: =SUM(D17:V17) -> 0 | Z17: =SUM(W17:Y17) -> 0 | AC17: =C17-M17 -> 0
C18: ='R7.9'!AC18 -> 0 | W18: =SUM(D18:V18) -> 0 | Z18: =SUM(W18:Y18) -> 0 | AC18: =C18-M18 -> 0
C19: ='R7.9'!AC19 -> 0 | W19: =SUM(D19:V19) -> 0 | Z19: =SUM(W19:Y19) -> 0 | AC19: =C19-M19 -> 0
C20: ='R7.9'!AC20 -> 0 | W20: =SUM(D20:V20) -> 0 | Z20: =SUM(W20:Y20) -> 0 | AC20: =C20-M20 -> 0
C21: ='R7.9'!AC21 -> 0 | W21: =SUM(D21:V21) -> 0 | Z21: =SUM(W21:Y21) -> 0 | AC21: =C21-M21 -> 0
C22: ='R7.9'!AC22 -> 0 | W22: =SUM(D22:V22) -> 0 | Z22: =SUM(W22:Y22) -> 0 | AC22: =C22-M22 -> 0
C23: ='R7.9'!AC23 -> 0 | W23: =SUM(D23:V23) -> 0 | Z23: =SUM(W23:Y23) -> 0 | AC23: =C23-M23 -> 0
C24: ='R7.9'!AC24 -> 0 | W24: =SUM(D24:V24) -> 0 | Z24: =SUM(W24:Y24) -> 0 | AC24: =C24-M24 -> 0
C25: ='R7.9'!AC25 -> 0 | W25: =SUM(D25:V25) -> 0 | Z25: =SUM(W25:Y25) -> 0 | AC25: =C25-M25 -> 0
C26: ='R7.9'!AC26 -> 0 | W26: =SUM(D26:V26) -> 0 | Z26: =SUM(W26:Y26) -> 0 | AC26: =C26-M26 -> 0
C27: ='R7.9'!AC27 -> 0 | W27: =SUM(D27:V27) -> 0 | Z27: =SUM(W27:Y27) -> 0 | AC27: =C27-M27 -> 0
... C109: ='R7.9'!AC109 -> 0 | W109: =SUM(D109:V109) -> 0 | Z109: =SUM(W109:Y109) -> 0 | AC109: =C109-M109 -> 0
A110: 合計 | C110: ='R7.9'!AC110 | D110: =SUM(D3:D109) -> 280000 | E110: =SUM(E3:E109) -> 35000 | F110: =SUM(F3:F109) -> 35000 | G110: =SUM(G3:G109) -> 14000 | H110: =SUM(H3:H109) -> 70000 | I110: =SUM(I3:I109) -> 125290 | J110: =SUM(J3:J109) -> -44275 | K110: =SUM(K3:K109) -> 0 | ... V110: =SUM(V3:V109) -> -430000 | W110: =SUM(D110:V110) -> 121305 | X110: =SUM(X3:X109) -> 26207 | Y110: =SUM(Y3:Y109) -> 2500 | Z110: =SUM(W110:Y110) -> 150012
AE111: ↑来月の過不足へ反映
C113: 数式修正 | V113: 数式修正

Sheet R7.11
A1: 45991 | C1: 請求 | D1: D | E1: E | F1: F | G1: G | H1: H | I1: I | J1: J | K1: K | L1: L | M1: M | N1: N | O1: O | P1: P | Q1: Q | R1: R | S1: S | T1: T | U1: U | V1: V | W1: W | X1: X | Y1: Y | Z1: Z | AA1: AA | AB1: AB
A2: 居室 | B2: 利用者名 | C2: 分納残 | D2: 家賃 | E2: 管理費 | F2: 共益費 | G2: 水道料金 | H2: 定額光熱費 | I2: 食事 | J2: 調整額 | K2: オムツ | L2: 日用品 | M2: 分割支払い | N2: 事務手数料 | O2: デイサービス | P2: 福祉用具 | Q2: しろくま薬局 | R2: 往診診療費 | S2: サポート費 | T2: その他 | W2: 計 | X2: 一部負担(介護) | Y2: 一部負担(看護) | Z2: 合計 | AA2: 備考 | AB2: 請求書 | AC2: 分割残高 | AD2: 入金額 | AE2: 過不足
A3: 2A | B3: 椎雅彦 | C3: ='R7.9'!AC3 -> 0 | D3: 40000 | E3: 5000 | F3: 5000 | G3: 2000 | H3: 10000 | I3: 38500 | L3: 2190 | O3: 6050 | W3: =SUM(D3:V3) -> 108740 | X3: 0 | Z3: =SUM(W3:Y3) -> 108740 | AA3: 生保予定 | AB3: 未作成 | AC3: =C3-M3 -> 0
A4: 2B | B4: 笠岡康志 | C4: ='R7.9'!AC4 -> 0 | D4: 40000 | E4: 5000 | F4: 5000 | G4: 2000 | H4: 10000 | W4: =SUM(D4:V4) -> 62000 | X4: 0 | Z4: =SUM(W4:Y4) -> 62000 | AA4: 通常請求 | AB4: 未作成 | AC4: =C4-M4 -> 0
A5: 2E | B5: 藤本敏博 | C5: ='R7.10'!AC5 -> 82000 | D5: 40000 | E5: 5000 | F5: 5000 | G5: 2000 | H5: 10000 | I5: 38500 | J5: -33643 | L5: 2190 | M5: 10000 | Q5: 6477 | W5: =SUM(D5:V5) -> 85524 | X5: 19476 | Y5: 5000 | Z5: =SUM(W5:Y5) -> 110000 | AA5: 110000 | AB5: 未作成 | AC5: =C5-M5 -> 72000
A6: 5B | B6: 中込和人 | C6: ='R7.10'!AC6 -> 0 | D6: 40000 | E6: 5000 | F6: 5000 | G6: 2000 | H6: 10000 | L6: 2190 | Q6: 50 | W6: =SUM(D6:V6) -> 64240 | Z6: =SUM(W6:Y6) -> 64240 | AA6: 通常請求 | AB6: 未作成 | AC6: =C6-M6 -> 0
A7: 5C | B7: 上田清江 | C7: ='R7.10'!AC7 -> 30000 | D7: 40000 | E7: 5000 | F7: 5000 | G7: 2000 | H7: 10000 | I7: 40700 | J7: -46358 | L7: 2190 | M7: 10000 | O7: 8623 | Q7: 2996 | V7: ='R7.10'!AE7 -> -320000 | W7: =SUM(D7:U7)-V7 -> 400151 | X7: 27349 | Y7: 2500 | Z7: =SUM(W7:Y7) -> 430000 | AA7: 110000 | AB7: 未作成 | AC7: =C7-M7 -> 20000 | AE7: =AD7-Z7 -> -430000
A8: 6A | C8: ='R7.10'!AC8 -> 0 | W8: =SUM(D8:V8) -> 0 | Z8: =SUM(W8:Y8) -> 0 | AB8: 未作成 | AC8: =C8-M8 -> 0
A9: 6B | B9: 小山美由紀 | C9: ='R7.10'!AC9 -> 0 | D9: 40000 | E9: 5000 | F9: 5000 | G9: 2000 | H9: 10000 | W9: =SUM(D9:V9) -> 62000 | Z9: =SUM(W9:Y9) -> 62000 | AA9: 通常請求 | AB9: 未作成 | AC9: =C9-M9 -> 0
A10: 6C | B10: 宮本浩行 | C10: ='R7.10'!AC10 -> 0 | D10: 40000 | E10: 5000 | F10: 5000 | G10: 2000 | H10: 10000 | I10: 42900 | L10: 2190 | W10: =SUM(D10:V10) -> 107090 | Z10: =SUM(W10:Y10) -> 107090 | AA10: 通常請求 | AB10: 未作成 | AC10: =C10-M10 -> 0
A11: 6D | B11: 民徳正人 | C11: ='R7.10'!AC11 -> 0 | D11: 40000 | E11: 5000 | F11: 5000 | G11: 2000 | H11: 10000 | L11: 2190 | W11: =SUM(D11:V11) -> 64190 | Z11: =SUM(W11:Y11) -> 64190 | AB11: 未作成 | AC11: =C11-M11 -> 0
C12: ='R7.10'!AC12 -> 0 | W12: =SUM(D12:V12) -> 0 | Z12: =SUM(W12:Y12) -> 0 | AA12: 通常請求 | AB12: 未作成 | AC12: =C12-M12 -> 0
C13: ='R7.10'!AC13 -> 0 | W13: =SUM(D13:V13) -> 0 | Z13: =SUM(W13:Y13) -> 0 | AB13: 未作成 | AC13: =C13-M13 -> 0
C14: ='R7.9'!AC14 -> 0 | W14: =SUM(D14:V14) -> 0 | Z14: =SUM(W14:Y14) -> 0 | AC14: =C14-M14 -> 0
C15: ='R7.9'!AC15 -> 0 | W15: =SUM(D15:V15) -> 0 | Z15: =SUM(W15:Y15) -> 0 | AC15: =C15-M15 -> 0
C16: ='R7.9'!AC16 -> 0 | W16: =SUM(D16:V16) -> 0 | Z16: =SUM(W16:Y16) -> 0 | AC16: =C16-M16 -> 0
C17: ='R7.9'!AC17 -> 0 | W17: =SUM(D17:V17) -> 0 | Z17: =SUM(W17:Y17) -> 0 | AC17: =C17-M17 -> 0
C18: ='R7.9'!AC18 -> 0 | W18: =SUM(D18:V18) -> 0 | Z18: =SUM(W18:Y18) -> 0 | AC18: =C18-M18 -> 0
C19: ='R7.9'!AC19 -> 0 | W19: =SUM(D19:V19) -> 0 | Z19: =SUM(W19:Y19) -> 0 | AC19: =C19-M19 -> 0
C20: ='R7.9'!AC20 -> 0 | W20: =SUM(D20:V20) -> 0 | Z20: =SUM(W20:Y20) -> 0 | AC20: =C20-M20 -> 0
C21: ='R7.9'!AC21 -> 0 | W21: =SUM(D21:V21) -> 0 | Z21: =SUM(W21:Y21) -> 0 | AC21: =C21-M21 -> 0
C22: ='R7.9'!AC22 -> 0 | W22: =SUM(D22:V22) -> 0 | Z22: =SUM(W22:Y22) -> 0 | AC22: =C22-M22 -> 0
C23: ='R7.9'!AC23 -> 0 | W23: =SUM(D23:V23) -> 0 | Z23: =SUM(W23:Y23) -> 0 | AC23: =C23-M23 -> 0
C24: ='R7.9'!AC24 -> 0 | W24: =SUM(D24:V24) -> 0 | Z24: =SUM(W24:Y24) -> 0 | AC24: =C24-M24 -> 0
C25: ='R7.9'!AC25 -> 0 | W25: =SUM(D25:V25) -> 0 | Z25: =SUM(W25:Y25) -> 0 | AC25: =C25-M25 -> 0
... C109: ='R7.9'!AC109 -> 0 | W109: =SUM(D109:V109) -> 0 | Z109: =SUM(W109:Y109) -> 0 | AC109: =C109-M109 -> 0
A110: 合計 | C110: ='R7.9'!AC110 | D110: =SUM(D3:D109) -> 320000 | E110: =SUM(E3:E109) -> 40000 | F110: =SUM(F3:F109) -> 40000 | G110: =SUM(G3:G109) -> 16000 | H110: =SUM(H3:H109) -> 80000 | I110: =SUM(I3:I109) -> 160600 | J110: =SUM(J3:J109) -> -80001 | K110: =SUM(K3:K109) -> 0 | ... V110: =SUM(V3:V109) -> -320000 | W110: =SUM(D110:V110) -> 313935 | X110: =SUM(X3:X109) -> 46825 | Y110: =SUM(Y3:Y109) -> 7500 | Z110: =SUM(W110:Y110) -> 368260
AE111: ↑来月の過不足へ反映
C113: 数式修正 | V113: 数式修正

Sheet R7.10
A1: 45961 | C1: 請求 | D1: D | E1: E | F1: F | G1: G | H1: H | I1: I | J1: J | K1: K | L1: L | M1: M | N1: N | O1: O | P1: P | Q1: Q | R1: R | S1: S | T1: T | U1: U | V1: V | W1: W | X1: X | Y1: Y | Z1: Z | AA1: AA | AB1: AB
A2: 居室 | B2: 利用者名 | C2: 分納残 | D2: 家賃 | E2: 管理費 | F2: 共益費 | G2: 水道料金 | H2: 定額光熱費 | I2: 食事 | J2: 調整額 | K2: オムツ | L2: 日用品 | M2: 分割支払い | N2: 事務手数料 | O2: デイサービス | P2: 福祉用具 | Q2: しろくま薬局 | R2: 往診診療費 | S2: サポート費 | T2: その他 | W2: 計 | X2: 一部負担(介護) | Y2: 一部負担(看護) | Z2: 合計 | AA2: 備考 | AB2: 請求書 | AC2: 分割残高 | AD2: 入金額 | AE2: 過不足
A3: 2A | B3: 椎雅彦 | C3: ='R7.9'!AC3 -> 0 | D3: 40000 | E3: 5000 | F3: 5000 | G3: 2000 | H3: 10000 | I3: 39380 | J3: -19531 | K3: 0 | L3: 2263 | O3: 650 | W3: =SUM(D3:V3) -> 84762 | X3: 19531 | Z3: =SUM(W3:Y3) -> 104293 | AA3: 生保予定 | AB3: 未作成 | AC3: =C3-M3 -> 0
A4: 2B | B4: 笠岡康志 | C4: ='R7.9'!AC4 -> 0 | D4: 40000 | E4: 5000 | F4: 5000 | G4: 2000 | H4: 10000 | I4: 17050 | J4: 0 | K4: 0 | L4: 0 | W4: =SUM(D4:V4) -> 79050 | Z4: =SUM(W4:Y4) -> 79050 | AA4: 通常請求 | AB4: 未作成 | AC4: =C4-M4 -> 0
A5: 2E | B5: 藤本敏博 | C5: ='R7.9'!AC5 -> 92000 | D5: 40000 | E5: 5000 | F5: 5000 | G5: 2000 | H5: 10000 | I5: 19030 | J5: -16264 | K5: 0 | L5: 2263 | M5: 10000 | Q5: 6386 | W5: =SUM(D5:V5) -> 83415 | X5: 21585 | Y5: 5000 | Z5: =SUM(W5:Y5) -> 110000 | AA5: 110000 | AB5: 未作成 | AC5: =C5-M5 -> 82000
A6: 5B | B6: 中込和人 | C6: ='R7.9'!AC6 -> 0 | D6: 40000 | E6: 5000 | F6: 5000 | G6: 2000 | H6: 10000 | I6: 0 | J6: 0 | K6: 0 | L6: 2263 | Q6: 50 | W6: =SUM(D6:V6) -> 64313 | Z6: =SUM(W6:Y6) -> 64313 | AA6: 通常請求 | AB6: 未作成 | AC6: =C6-M6 -> 0
A7: 5C | B7: 上田清江 | C7: ='R7.9'!AC7 -> 40000 | D7: 40000 | E7: 5000 | F7: 5000 | G7: 2000 | H7: 10000 | I7: 41580 | J7: -43771 | K7: 0 | L7: 2263 | M7: 10000 | O7: 6899 | Q7: 2796 | V7: ='R7.9'!AE7 -> -210000 | W7: =SUM(D7:U7)-V7 -> 291767 | X7: 25733 | Y7: 2500 | Z7: =SUM(W7:Y7) -> 320000 | AA7: 110000 | AB7: 未作成 | AC7: =C7-M7 -> 30000 | AE7: =AD7-Z7 -> -320000
A8: 6A | C8: ='R7.9'!AC8 -> 0 | W8: =SUM(D8:V8) -> 0 | Z8: =SUM(W8:Y8) -> 0 | AB8: 未作成 | AC8: =C8-M8 -> 0
A9: 6B | B9: 小山美由紀 | C9: ='R7.9'!AC9 -> 0 | D9: 40000 | E9: 5000 | F9: 5000 | G9: 2000 | H9: 10000 | I9: 0 | J9: 0 | K9: 0 | L9: 0 | W9: =SUM(D9:V9) -> 62000 | Z9: =SUM(W9:Y9) -> 62000 | AA9: 通常請求 | AB9: 未作成 | AC9: =C9-M9 -> 0
A10: 6C | B10: 宮本浩行 | C10: ='R7.9'!AC10 -> 0 | D10: 40000 | E10: 5000 | F10: 5000 | G10: 2000 | H10: 10000 | I10: 44330 | J10: 0 | K10: 0 | L10: 2263 | W10: =SUM(D10:V10) -> 108593 | Z10: =SUM(W10:Y10) -> 108593 | AA10: 通常請求 | AB10: 未作成 | AC10: =C10-M10 -> 0
A11: 6D | B11: 民徳正人 | C11: ='R7.9'!AC11 -> 0 | D11: 40000 | E11: 5000 | F11: 5000 | G11: 2000 | H11: 10000 | I11: 660 | J11: 0 | K11: 0 | L11: 2263 | W11: =SUM(D11:V11) -> 64923 | Z11: =SUM(W11:Y11) -> 64923 | AB11: 未作成 | AC11: =C11-M11 -> 0
C12: ='R7.9'!AC12 -> 0 | W12: =SUM(D12:V12) -> 0 | Z12: =SUM(W12:Y12) -> 0 | AA12: 通常請求 | AB12: 未作成 | AC12: =C12-M12 -> 0
C13: ='R7.9'!AC13 -> 0 | W13: =SUM(D13:V13) -> 0 | Z13: =SUM(W13:Y13) -> 0 | AB13: 未作成 | AC13: =C13-M13 -> 0
C14: ='R7.9'!AC14 -> 0 | W14: =SUM(D14:V14) -> 0 | Z14: =SUM(W14:Y14) -> 0 | AC14: =C14-M14 -> 0
C15: ='R7.9'!AC15 -> 0 | W15: =SUM(D15:V15) -> 0 | Z15: =SUM(W15:Y15) -> 0 | AC15: =C15-M15 -> 0
C16: ='R7.9'!AC16 -> 0 | W16: =SUM(D16:V16) -> 0 | Z16: =SUM(W16:Y16) -> 0 | AC16: =C16-M16 -> 0
C17: ='R7.9'!AC17 -> 0 | W17: =SUM(D17:V17) -> 0 | Z17: =SUM(W17:Y17) -> 0 | AC17: =C17-M17 -> 0
C18: ='R7.9'!AC18 -> 0 | W18: =SUM(D18:V18) -> 0 | Z18: =SUM(W18:Y18) -> 0 | AC18: =C18-M18 -> 0
C19: ='R7.9'!AC19 -> 0 | W19: =SUM(D19:V19) -> 0 | Z19: =SUM(W19:Y19) -> 0 | AC19: =C19-M19 -> 0
C20: ='R7.9'!AC20 -> 0 | W20: =SUM(D20:V20) -> 0 | Z20: =SUM(W20:Y20) -> 0 | AC20: =C20-M20 -> 0
C21: ='R7.9'!AC21 -> 0 | W21: =SUM(D21:V21) -> 0 | Z21: =SUM(W21:Y21) -> 0 | AC21: =C21-M21 -> 0
C22: ='R7.9'!AC22 -> 0 | W22: =SUM(D22:V22) -> 0 | Z22: =SUM(W22:Y22) -> 0 | AC22: =C22-M22 -> 0
C23: ='R7.9'!AC23 -> 0 | W23: =SUM(D23:V23) -> 0 | Z23: =SUM(W23:Y23) -> 0 | AC23: =C23-M23 -> 0
C24: ='R7.9'!AC24 -> 0 | W24: =SUM(D24:V24) -> 0 | Z24: =SUM(W24:Y24) -> 0 | AC24: =C24-M24 -> 0
C25: ='R7.9'!AC25 -> 0 | W25: =SUM(D25:V25) -> 0 | Z25: =SUM(W25:Y25) -> 0 | AC25: =C25-M25 -> 0
... C109: ='R7.9'!AC109 -> 0 | W109: =SUM(D109:V109) -> 0 | Z109: =SUM(W109:Y109) -> 0 | AC109: =C109-M109 -> 0
A110: 合計 | C110: ='R7.9'!AC110 | D110: =SUM(D3:D109) -> 320000 | E110: =SUM(E3:E109) -> 40000 | F110: =SUM(F3:F109) -> 40000 | G110: =SUM(G3:G109) -> 16000 | H110: =SUM(H3:H109) -> 80000 | I110: =SUM(I3:I109) -> 162030 | J110: =SUM(J3:J109) -> -79566 | K110: =SUM(K3:K109) -> 0 | ... V110: =SUM(V3:V109) -> -210000 | W110: =SUM(D110:V110) -> 418823 | X110: =SUM(X3:X109) -> 66849 | Y110: =SUM(Y3:Y109) -> 7500 | Z110: =SUM(W110:Y110) -> 493172
AE111: ↑来月の過不足へ反映
C113: 数式修正 | V113: 数式修正

Sheet R7.9
A1: 45930 | C1: 請求 | D1: D | E1: E | F1: F | G1: G | H1: H | I1: I | J1: J | K1: K | L1: L | M1: M | N1: N | O1: O | P1: P | Q1: Q | R1: R | S1: S | T1: T | U1: U | V1: V | W1: W | X1: X | Y1: Y | Z1: Z | AA1: AA | AB1: AB
A2: 居室 | B2: 利用者名 | C2: 分納残 | D2: 家賃 | E2: 管理費 | F2: 共益費 | G2: 水道料金 | H2: 定額光熱費 | I2: 食事 | J2: 調整額 | K2: オムツ | L2: 日用品 | M2: 分割支払い | N2: 事務手数料 | O2: デイサービス | P2: 福祉用具 | Q2: しろくま薬局 | R2: 往診診療費 | S2: サポート費 | T2: その他 | W2: 計 | X2: 一部負担(介護) | Y2: 一部負担(看護) | Z2: 合計 | AA2: 備考 | AB2: 請求書 | AC2: 分割残高 | AD2: 入金額 | AE2: 過不足
A3: 2A | B3: 椎雅彦 | C3: ='R7.8'!AC3 -> 0 | D3: 40000 | E3: 5000 | F3: 5000 | G3: 2000 | H3: 10000 | I3: 41800 | K3: 0 | L3: 2190 | W3: =SUM(D3:V3) -> 105990 | Z3: =SUM(W3:Y3) -> 105990 | AB3: 未作成 | AC3: =C3-M3 -> 0
A4: 2B | B4: 笠岡康志 | C4: ='R7.8'!AC4 -> 0 | D4: 40000 | E4: 5000 | F4: 5000 | G4: 2000 | H4: 10000 | I4: 16500 | K4: 0 | L4: 0 | W4: =SUM(D4:V4) -> 78500 | Z4: =SUM(W4:Y4) -> 78500 | AA4: 通常請求 | AB4: 未作成 | AC4: =C4-M4 -> 0
A5: 2E | B5: 藤本敏博 | C5: ='R7.8'!AC5 -> 102000 | D5: 40000 | E5: 5000 | F5: 5000 | G5: 2000 | H5: 10000 | I5: 39050 | J5: -36289 | K5: 0 | L5: 2190 | M5: 10000 | Q5: 6456 | W5: =SUM(D5:V5) -> 83407 | X5: 21593 | Y5: 5000 | Z5: =SUM(W5:Y5) -> 110000 | AA5: 110000 | AB5: 未作成 | AC5: =C5-M5 -> 92000
A6: 5B | B6: 中込和人 | C6: ='R7.8'!AC6 -> 0 | D6: 40000 | E6: 5000 | F6: 5000 | G6: 2000 | H6: 10000 | I6: 0 | K6: 0 | L6: 2190 | W6: =SUM(D6:V6) -> 64190 | Z6: =SUM(W6:Y6) -> 64190 | AA6: 通常請求 | AB6: 未作成 | AC6: =C6-M6 -> 0
A7: 5C | B7: 上田清江 | C7: ='R7.8'!AC7 -> 50000 | D7: 40000 | E7: 5000 | F7: 5000 | G7: 2000 | H7: 10000 | I7: 40700 | J7: -50348 | K7: 0 | L7: 2190 | M7: 10000 | Q7: 15390 | V7: ='R7.8'!AE7 -> -100000 | W7: =SUM(D7:U7)-V7 -> 179932 | X7: 27568 | Y7: 2500 | Z7: =SUM(W7:Y7) -> 210000 | AA7: 110000 | AB7: 未作成 | AC7: =C7-M7 -> 40000 | AE7: =AD7-Z7 -> -210000
A8: 6A | C8: ='R7.8'!AC8 -> 0 | K8: 0 | W8: =SUM(D8:V8) -> 0 | Z8: =SUM(W8:Y8) -> 0 | AB8: 未作成 | AC8: =C8-M8 -> 0
A9: 6B | B9: 小山美由紀 | C9: ='R7.8'!AC9 -> 0 | D9: 40000 | E9: 5000 | F9: 5000 | G9: 2000 | H9: 10000 | I9: 3850 | K9: 0 | L9: 0 | W9: =SUM(D9:V9) -> 65850 | Z9: =SUM(W9:Y9) -> 65850 | AA9: 通常請求 | AB9: 未作成 | AC9: =C9-M9 -> 0
A10: 6C | B10: 宮本浩行 | C10: ='R7.8'!AC10 -> 0 | D10: 40000 | E10: 5000 | F10: 5000 | G10: 2000 | H10: 10000 | I10: 42900 | K10: 0 | L10: 2190 | W10: =SUM(D10:V10) -> 107090 | Z10: =SUM(W10:Y10) -> 107090 | AA10: 通常請求 | AB10: 未作成 | AC10: =C10-M10 -> 0
A11: 6D | B11: 民徳正人 | C11: ='R7.8'!AC11 -> 0 | D11: 40000 | E11: 5000 | F11: 5000 | G11: 2000 | H11: 10000 | I11: 9900 | K11: 0 | L11: 2190 | W11: =SUM(D11:V11) -> 74090 | Z11: =SUM(W11:Y11) -> 74090 | AB11: 未作成 | AC11: =C11-M11 -> 0
A12: 6E | B12: 岡村三男 | C12: ='R7.8'!AC12 -> 0 | N12: 0 | O12: 0 | T12: 0 | W12: =SUM(D12:V12) -> 0 | Z12: =SUM(W12:Y12) -> 0 | AA12: 通常請求 | AB12: 未作成 | AC12: =C12-M12 -> 0
C13: ='R7.8'!AC13 -> 0 | W13: =SUM(D13:V13) -> 0 | Z13: =SUM(W13:Y13) -> 0 | AB13: 未作成 | AC13: =C13-M13 -> 0
C14: ='R7.8'!AC14 -> 0 | W14: =SUM(D14:V14) -> 0 | Z14: =SUM(W14:Y14) -> 0 | AC14: =C14-M14 -> 0
C15: ='R7.8'!AC15 -> 0 | W15: =SUM(D15:V15) -> 0 | Z15: =SUM(W15:Y15) -> 0 | AC15: =C15-M15 -> 0
C16: ='R7.8'!AC16 -> 0 | W16: =SUM(D16:V16) -> 0 | Z16: =SUM(W16:Y16) -> 0 | AC16: =C16-M16 -> 0
C17: ='R7.8'!AC17 -> 0 | W17: =SUM(D17:V17) -> 0 | Z17: =SUM(W17:Y17) -> 0 | AC17: =C17-M17 -> 0
C18: ='R7.8'!AC18 -> 0 | W18: =SUM(D18:V18) -> 0 | Z18: =SUM(W18:Y18) -> 0 | AC18: =C18-M18 -> 0
C19: ='R7.8'!AC19 -> 0 | W19: =SUM(D19:V19) -> 0 | Z19: =SUM(W19:Y19) -> 0 | AC19: =C19-M19 -> 0
C20: ='R7.8'!AC20 -> 0 | W20: =SUM(D20:V20) -> 0 | Z20: =SUM(W20:Y20) -> 0 | AC20: =C20-M20 -> 0
C21: ='R7.8'!AC21 -> 0 | W21: =SUM(D21:V21) -> 0 | Z21: =SUM(W21:Y21) -> 0 | AC21: =C21-M21 -> 0
C22: ='R7.8'!AC22 -> 0 | W22: =SUM(D22:V22) -> 0 | Z22: =SUM(W22:Y22) -> 0 | AC22: =C22-M22 -> 0
C23: ='R7.8'!AC23 -> 0 | W23: =SUM(D23:V23) -> 0 | Z23: =SUM(W23:Y23) -> 0 | AC23: =C23-M23 -> 0
C24: ='R7.8'!AC24 -> 0 | W24: =SUM(D24:V24) -> 0 | Z24: =SUM(W24:Y24) -> 0 | AC24: =C24-M24 -> 0
C25: ='R7.8'!AC25 -> 0 | W25: =SUM(D25:V25) -> 0 | Z25: =SUM(W25:Y25) -> 0 | AC25: =C25-M25 -> 0
... C109: ='R7.8'!AC109 -> 0 | W109: =SUM(D109:V109) -> 0 | Z109: =SUM(W109:Y109) -> 0 | AC109: =C109-M109 -> 0
A110: 合計 | D110: =SUM(D3:D109) -> 320000 | E110: =SUM(E3:E109) -> 40000 | F110: =SUM(F3:F109) -> 40000 | G110: =SUM(G3:G109) -> 16000 | H110: =SUM(H3:H109) -> 80000 | I110: =SUM(I3:I109) -> 194700 | J110: =SUM(J3:J109) -> -86637 | K110: =SUM(K3:K109) -> 0 | ... V110: =SUM(V3:V109) -> -100000 | W110: =SUM(D110:V110) -> 559049 | X110: =SUM(X3:X109) -> 49161 | Y110: =SUM(Y3:Y109) -> 7500 | Z110: =SUM(W110:Y110) -> 615710
AE111: ↑来月の過不足へ反映

Sheet R7.8
A1: 45900 | C1: 請求 | D1: D | E1: E | F1: F | G1: G | H1: H | I1: I | J1: J | K1: K | L1: L | M1: M | N1: N | O1: O | P1: P | Q1: Q | R1: R | S1: S | T1: T | U1: U | V1: V | W1: W | X1: X | Y1: Y | Z1: Z | AA1: AA | AB1: AB
A2: 居室 | B2: 利用者名 | C2: 分納残 | D2: 家賃 | E2: 管理費 | F2: 共益費 | G2: 水道料金 | H2: 定額光熱費 | I2: 食事 | J2: 調整額 | K2: オムツ | L2: 日用品 | M2: 分割支払い | N2: 事務手数料 | O2: デイサービス | P2: 福祉用具 | Q2: しろくま薬局 | R2: 往診診療費 | S2: サポート費 | T2: その他 | W2: 計 | X2: 一部負担(介護) | Y2: 一部負担(看護) | Z2: 合計 | AA2: 備考 | AB2: 請求書 | AC2: 分割残高 | AD2: 入金額 | AE2: 過不足
A3: 2A | B3: 椎雅彦 | C3: ='R7.7'!AC3 -> 0 | D3: 40000 | E3: 5000 | F3: 5000 | G3: 2000 | H3: 10000 | I3: 44330 | K3: 0 | L3: =73*31 -> 2263 | M3: 0 | N3: 0 | O3: 0 | Q3: 0 | W3: =SUM(D3:V3) -> 108593 | Z3: =SUM(W3:Y3) -> 108593 | AB3: 未作成 | AC3: =C3-M3 -> 0
A4: 2B | B4: 笠岡康志 | C4: ='R7.7'!AC4 -> 0 | D4: 40000 | E4: 5000 | F4: 5000 | G4: 2000 | H4: 10000 | I4: 17050 | K4: 0 | L4: 0 | M4: 0 | N4: 0 | O4: 0 | Q4: 0 | T4: 0 | W4: =SUM(D4:V4) -> 79050 | Z4: =SUM(W4:Y4) -> 79050 | AA4: 通常請求 | AB4: 未作成 | AC4: =C4-M4 -> 0
A5: 2E | B5: 藤本敏博 | C5: ='R7.7'!AC5 -> 112000 | D5: 40000 | E5: 5000 | F5: 5000 | G5: 2000 | H5: 10000 | I5: 42130 | J5: -32753 | K5: 0 | L5: =73*31 -> 2263 | M5: 10000 | N5: 0 | O5: 0 | Q5: 8006 | T5: 0 | W5: =SUM(D5:V5) -> 91646 | X5: 18354 | Z5: =SUM(W5:Y5) -> 110000 | AA5: 110000 | AB5: 未作成 | AC5: =C5-M5 -> 102000
A6: 5B | B6: 中込和人 | C6: ='R7.7'!AC6 -> 0 | D6: 40000 | E6: 5000 | F6: 5000 | G6: 2000 | H6: 10000 | I6: 0 | K6: 0 | L6: =73*31 -> 2263 | M6: 0 | N6: 1500 | O6: 0 | Q6: 50 | T6: 0 | W6: =SUM(D6:V6) -> 65813 | Z6: =SUM(W6:Y6) -> 65813 | AA6: 通常請求 | AB6: 未作成 | AC6: =C6-M6 -> 0
A7: 5C | B7: 上田清江 | C7: ='R7.7'!AC7 -> 60000 | D7: 40000 | E7: 5000 | F7: 5000 | G7: 2000 | H7: 10000 | I7: 42130 | J7: -42448 | K7: 0 | L7: =73*31 -> 2263 | M7: 10000 | O7: 6899 | Q7: 0 | V7: ='R7.7'!AE7 -> 10000 | W7: =SUM(D7:U7)-V7 -> 70844 | X7: 26656 | Y7: 2500 | Z7: =SUM(W7:Y7) -> 100000 | AA7: 110000 | AB7: 未作成 | AC7: =C7-M7 -> 50000 | AE7: =AD7-Z7 -> -100000
A8: 6A | C8: ='R7.7'!AC8 -> 0 | K8: 0 | L8: 0 | O8: 0 | W8: =SUM(D8:V8) -> 0 | Z8: =SUM(W8:Y8) -> 0 | AB8: 未作成 | AC8: =C8-M8 -> 0
A9: 6B | B9: 小山美由紀 | C9: ='R7.7'!AC9 -> 0 | D9: 40000 | E9: 5000 | F9: 5000 | G9: 2000 | H9: 10000 | I9: 13750 | K9: 0 | L9: =73*25 -> 1825 | M9: 0 | N9: 0 | O9: 0 | Q9: 0 | T9: 0 | W9: =SUM(D9:V9) -> 77575 | Z9: =SUM(W9:Y9) -> 77575 | AA9: 通常請求 | AB9: 未作成 | AC9: =C9-M9 -> 0
A10: 6C | B10: 宮本浩行 | C10: ='R7.7'!AC10 -> 0 | D10: 40000 | E10: 5000 | F10: 5000 | G10: 2000 | H10: 10000 | I10: 44330 | K10: 0 | L10: =73*31 -> 2263 | M10: 0 | N10: 0 | O10: 0 | Q10: 0 | T10: 0 | W10: =SUM(D10:V10) -> 108593 | Z10: =SUM(W10:Y10) -> 108593 | AA10: 通常請求 | AB10: 未作成 | AC10: =C10-M10 -> 0
A11: 6D | B11: 民徳正人 | C11: ='R7.7'!AC11 -> 0 | D11: 40000 | E11: 5000 | F11: 5000 | G11: 2000 | H11: 10000 | I11: 25300 | K11: 0 | L11: =73*31 -> 2263 | M11: 0 | N11: 0 | O11: 0 | Q11: 0 | T11: 0 | W11: =SUM(D11:V11) -> 89563 | Z11: =SUM(W11:Y11) -> 89563 | AB11: 未作成 | AC11: =C11-M11 -> 0
A12: 6E | B12: 岡村三男 | C12: ='R7.7'!AC12 -> 0 | N12: 0 | O12: 0 | T12: 0 | W12: =SUM(D12:V12) -> 0 | Z12: =SUM(W12:Y12) -> 0 | AA12: 通常請求 | AB12: 未作成 | AC12: =C12-M12 -> 0
C13: ='R7.7'!AC13 -> 0 | W13: =SUM(D13:V13) -> 0 | Z13: =SUM(W13:Y13) -> 0 | AB13: 未作成 | AC13: =C13-M13 -> 0
C14: ='R7.7'!AC14 -> 0 | W14: =SUM(D14:V14) -> 0 | Z14: =SUM(W14:Y14) -> 0 | AC14: =C14-M14 -> 0
C15: ='R7.7'!AC15 -> 0 | W15: =SUM(D15:V15) -> 0 | Z15: =SUM(W15:Y15) -> 0 | AC15: =C15-M15 -> 0
C16: ='R7.7'!AC16 -> 0 | W16: =SUM(D16:V16) -> 0 | Z16: =SUM(W16:Y16) -> 0 | AC16: =C16-M16 -> 0
C17: ='R7.7'!AC17 -> 0 | W17: =SUM(D17:V17) -> 0 | Z17: =SUM(W17:Y17) -> 0 | AC17: =C17-M17 -> 0
C18: ='R7.7'!AC18 -> 0 | W18: =SUM(D18:V18) -> 0 | Z18: =SUM(W18:Y18) -> 0 | AC18: =C18-M18 -> 0
C19: ='R7.7'!AC19 -> 0 | W19: =SUM(D19:V19) -> 0 | Z19: =SUM(W19:Y19) -> 0 | AC19: =C19-M19 -> 0
C20: ='R7.7'!AC20 -> 0 | W20: =SUM(D20:V20) -> 0 | Z20: =SUM(W20:Y20) -> 0 | AC20: =C20-M20 -> 0
C21: ='R7.7'!AC21 -> 0 | W21: =SUM(D21:V21) -> 0 | Z21: =SUM(W21:Y21) -> 0 | AC21: =C21-M21 -> 0
C22: ='R7.7'!AC22 -> 0 | W22: =SUM(D22:V22) -> 0 | Z22: =SUM(W22:Y22) -> 0 | AC22: =C22-M22 -> 0
C23: ='R7.7'!AC23 -> 0 | W23: =SUM(D23:V23) -> 0 | Z23: =SUM(W23:Y23) -> 0 | AC23: =C23-M23 -> 0
C24: ='R7.7'!AC24 -> 0 | W24: =SUM(D24:V24) -> 0 | Z24: =SUM(W24:Y24) -> 0 | AC24: =C24-M24 -> 0
C25: ='R7.7'!AC25 -> 0 | W25: =SUM(D25:V25) -> 0 | Z25: =SUM(W25:Y25) -> 0 | AC25: =C25-M25 -> 0
... C109: ='R7.7'!AC109 -> 0 | W109: =SUM(D109:V109) -> 0 | Z109: =SUM(W109:Y109) -> 0 | AC109: =C109-M109 -> 0
A110: 合計 | D110: =SUM(D3:D109) -> 320000 | E110: =SUM(E3:E109) -> 40000 | F110: =SUM(F3:F109) -> 40000 | G110: =SUM(G3:G109) -> 16000 | H110: =SUM(H3:H109) -> 80000 | I110: =SUM(I3:I109) -> 229020 | J110: =SUM(J3:J109) -> -75201 | K110: =SUM(K3:K109) -> 0 | ... V110: =SUM(V3:V109) -> 10000 | W110: =SUM(D110:V110) -> 711677 | X110: =SUM(X3:X109) -> 45010 | Y110: =SUM(Y3:Y109) -> 2500 | Z110: =SUM(W110:Y110) -> 759187
AE111: ↑来月の過不足へ反映

Sheet R7.7
A1: 45869 | C1: 請求 | D1: D | E1: E | F1: F | G1: G | H1: H | I1: I | J1: J | K1: K | L1: L | M1: M | N1: N | O1: O | P1: P | Q1: Q | R1: R | S1: S | T1: T | U1: U | V1: V | W1: W | X1: X | Y1: Y | Z1: Z | AA1: AA | AB1: AB
A2: 居室 | B2: 利用者名 | C2: 分納残 | D2: 家賃 | E2: 管理費 | F2: 共益費 | G2: 水道料金 | H2: 定額光熱費 | I2: 食事 | J2: 調整額 | K2: オムツ | L2: 日用品 | M2: 分割支払い | N2: 事務手数料 | O2: デイサービス | P2: 福祉用具 | Q2: しろくま薬局 | R2: 往診診療費 | S2: サポート費 | T2: その他 | W2: 計 | X2: 一部負担(介護) | Y2: 一部負担(看護) | Z2: 合計 | AA2: 備考 | AB2: 請求書 | AC2: 分割残高 | AD2: 入金額 | AE2: 過不足
A3: 2A | C3: ='R7.6'!AC3 -> 0 | W3: =SUM(D3:V3) -> 0 | Z3: =SUM(W3:Y3) -> 0 | AB3: 未作成 | AC3: =C3-M3 -> 0
A4: 2B | C4: ='R7.6'!AC4 -> 0 | W4: =SUM(D4:V4) -> 0 | Z4: =SUM(W4:Y4) -> 0 | AA4: 通常請求 | AB4: 未作成 | AC4: =C4-M4 -> 0
A5: 2E | C5: ='R7.6'!AC5 -> 0 | W5: =SUM(D5:V5) -> 0 | Z5: =SUM(W5:Y5) -> 0 | AA5: 110000 | AB5: 未作成 | AC5: 112000
A6: 5B | C6: ='R7.6'!AC6 -> 0 | W6: =SUM(D6:V6) -> 0 | Z6: =SUM(W6:Y6) -> 0 | AA6: 通常請求 | AB6: 未作成 | AC6: =C6-M6 -> 0
A7: 5C | B7: 上田清江 | C7: ='R7.6'!AC7 -> 70000 | D7: 40000 | E7: 5000 | F7: 5000 | G7: 2000 | H7: 0 | I7: 21793 | M7: 10000 | V7: ='R7.6'!AE7 -> 120000 | W7: =SUM(D7:U7)-V7 -> -36207 | X7: 26207 | Z7: =SUM(W7:Y7) -> -10000 | AA7: 110000 | AB7: 未作成 | AC7: =C7-M7 -> 60000 | AE7: =AD7-Z7 -> 10000
A8: 6A | C8: ='R7.6'!AC8 -> 0 | W8: =SUM(D8:V8) -> 0 | Z8: =SUM(W8:Y8) -> 0 | AB8: 未作成 | AC8: =C8-M8 -> 0
A9: 6B | C9: ='R7.6'!AC9 -> 0 | W9: =SUM(D9:V9) -> 0 | Z9: =SUM(W9:Y9) -> 0 | AA9: 通常請求 | AB9: 未作成 | AC9: =C9-M9 -> 0
A10: 6C | C10: ='R7.6'!AC10 -> 0 | W10: =SUM(D10:V10) -> 0 | Z10: =SUM(W10:Y10) -> 0 | AA10: 通常請求 | AB10: 未作成 | AC10: =C10-M10 -> 0
A11: 6D | C11: ='R7.6'!AC11 -> 0 | W11: =SUM(D11:V11) -> 0 | Z11: =SUM(W11:Y11) -> 0 | AB11: 未作成 | AC11: =C11-M11 -> 0
A12: 6E | C12: ='R7.6'!AC12 -> 0 | W12: =SUM(D12:V12) -> 0 | Z12: =SUM(W12:Y12) -> 0 | AA12: 通常請求 | AB12: 未作成 | AC12: =C12-M12 -> 0
W13: =SUM(D13:V13) -> 0 | Z13: =SUM(W13:Y13) -> 0 | AB13: 未作成 | AC13: =C13-M13 -> 0
W14: =SUM(D14:V14) -> 0 | Z14: =SUM(W14:Y14) -> 0 | AC14: =C14-M14 -> 0
W15: =SUM(D15:V15) -> 0 | Z15: =SUM(W15:Y15) -> 0 | AC15: =C15-M15 -> 0
W16: =SUM(D16:V16) -> 0 | Z16: =SUM(W16:Y16) -> 0 | AC16: =C16-M16 -> 0
W17: =SUM(D17:V17) -> 0 | Z17: =SUM(W17:Y17) -> 0 | AC17: =C17-M17 -> 0
W18: =SUM(D18:V18) -> 0 | Z18: =SUM(W18:Y18) -> 0 | AC18: =C18-M18 -> 0
W19: =SUM(D19:V19) -> 0 | Z19: =SUM(W19:Y19) -> 0 | AC19: =C19-M19 -> 0
W20: =SUM(D20:V20) -> 0 | Z20: =SUM(W20:Y20) -> 0 | AC20: =C20-M20 -> 0
W21: =SUM(D21:V21) -> 0 | Z21: =SUM(W21:Y21) -> 0 | AC21: =C21-M21 -> 0
W22: =SUM(D22:V22) -> 0 | Z22: =SUM(W22:Y22) -> 0 | AC22: =C22-M22 -> 0
W23: =SUM(D23:V23) -> 0 | Z23: =SUM(W23:Y23) -> 0 | AC23: =C23-M23 -> 0
W24: =SUM(D24:V24) -> 0 | Z24: =SUM(W24:Y24) -> 0 | AC24: =C24-M24 -> 0
W25: =SUM(D25:V25) -> 0 | Z25: =SUM(W25:Y25) -> 0 | AC25: =C25-M25 -> 0
... W109: =SUM(D109:V109) -> 0 | Z109: =SUM(W109:Y109) -> 0 | AC109: =C109-M109 -> 0
A110: 合計 | D110: =SUM(D3:D109) -> 40000 | E110: =SUM(E3:E109) -> 5000 | F110: =SUM(F3:F109) -> 5000 | G110: =SUM(G3:G109) -> 2000 | H110: =SUM(H3:H109) -> 0 | I110: =SUM(I3:I109) -> 21793 | J110: =SUM(J3:J109) -> 0 | K110: =SUM(K3:K109) -> 0 | ... V110: =SUM(V3:V109) -> 120000 | W110: =SUM(D110:V110) -> 203793 | X110: =SUM(X3:X109) -> 26207 | Y110: =SUM(Y3:Y109) -> 0 | Z110: =SUM(W110:Y110) -> 230000
AE111: ↑来月の過不足へ反映

Sheet R7.6
A1: 45838 | C1: 請求 | D1: D | E1: E | F1: F | G1: G | H1: H | I1: I | J1: J | K1: K | L1: L | M1: M | N1: N | O1: O | P1: P | Q1: Q | R1: R | S1: S | T1: T | U1: U | V1: V | W1: W | X1: X | Y1: Y | Z1: Z | AA1: AA | AB1: AB
A2: 居室 | B2: 利用者名 | C2: 分納残 | D2: 家賃 | E2: 管理費 | F2: 共益費 | G2: 水道料金 | H2: 定額光熱費 | I2: 食事 | J2: 調整額 | K2: オムツ | L2: 日用品 | M2: 分割支払い | N2: 事務手数料 | O2: デイサービス | P2: 福祉用具 | Q2: しろくま薬局 | R2: 往診診療費 | S2: サポート費 | T2: その他 | W2: 計 | X2: 一部負担(介護) | Y2: 一部負担(看護) | Z2: 合計 | AA2: 備考 | AB2: 請求書 | AC2: 分割残高 | AD2: 入金額 | AE2: 過不足
A3: 2A | C3: ='R7.5'!AC3 -> 0 | W3: =SUM(D3:V3) -> 0 | Z3: =SUM(W3:Y3) -> 0 | AB3: 未作成 | AC3: =C3-M3 -> 0
A4: 2B | C4: ='R7.5'!AC4 -> 0 | W4: =SUM(D4:V4) -> 0 | Z4: =SUM(W4:Y4) -> 0 | AA4: 通常請求 | AB4: 未作成 | AC4: =C4-M4 -> 0
A5: 2E | C5: ='R7.5'!AC5 -> 0 | W5: =SUM(D5:V5) -> 0 | Z5: =SUM(W5:Y5) -> 0 | AA5: 110000 | AB5: 未作成 | AC5: =C5-M5 -> 0
A6: 5B | C6: ='R7.5'!AC6 -> 0 | W6: =SUM(D6:V6) -> 0 | Z6: =SUM(W6:Y6) -> 0 | AA6: 通常請求 | AB6: 未作成 | AC6: =C6-M6 -> 0
A7: 5C | B7: 上田清江 | C7: ='R7.5'!AC7 -> 80000 | D7: 40000 | E7: 5000 | F7: 5000 | G7: 2000 | H7: 0 | I7: 40700 | M7: 10000 | S7: 7300 | V7: ='R7.5'!AE7 -> 30000 | W7: =SUM(D7:U7)-V7 -> 80000 | Z7: =SUM(W7:Y7) -> 80000 | AA7: 110000 | AB7: 未作成 | AC7: =C7-M7 -> 70000 | AD7: 200000 | AE7: =AD7-Z7 -> 120000 | AF7: 45950
A8: 6A | C8: ='R7.5'!AC8 -> 0 | W8: =SUM(D8:V8) -> 0 | Z8: =SUM(W8:Y8) -> 0 | AB8: 未作成 | AC8: =C8-M8 -> 0
A9: 6B | C9: ='R7.5'!AC9 -> 0 | W9: =SUM(D9:V9) -> 0 | Z9: =SUM(W9:Y9) -> 0 | AA9: 通常請求 | AB9: 未作成 | AC9: =C9-M9 -> 0
A10: 6C | C10: ='R7.5'!AC10 -> 0 | W10: =SUM(D10:V10) -> 0 | Z10: =SUM(W10:Y10) -> 0 | AA10: 通常請求 | AB10: 未作成 | AC10: =C10-M10 -> 0
A11: 6D | C11: ='R7.5'!AC11 -> 0 | W11: =SUM(D11:V11) -> 0 | Z11: =SUM(W11:Y11) -> 0 | AB11: 未作成 | AC11: =C11-M11 -> 0
A12: 6E | C12: ='R7.5'!AC12 -> 0 | W12: =SUM(D12:V12) -> 0 | Z12: =SUM(W12:Y12) -> 0 | AA12: 通常請求 | AB12: 未作成 | AC12: =C12-M12 -> 0
W13: =SUM(D13:V13) -> 0 | Z13: =SUM(W13:Y13) -> 0 | AB13: 未作成 | AC13: =C13-M13 -> 0
W14: =SUM(D14:V14) -> 0 | Z14: =SUM(W14:Y14) -> 0 | AC14: =C14-M14 -> 0
W15: =SUM(D15:V15) -> 0 | Z15: =SUM(W15:Y15) -> 0 | AC15: =C15-M15 -> 0
W16: =SUM(D16:V16) -> 0 | Z16: =SUM(W16:Y16) -> 0 | AC16: =C16-M16 -> 0
W17: =SUM(D17:V17) -> 0 | Z17: =SUM(W17:Y17) -> 0 | AC17: =C17-M17 -> 0
W18: =SUM(D18:V18) -> 0 | Z18: =SUM(W18:Y18) -> 0 | AC18: =C18-M18 -> 0
W19: =SUM(D19:V19) -> 0 | Z19: =SUM(W19:Y19) -> 0 | AC19: =C19-M19 -> 0
W20: =SUM(D20:V20) -> 0 | Z20: =SUM(W20:Y20) -> 0 | AC20: =C20-M20 -> 0
W21: =SUM(D21:V21) -> 0 | Z21: =SUM(W21:Y21) -> 0 | AC21: =C21-M21 -> 0
W22: =SUM(D22:V22) -> 0 | Z22: =SUM(W22:Y22) -> 0 | AC22: =C22-M22 -> 0
W23: =SUM(D23:V23) -> 0 | Z23: =SUM(W23:Y23) -> 0 | AC23: =C23-M23 -> 0
W24: =SUM(D24:V24) -> 0 | Z24: =SUM(W24:Y24) -> 0 | AC24: =C24-M24 -> 0
W25: =SUM(D25:V25) -> 0 | Z25: =SUM(W25:Y25) -> 0 | AC25: =C25-M25 -> 0
... W109: =SUM(D109:V109) -> 0 | Z109: =SUM(W109:Y109) -> 0 | AC109: =C109-M109 -> 0
A110: 合計 | D110: =SUM(D3:D109) -> 40000 | E110: =SUM(E3:E109) -> 5000 | F110: =SUM(F3:F109) -> 5000 | G110: =SUM(G3:G109) -> 2000 | H110: =SUM(H3:H109) -> 0 | I110: =SUM(I3:I109) -> 40700 | J110: =SUM(J3:J109) -> 0 | K110: =SUM(K3:K109) -> 0 | ... V110: =SUM(V3:V109) -> 30000 | W110: =SUM(D110:V110) -> 140000 | X110: =SUM(X3:X109) -> 0 | Y110: =SUM(Y3:Y109) -> 0 | Z110: =SUM(W110:Y110) -> 140000
AE111: ↑来月の過不足へ反映

Sheet R7.5
A1: 45808 | C1: 請求 | D1: D | E1: E | F1: F | G1: G | H1: H | I1: I | J1: J | K1: K | L1: L | M1: M | N1: N | O1: O | P1: P | Q1: Q | R1: R | S1: S | T1: T | U1: U | V1: V | W1: W | X1: X | Y1: Y | Z1: Z | AA1: AA | AB1: AB
A2: 居室 | B2: 利用者名 | C2: 分納残 | D2: 家賃 | E2: 管理費 | F2: 共益費 | G2: 水道料金 | H2: 定額光熱費 | I2: 食事 | J2: 調整額 | K2: オムツ | L2: 日用品 | M2: 分割支払い | N2: 事務手数料 | O2: デイサービス | P2: 福祉用具 | Q2: しろくま薬局 | R2: 往診診療費 | S2: サポート費 | T2: その他 | W2: 計 | X2: 一部負担(介護) | Y2: 一部負担(看護) | Z2: 合計 | AA2: 備考 | AB2: 請求書 | AC2: 分割残高 | AD2: 入金額 | AE2: 過不足
A3: 2A | C3: ='R7.4'!AC3 -> 0 | W3: =SUM(D3:V3) -> 0 | Z3: =SUM(W3:Y3) -> 0 | AB3: 未作成 | AC3: =C3-M3 -> 0
A4: 2B | C4: ='R7.4'!AC4 -> 0 | W4: =SUM(D4:V4) -> 0 | Z4: =SUM(W4:Y4) -> 0 | AA4: 通常請求 | AB4: 未作成 | AC4: =C4-M4 -> 0
A5: 2E | C5: ='R7.4'!AC5 -> 0 | W5: =SUM(D5:V5) -> 0 | Z5: =SUM(W5:Y5) -> 0 | AA5: 110000 | AB5: 未作成 | AC5: =C5-M5 -> 0
A6: 5B | C6: ='R7.4'!AC6 -> 0 | W6: =SUM(D6:V6) -> 0 | Z6: =SUM(W6:Y6) -> 0 | AA6: 通常請求 | AB6: 未作成 | AC6: =C6-M6 -> 0
A7: 5C | B7: 上田清江 | C7: ='R7.4'!AC7 -> 90000 | D7: 40000 | E7: 5000 | F7: 5000 | G7: 2000 | H7: 0 | I7: 42130 | M7: 10000 | S7: 5870 | V7: ='R7.4'!AE7 -> 50000 | W7: =SUM(D7:U7)-V7 -> 60000 | Z7: =SUM(W7:Y7) -> 60000 | AA7: 110000 | AB7: 未作成 | AC7: =C7-M7 -> 80000 | AD7: 90000 | AE7: =AD7-Z7 -> 30000 | AF7: 45894
A8: 6A | C8: ='R7.4'!AC8 -> 0 | W8: =SUM(D8:V8) -> 0 | Z8: =SUM(W8:Y8) -> 0 | AB8: 未作成 | AC8: =C8-M8 -> 0
A9: 6B | C9: ='R7.4'!AC9 -> 0 | W9: =SUM(D9:V9) -> 0 | Z9: =SUM(W9:Y9) -> 0 | AA9: 通常請求 | AB9: 未作成 | AC9: =C9-M9 -> 0
A10: 6C | C10: ='R7.4'!AC10 -> 0 | W10: =SUM(D10:V10) -> 0 | Z10: =SUM(W10:Y10) -> 0 | AA10: 通常請求 | AB10: 未作成 | AC10: =C10-M10 -> 0
A11: 6D | C11: ='R7.4'!AC11 -> 0 | W11: =SUM(D11:V11) -> 0 | Z11: =SUM(W11:Y11) -> 0 | AB11: 未作成 | AC11: =C11-M11 -> 0
A12: 6E | C12: ='R7.4'!AC12 -> 0 | W12: =SUM(D12:V12) -> 0 | Z12: =SUM(W12:Y12) -> 0 | AA12: 通常請求 | AB12: 未作成 | AC12: =C12-M12 -> 0
W13: =SUM(D13:V13) -> 0 | Z13: =SUM(W13:Y13) -> 0 | AB13: 未作成 | AC13: =C13-M13 -> 0
W14: =SUM(D14:V14) -> 0 | Z14: =SUM(W14:Y14) -> 0 | AC14: =C14-M14 -> 0
W15: =SUM(D15:V15) -> 0 | Z15: =SUM(W15:Y15) -> 0 | AC15: =C15-M15 -> 0
W16: =SUM(D16:V16) -> 0 | Z16: =SUM(W16:Y16) -> 0 | AC16: =C16-M16 -> 0
W17: =SUM(D17:V17) -> 0 | Z17: =SUM(W17:Y17) -> 0 | AC17: =C17-M17 -> 0
W18: =SUM(D18:V18) -> 0 | Z18: =SUM(W18:Y18) -> 0 | AC18: =C18-M18 -> 0
W19: =SUM(D19:V19) -> 0 | Z19: =SUM(W19:Y19) -> 0 | AC19: =C19-M19 -> 0
W20: =SUM(D20:V20) -> 0 | Z20: =SUM(W20:Y20) -> 0 | AC20: =C20-M20 -> 0
W21: =SUM(D21:V21) -> 0 | Z21: =SUM(W21:Y21) -> 0 | AC21: =C21-M21 -> 0
W22: =SUM(D22:V22) -> 0 | Z22: =SUM(W22:Y22) -> 0 | AC22: =C22-M22 -> 0
W23: =SUM(D23:V23) -> 0 | Z23: =SUM(W23:Y23) -> 0 | AC23: =C23-M23 -> 0
W24: =SUM(D24:V24) -> 0 | Z24: =SUM(W24:Y24) -> 0 | AC24: =C24-M24 -> 0
W25: =SUM(D25:V25) -> 0 | Z25: =SUM(W25:Y25) -> 0 | AC25: =C25-M25 -> 0
... W109: =SUM(D109:V109) -> 0 | Z109: =SUM(W109:Y109) -> 0 | AC109: =C109-M109 -> 0
A110: 合計 | D110: =SUM(D3:D109) -> 40000 | E110: =SUM(E3:E109) -> 5000 | F110: =SUM(F3:F109) -> 5000 | G110: =SUM(G3:G109) -> 2000 | H110: =SUM(H3:H109) -> 0 | I110: =SUM(I3:I109) -> 42130 | J110: =SUM(J3:J109) -> 0 | K110: =SUM(K3:K109) -> 0 | ... V110: =SUM(V3:V109) -> 50000 | W110: =SUM(D110:V110) -> 160000 | X110: =SUM(X3:X109) -> 0 | Y110: =SUM(Y3:Y109) -> 0 | Z110: =SUM(W110:Y110) -> 160000
AE111: ↑来月の過不足へ反映

Sheet R7.4
A1: 45777 | C1: 請求 | D1: D | E1: E | F1: F | G1: G | H1: H | I1: I | J1: J | K1: K | L1: L | M1: M | N1: N | O1: O | P1: P | Q1: Q | R1: R | S1: S | T1: T | U1: U | V1: V | W1: W | X1: X | Y1: Y | Z1: Z | AA1: AA | AB1: AB
A2: 居室 | B2: 利用者名 | C2: 分納残 | D2: 家賃 | E2: 管理費 | F2: 共益費 | G2: 水道料金 | H2: 定額光熱費 | I2: 食事 | J2: 調整額 | K2: オムツ | L2: 日用品 | M2: 分割支払い | N2: 事務手数料 | O2: デイサービス | P2: 福祉用具 | Q2: しろくま薬局 | R2: 往診診療費 | S2: サポート費 | T2: その他 | W2: 計 | X2: 一部負担(介護) | Y2: 一部負担(看護) | Z2: 合計 | AA2: 備考 | AB2: 請求書 | AC2: 分割残高 | AD2: 入金額 | AE2: 過不足
A3: 2A | C3: ='R7.3'!AC3 -> 0 | W3: =SUM(D3:V3) -> 0 | Z3: =SUM(W3:Y3) -> 0 | AB3: 未作成 | AC3: =C3-M3 -> 0
A4: 2B | C4: ='R7.3'!AC4 -> 0 | W4: =SUM(D4:V4) -> 0 | Z4: =SUM(W4:Y4) -> 0 | AA4: 通常請求 | AB4: 未作成 | AC4: =C4-M4 -> 0
A5: 2E | C5: ='R7.3'!AC5 -> 0 | W5: =SUM(D5:V5) -> 0 | Z5: =SUM(W5:Y5) -> 0 | AA5: 110000 | AB5: 未作成 | AC5: =C5-M5 -> 0
A6: 5B | C6: ='R7.3'!AC6 -> 0 | W6: =SUM(D6:V6) -> 0 | Z6: =SUM(W6:Y6) -> 0 | AA6: 通常請求 | AB6: 未作成 | AC6: =C6-M6 -> 0
A7: 5C | B7: 上田清江 | C7: ='R7.3'!AC7 -> 100000 | D7: 40000 | E7: 5000 | F7: 5000 | G7: 2000 | H7: 0 | I7: 42900 | M7: 10000 | S7: 5100 | V7: ='R7.3'!AE7 -> 40000 | W7: =SUM(D7:U7)-V7 -> 70000 | Z7: =SUM(W7:Y7) -> 70000 | AA7: 110000 | AB7: 未作成 | AC7: =C7-M7 -> 90000 | AD7: 120000 | AE7: =AD7-Z7 -> 50000 | AF7: 45888
A8: 6A | C8: ='R7.3'!AC8 -> 0 | W8: =SUM(D8:V8) -> 0 | Z8: =SUM(W8:Y8) -> 0 | AB8: 未作成 | AC8: =C8-M8 -> 0
A9: 6B | C9: ='R7.3'!AC9 -> 0 | W9: =SUM(D9:V9) -> 0 | Z9: =SUM(W9:Y9) -> 0 | AA9: 通常請求 | AB9: 未作成 | AC9: =C9-M9 -> 0
A10: 6C | C10: ='R7.3'!AC10 -> 0 | W10: =SUM(D10:V10) -> 0 | Z10: =SUM(W10:Y10) -> 0 | AA10: 通常請求 | AB10: 未作成 | AC10: =C10-M10 -> 0
A11: 6D | C11: ='R7.3'!AC11 -> 0 | W11: =SUM(D11:V11) -> 0 | Z11: =SUM(W11:Y11) -> 0 | AB11: 未作成 | AC11: =C11-M11 -> 0
A12: 6E | C12: ='R7.3'!AC12 -> 0 | W12: =SUM(D12:V12) -> 0 | Z12: =SUM(W12:Y12) -> 0 | AA12: 通常請求 | AB12: 未作成 | AC12: =C12-M12 -> 0
W13: =SUM(D13:V13) -> 0 | Z13: =SUM(W13:Y13) -> 0 | AB13: 未作成 | AC13: =C13-M13 -> 0
W14: =SUM(D14:V14) -> 0 | Z14: =SUM(W14:Y14) -> 0 | AC14: =C14-M14 -> 0
W15: =SUM(D15:V15) -> 0 | Z15: =SUM(W15:Y15) -> 0 | AC15: =C15-M15 -> 0
W16: =SUM(D16:V16) -> 0 | Z16: =SUM(W16:Y16) -> 0 | AC16: =C16-M16 -> 0
W17: =SUM(D17:V17) -> 0 | Z17: =SUM(W17:Y17) -> 0 | AC17: =C17-M17 -> 0
W18: =SUM(D18:V18) -> 0 | Z18: =SUM(W18:Y18) -> 0 | AC18: =C18-M18 -> 0
W19: =SUM(D19:V19) -> 0 | Z19: =SUM(W19:Y19) -> 0 | AC19: =C19-M19 -> 0
W20: =SUM(D20:V20) -> 0 | Z20: =SUM(W20:Y20) -> 0 | AC20: =C20-M20 -> 0
W21: =SUM(D21:V21) -> 0 | Z21: =SUM(W21:Y21) -> 0 | AC21: =C21-M21 -> 0
W22: =SUM(D22:V22) -> 0 | Z22: =SUM(W22:Y22) -> 0 | AC22: =C22-M22 -> 0
W23: =SUM(D23:V23) -> 0 | Z23: =SUM(W23:Y23) -> 0 | AC23: =C23-M23 -> 0
W24: =SUM(D24:V24) -> 0 | Z24: =SUM(W24:Y24) -> 0 | AC24: =C24-M24 -> 0
W25: =SUM(D25:V25) -> 0 | Z25: =SUM(W25:Y25) -> 0 | AC25: =C25-M25 -> 0
... W109: =SUM(D109:V109) -> 0 | Z109: =SUM(W109:Y109) -> 0 | AC109: =C109-M109 -> 0
A110: 合計 | D110: =SUM(D3:D109) -> 40000 | E110: =SUM(E3:E109) -> 5000 | F110: =SUM(F3:F109) -> 5000 | G110: =SUM(G3:G109) -> 2000 | H110: =SUM(H3:H109) -> 0 | I110: =SUM(I3:I109) -> 42900 | J110: =SUM(J3:J109) -> 0 | K110: =SUM(K3:K109) -> 0 | ... V110: =SUM(V3:V109) -> 40000 | W110: =SUM(D110:V110) -> 150000 | X110: =SUM(X3:X109) -> 0 | Y110: =SUM(Y3:Y109) -> 0 | Z110: =SUM(W110:Y110) -> 150000
AE111: ↑来月の過不足へ反映

Sheet R7.3
A1: 45747 | C1: 請求 | D1: D | E1: E | F1: F | G1: G | H1: H | I1: I | J1: J | K1: K | L1: L | M1: M | N1: N | O1: O | P1: P | Q1: Q | R1: R | S1: S | T1: T | U1: U | V1: V | W1: W | X1: X | Y1: Y | Z1: Z | AA1: AA | AB1: AB
A2: 居室 | B2: 利用者名 | C2: 分納残 | D2: 家賃 | E2: 管理費 | F2: 共益費 | G2: 水道料金 | H2: 定額光熱費 | I2: 食事 | J2: 調整額 | K2: オムツ | L2: 日用品 | M2: 分割支払い | N2: 事務手数料 | O2: デイサービス | P2: 福祉用具 | Q2: しろくま薬局 | R2: 往診診療費 | S2: サポート費 | T2: その他 | W2: 計 | X2: 一部負担(介護) | Y2: 一部負担(看護) | Z2: 合計 | AA2: 備考 | AB2: 請求書 | AC2: 分割残高 | AD2: 入金額 | AE2: 過不足
A3: 2A | C3: ='R7.2'!AC3 -> 0 | W3: =SUM(D3:V3) -> 0 | Z3: =SUM(W3:Y3) -> 0 | AB3: 未作成 | AC3: =C3-M3 -> 0
A4: 2B | C4: ='R7.2'!AC4 -> 0 | W4: =SUM(D4:V4) -> 0 | Z4: =SUM(W4:Y4) -> 0 | AA4: 通常請求 | AB4: 未作成 | AC4: =C4-M4 -> 0
A5: 2E | C5: ='R7.2'!AC5 -> 0 | W5: =SUM(D5:V5) -> 0 | Z5: =SUM(W5:Y5) -> 0 | AA5: 110000 | AB5: 未作成 | AC5: =C5-M5 -> 0
A6: 5B | C6: ='R7.2'!AC6 -> 0 | W6: =SUM(D6:V6) -> 0 | Z6: =SUM(W6:Y6) -> 0 | AA6: 通常請求 | AB6: 未作成 | AC6: =C6-M6 -> 0
A7: 5C | B7: 上田清江 | C7: ='R7.2'!AC7 -> 110000 | D7: 40000 | E7: 5000 | F7: 5000 | G7: 2000 | H7: 0 | I7: 34870 | M7: 10000 | S7: 13130 | V7: ='R7.2'!AE7 -> 30000 | W7: =SUM(D7:U7)-V7 -> 80000 | Z7: =SUM(W7:Y7) -> 80000 | AA7: 110000 | AB7: 未作成 | AC7: =C7-M7 -> 100000 | AD7: 120000 | AE7: =AD7-Z7 -> 40000 | AF7: 45828
A8: 6A | C8: ='R7.2'!AC8 -> 0 | W8: =SUM(D8:V8) -> 0 | Z8: =SUM(W8:Y8) -> 0 | AB8: 未作成 | AC8: =C8-M8 -> 0
A9: 6B | C9: ='R7.2'!AC9 -> 0 | W9: =SUM(D9:V9) -> 0 | Z9: =SUM(W9:Y9) -> 0 | AA9: 通常請求 | AB9: 未作成 | AC9: =C9-M9 -> 0
A10: 6C | C10: ='R7.2'!AC10 -> 0 | W10: =SUM(D10:V10) -> 0 | Z10: =SUM(W10:Y10) -> 0 | AA10: 通常請求 | AB10: 未作成 | AC10: =C10-M10 -> 0
A11: 6D | C11: ='R7.2'!AC11 -> 0 | W11: =SUM(D11:V11) -> 0 | Z11: =SUM(W11:Y11) -> 0 | AB11: 未作成 | AC11: =C11-M11 -> 0
A12: 6E | C12: ='R7.2'!AC12 -> 0 | W12: =SUM(D12:V12) -> 0 | Z12: =SUM(W12:Y12) -> 0 | AA12: 通常請求 | AB12: 未作成 | AC12: =C12-M12 -> 0
W13: =SUM(D13:V13) -> 0 | Z13: =SUM(W13:Y13) -> 0 | AB13: 未作成 | AC13: =C13-M13 -> 0
W14: =SUM(D14:V14) -> 0 | Z14: =SUM(W14:Y14) -> 0 | AC14: =C14-M14 -> 0
W15: =SUM(D15:V15) -> 0 | Z15: =SUM(W15:Y15) -> 0 | AC15: =C15-M15 -> 0
W16: =SUM(D16:V16) -> 0 | Z16: =SUM(W16:Y16) -> 0 | AC16: =C16-M16 -> 0
W17: =SUM(D17:V17) -> 0 | Z17: =SUM(W17:Y17) -> 0 | AC17: =C17-M17 -> 0
W18: =SUM(D18:V18) -> 0 | Z18: =SUM(W18:Y18) -> 0 | AC18: =C18-M18 -> 0
W19: =SUM(D19:V19) -> 0 | Z19: =SUM(W19:Y19) -> 0 | AC19: =C19-M19 -> 0
W20: =SUM(D20:V20) -> 0 | Z20: =SUM(W20:Y20) -> 0 | AC20: =C20-M20 -> 0
W21: =SUM(D21:V21) -> 0 | Z21: =SUM(W21:Y21) -> 0 | AC21: =C21-M21 -> 0
W22: =SUM(D22:V22) -> 0 | Z22: =SUM(W22:Y22) -> 0 | AC22: =C22-M22 -> 0
W23: =SUM(D23:V23) -> 0 | Z23: =SUM(W23:Y23) -> 0 | AC23: =C23-M23 -> 0
W24: =SUM(D24:V24) -> 0 | Z24: =SUM(W24:Y24) -> 0 | AC24: =C24-M24 -> 0
W25: =SUM(D25:V25) -> 0 | Z25: =SUM(W25:Y25) -> 0 | AC25: =C25-M25 -> 0
... W109: =SUM(D109:V109) -> 0 | Z109: =SUM(W109:Y109) -> 0 | AC109: =C109-M109 -> 0
A110: 合計 | D110: =SUM(D3:D109) -> 40000 | E110: =SUM(E3:E109) -> 5000 | F110: =SUM(F3:F109) -> 5000 | G110: =SUM(G3:G109) -> 2000 | H110: =SUM(H3:H109) -> 0 | I110: =SUM(I3:I109) -> 34870 | J110: =SUM(J3:J109) -> 0 | K110: =SUM(K3:K109) -> 0 | ... V110: =SUM(V3:V109) -> 30000 | W110: =SUM(D110:V110) -> 140000 | X110: =SUM(X3:X109) -> 0 | Y110: =SUM(Y3:Y109) -> 0 | Z110: =SUM(W110:Y110) -> 140000
AE111: ↑来月の過不足へ反映

Sheet R7.2
A1: 45716 | C1: 請求 | D1: D | E1: E | F1: F | G1: G | H1: H | I1: I | J1: J | K1: K | L1: L | M1: M | N1: N | O1: O | P1: P | Q1: Q | R1: R | S1: S | T1: T | U1: U | V1: V | W1: W | X1: X | Y1: Y | Z1: Z | AA1: AA | AB1: AB
A2: 居室 | B2: 利用者名 | C2: 分納残 | D2: 家賃 | E2: 管理費 | F2: 共益費 | G2: 水道料金 | H2: 定額光熱費 | I2: 食事 | J2: 調整額 | K2: オムツ | L2: 日用品 | M2: 分割支払い | N2: 事務手数料 | O2: デイサービス | P2: 福祉用具 | Q2: しろくま薬局 | R2: 往診診療費 | S2: サポート費 | T2: その他 | W2: 計 | X2: 一部負担(介護) | Y2: 一部負担(看護) | Z2: 合計 | AA2: 備考 | AB2: 請求書 | AC2: 分割残高 | AD2: 入金額 | AE2: 過不足
A3: 2A | C3: ='R7.1'!AC3 -> 0 | W3: =SUM(D3:V3) -> 0 | Z3: =SUM(W3:Y3) -> 0 | AB3: 未作成 | AC3: =C3-M3 -> 0
A4: 2B | C4: ='R7.1'!AC4 -> 0 | W4: =SUM(D4:V4) -> 0 | Z4: =SUM(W4:Y4) -> 0 | AA4: 通常請求 | AB4: 未作成 | AC4: =C4-M4 -> 0
A5: 2E | C5: ='R7.1'!AC5 -> 0 | W5: =SUM(D5:V5) -> 0 | Z5: =SUM(W5:Y5) -> 0 | AA5: 110000 | AB5: 未作成 | AC5: =C5-M5 -> 0
A6: 5B | C6: ='R7.1'!AC6 -> 0 | W6: =SUM(D6:V6) -> 0 | Z6: =SUM(W6:Y6) -> 0 | AA6: 通常請求 | AB6: 未作成 | AC6: =C6-M6 -> 0
A7: 5C | B7: 上田清江 | C7: ='R7.1'!AC7 -> 120000 | D7: 40000 | E7: 5000 | F7: 5000 | G7: 2000 | H7: 0 | I7: 0 | M7: 10000 | S7: 48000 | V7: ='R7.1'!AE7 -> 20000 | W7: =SUM(D7:U7)-V7 -> 90000 | Z7: =SUM(W7:Y7) -> 90000 | AA7: 110000 | AB7: 未作成 | AC7: =C7-M7 -> 110000 | AD7: 120000 | AE7: =AD7-Z7 -> 30000 | AF7: 45823
A8: 6A | C8: ='R7.1'!AC8 -> 0 | W8: =SUM(D8:V8) -> 0 | Z8: =SUM(W8:Y8) -> 0 | AB8: 未作成 | AC8: =C8-M8 -> 0
A9: 6B | C9: ='R7.1'!AC9 -> 0 | W9: =SUM(D9:V9) -> 0 | Z9: =SUM(W9:Y9) -> 0 | AA9: 通常請求 | AB9: 未作成 | AC9: =C9-M9 -> 0
A10: 6C | C10: ='R7.1'!AC10 -> 0 | W10: =SUM(D10:V10) -> 0 | Z10: =SUM(W10:Y10) -> 0 | AA10: 通常請求 | AB10: 未作成 | AC10: =C10-M10 -> 0
A11: 6D | C11: ='R7.1'!AC11 -> 0 | W11: =SUM(D11:V11) -> 0 | Z11: =SUM(W11:Y11) -> 0 | AB11: 未作成 | AC11: =C11-M11 -> 0
A12: 6E | C12: ='R7.1'!AC12 -> 0 | W12: =SUM(D12:V12) -> 0 | Z12: =SUM(W12:Y12) -> 0 | AA12: 通常請求 | AB12: 未作成 | AC12: =C12-M12 -> 0
C13: ='R7.1'!AC13 -> 0 | W13: =SUM(D13:V13) -> 0 | Z13: =SUM(W13:Y13) -> 0 | AB13: 未作成 | AC13: =C13-M13 -> 0
C14: ='R7.1'!AC14 -> 0 | W14: =SUM(D14:V14) -> 0 | Z14: =SUM(W14:Y14) -> 0 | AC14: =C14-M14 -> 0
C15: ='R7.1'!AC15 -> 0 | W15: =SUM(D15:V15) -> 0 | Z15: =SUM(W15:Y15) -> 0 | AC15: =C15-M15 -> 0
C16: ='R7.1'!AC16 -> 0 | W16: =SUM(D16:V16) -> 0 | Z16: =SUM(W16:Y16) -> 0 | AC16: =C16-M16 -> 0
C17: ='R7.1'!AC17 -> 0 | W17: =SUM(D17:V17) -> 0 | Z17: =SUM(W17:Y17) -> 0 | AC17: =C17-M17 -> 0
C18: ='R7.1'!AC18 -> 0 | W18: =SUM(D18:V18) -> 0 | Z18: =SUM(W18:Y18) -> 0 | AC18: =C18-M18 -> 0
C19: ='R7.1'!AC19 -> 0 | W19: =SUM(D19:V19) -> 0 | Z19: =SUM(W19:Y19) -> 0 | AC19: =C19-M19 -> 0
C20: ='R7.1'!AC20 -> 0 | W20: =SUM(D20:V20) -> 0 | Z20: =SUM(W20:Y20) -> 0 | AC20: =C20-M20 -> 0
C21: ='R7.1'!AC21 -> 0 | W21: =SUM(D21:V21) -> 0 | Z21: =SUM(W21:Y21) -> 0 | AC21: =C21-M21 -> 0
C22: ='R7.1'!AC22 -> 0 | W22: =SUM(D22:V22) -> 0 | Z22: =SUM(W22:Y22) -> 0 | AC22: =C22-M22 -> 0
C23: ='R7.1'!AC23 -> 0 | W23: =SUM(D23:V23) -> 0 | Z23: =SUM(W23:Y23) -> 0 | AC23: =C23-M23 -> 0
C24: ='R7.1'!AC24 -> 0 | W24: =SUM(D24:V24) -> 0 | Z24: =SUM(W24:Y24) -> 0 | AC24: =C24-M24 -> 0
C25: ='R7.1'!AC25 -> 0 | W25: =SUM(D25:V25) -> 0 | Z25: =SUM(W25:Y25) -> 0 | AC25: =C25-M25 -> 0
... C109: ='R7.1'!AC109 -> 0 | W109: =SUM(D109:V109) -> 0 | Z109: =SUM(W109:Y109) -> 0 | AC109: =C109-M109 -> 0
A110: 合計 | D110: =SUM(D3:D109) -> 40000 | E110: =SUM(E3:E109) -> 5000 | F110: =SUM(F3:F109) -> 5000 | G110: =SUM(G3:G109) -> 2000 | H110: =SUM(H3:H109) -> 0 | I110: =SUM(I3:I109) -> 0 | J110: =SUM(J3:J109) -> 0 | K110: =SUM(K3:K109) -> 0 | ... V110: =SUM(V3:V109) -> 20000 | W110: =SUM(D110:V110) -> 130000 | X110: =SUM(X3:X109) -> 0 | Y110: =SUM(Y3:Y109) -> 0 | Z110: =SUM(W110:Y110) -> 130000
AE111: ↑来月の過不足へ反映

Sheet R7.1
A1: 45688 | C1: 請求 | D1: D | E1: E | F1: F | G1: G | H1: H | I1: I | J1: J | K1: K | L1: L | M1: M | N1: N | O1: O | P1: P | Q1: Q | R1: R | S1: S | T1: T | U1: U | V1: V | W1: W | X1: X | Y1: Y | Z1: Z | AA1: AA | AB1: AB
A2: 居室 | B2: 利用者名 | C2: 分納残 | D2: 家賃 | E2: 管理費 | F2: 共益費 | G2: 水道料金 | H2: 定額光熱費 | I2: 食事 | J2: 調整額 | K2: オムツ | L2: 日用品 | M2: 分割支払い | N2: 事務手数料 | O2: デイサービス | P2: 福祉用具 | Q2: しろくま薬局 | R2: 往診診療費 | S2: サポート費 | T2: その他 | W2: 計 | X2: 一部負担(介護) | Y2: 一部負担(看護) | Z2: 合計 | AA2: 備考 | AB2: 請求書 | AC2: 分割残高 | AD2: 入金額 | AE2: 過不足
A3: 2A | C3: ='R6.12'!AC3 -> 0 | V3: ='R6.12'!AE3 | W3: =SUM(D3:U3)-V3 -> 0 | Z3: =SUM(W3:Y3) -> 0 | AB3: 未作成 | AC3: =C3-M3 -> 0
A4: 2B | C4: ='R6.12'!AC4 -> 0 | V4: ='R6.12'!AE4 | W4: =SUM(D4:U4)-V4 -> 0 | Z4: =SUM(W4:Y4) -> 0 | AA4: 通常請求 | AB4: 未作成 | AC4: =C4-M4 -> 0
A5: 2E | C5: ='R6.12'!AC5 -> 0 | V5: ='R6.12'!AE5 | W5: =SUM(D5:U5)-V5 -> 0 | Z5: =SUM(W5:Y5) -> 0 | AA5: 110000 | AB5: 未作成 | AC5: =C5-M5 -> 0
A6: 5B | C6: ='R6.12'!AC6 -> 0 | V6: ='R6.12'!AE6 | W6: =SUM(D6:U6)-V6 -> 0 | Z6: =SUM(W6:Y6) -> 0 | AA6: 通常請求 | AB6: 未作成 | AC6: =C6-M6 -> 0
A7: 5C | B7: 上田清江 | C7: ='R6.12'!AC7 -> 130000 | D7: 40000 | E7: 5000 | F7: 5000 | G7: 2000 | H7: 0 | I7: 5720 | M7: 10000 | S7: 42280 | V7: ='R6.12'!AE7 -> 10000 | W7: =SUM(D7:U7)-V7 -> 100000 | Z7: =SUM(W7:Y7) -> 100000 | AA7: 110000 | AB7: 未作成 | AC7: =C7-M7 -> 120000 | AD7: 120000 | AE7: =AD7-Z7 -> 20000 | AF7: 45725
A8: 6A | C8: ='R6.12'!AC8 -> 0 | V8: ='R6.12'!AE8 | W8: =SUM(D8:U8)-V8 -> 0 | Z8: =SUM(W8:Y8) -> 0 | AB8: 未作成 | AC8: =C8-M8 -> 0
A9: 6B | C9: ='R6.12'!AC9 -> 0 | V9: ='R6.12'!AE9 | W9: =SUM(D9:U9)-V9 -> 0 | Z9: =SUM(W9:Y9) -> 0 | AA9: 通常請求 | AB9: 未作成 | AC9: =C9-M9 -> 0
A10: 6C | C10: ='R6.12'!AC10 -> 0 | V10: ='R6.12'!AE10 | W10: =SUM(D10:U10)-V10 -> 0 | Z10: =SUM(W10:Y10) -> 0 | AA10: 通常請求 | AB10: 未作成 | AC10: =C10-M10 -> 0
A11: 6D | C11: ='R6.12'!AC11 -> 0 | V11: ='R6.12'!AE11 | W11: =SUM(D11:U11)-V11 -> 0 | Z11: =SUM(W11:Y11) -> 0 | AB11: 未作成 | AC11: =C11-M11 -> 0
A12: 6E | C12: ='R6.12'!AC12 -> 0 | V12: ='R6.12'!AE12 | W12: =SUM(D12:U12)-V12 -> 0 | Z12: =SUM(W12:Y12) -> 0 | AA12: 通常請求 | AB12: 未作成 | AC12: =C12-M12 -> 0
C13: ='R6.12'!AC13 -> 0 | V13: ='R6.12'!AE13 | W13: =SUM(D13:U13)-V13 -> 0 | Z13: =SUM(W13:Y13) -> 0 | AB13: 未作成 | AC13: =C13-M13 -> 0
C14: ='R6.12'!AC14 -> 0 | V14: ='R6.12'!AE14 | W14: =SUM(D14:U14)-V14 -> 0 | Z14: =SUM(W14:Y14) -> 0 | AC14: =C14-M14 -> 0
C15: ='R6.12'!AC15 -> 0 | V15: ='R6.12'!AE15 | W15: =SUM(D15:U15)-V15 -> 0 | Z15: =SUM(W15:Y15) -> 0 | AC15: =C15-M15 -> 0
C16: ='R6.12'!AC16 -> 0 | V16: ='R6.12'!AE16 | W16: =SUM(D16:U16)-V16 -> 0 | Z16: =SUM(W16:Y16) -> 0 | AC16: =C16-M16 -> 0
C17: ='R6.12'!AC17 -> 0 | V17: ='R6.12'!AE17 | W17: =SUM(D17:U17)-V17 -> 0 | Z17: =SUM(W17:Y17) -> 0 | AC17: =C17-M17 -> 0
C18: ='R6.12'!AC18 -> 0 | V18: ='R6.12'!AE18 | W18: =SUM(D18:U18)-V18 -> 0 | Z18: =SUM(W18:Y18) -> 0 | AC18: =C18-M18 -> 0
C19: ='R6.12'!AC19 -> 0 | V19: ='R6.12'!AE19 | W19: =SUM(D19:U19)-V19 -> 0 | Z19: =SUM(W19:Y19) -> 0 | AC19: =C19-M19 -> 0
C20: ='R6.12'!AC20 -> 0 | V20: ='R6.12'!AE20 | W20: =SUM(D20:U20)-V20 -> 0 | Z20: =SUM(W20:Y20) -> 0 | AC20: =C20-M20 -> 0
C21: ='R6.12'!AC21 -> 0 | V21: ='R6.12'!AE21 | W21: =SUM(D21:U21)-V21 -> 0 | Z21: =SUM(W21:Y21) -> 0 | AC21: =C21-M21 -> 0
C22: ='R6.12'!AC22 -> 0 | V22: ='R6.12'!AE22 | W22: =SUM(D22:U22)-V22 -> 0 | Z22: =SUM(W22:Y22) -> 0 | AC22: =C22-M22 -> 0
C23: ='R6.12'!AC23 -> 0 | V23: ='R6.12'!AE23 | W23: =SUM(D23:U23)-V23 -> 0 | Z23: =SUM(W23:Y23) -> 0 | AC23: =C23-M23 -> 0
C24: ='R6.12'!AC24 -> 0 | V24: ='R6.12'!AE24 | W24: =SUM(D24:U24)-V24 -> 0 | Z24: =SUM(W24:Y24) -> 0 | AC24: =C24-M24 -> 0
C25: ='R6.12'!AC25 -> 0 | V25: ='R6.12'!AE25 | W25: =SUM(D25:U25)-V25 -> 0 | Z25: =SUM(W25:Y25) -> 0 | AC25: =C25-M25 -> 0
... C109: ='R6.12'!AC109 -> 0 | V109: ='R6.12'!AE109 | W109: =SUM(D109:U109)-V109 -> 0 | Z109: =SUM(W109:Y109) -> 0 | AC109: =C109-M109 -> 0
A110: 合計 | D110: =SUM(D3:D109) -> 40000 | E110: =SUM(E3:E109) -> 5000 | F110: =SUM(F3:F109) -> 5000 | G110: =SUM(G3:G109) -> 2000 | H110: =SUM(H3:H109) -> 0 | I110: =SUM(I3:I109) -> 5720 | J110: =SUM(J3:J109) -> 0 | K110: =SUM(K3:K109) -> 0 | ... V110: =SUM(V3:V109) -> 10000 | W110: =SUM(D110:V110) -> 120000 | X110: =SUM(X3:X109) -> 0 | Y110: =SUM(Y3:Y109) -> 0 | Z110: =SUM(W110:Y110) -> 120000
AE111: ↑来月の過不足へ反映

Sheet R6.12
A1: 45657 | C1: 請求 | D1: D | E1: E | F1: F | G1: G | H1: H | I1: I | J1: J | K1: K | L1: L | M1: M | N1: N | O1: O | P1: P | Q1: Q | R1: R | S1: S | T1: T | U1: U | V1: V | W1: W | X1: X | Y1: Y | Z1: Z | AA1: AA | AB1: AB
A2: 居室 | B2: 利用者名 | C2: 分納残 | D2: 家賃 | E2: 管理費 | F2: 共益費 | G2: 水道料金 | H2: 定額光熱費 | I2: 食事 | J2: 調整額 | K2: オムツ | L2: 日用品 | M2: 分割支払い | N2: 事務手数料 | O2: デイサービス | P2: 福祉用具 | Q2: しろくま薬局 | R2: 往診診療費 | S2: サポート費 | T2: その他 | W2: 計 | X2: 一部負担(介護) | Y2: 一部負担(看護) | Z2: 合計 | AA2: 備考 | AB2: 請求書 | AC2: 分割残高 | AD2: 入金額 | AE2: 過不足
A3: 2A | C3: ='R6.11'!AC3 -> 0 | W3: =SUM(D3:V3) -> 0 | Z3: =SUM(W3:Y3) -> 0 | AB3: 未作成 | AC3: =C3-M3 -> 0
A4: 2B | C4: ='R6.11'!AC4 -> 0 | W4: =SUM(D4:V4) -> 0 | Z4: =SUM(W4:Y4) -> 0 | AA4: 通常請求 | AB4: 未作成 | AC4: =C4-M4 -> 0
A5: 2E | C5: ='R6.11'!AC5 -> 0 | W5: =SUM(D5:V5) -> 0 | Z5: =SUM(W5:Y5) -> 0 | AA5: 110000 | AB5: 未作成 | AC5: =C5-M5 -> 0
A6: 5B | C6: ='R6.11'!AC6 -> 0 | W6: =SUM(D6:V6) -> 0 | Z6: =SUM(W6:Y6) -> 0 | AA6: 通常請求 | AB6: 未作成 | AC6: =C6-M6 -> 0
A7: 5C | B7: 上田清江 | C7: ='R6.11'!AC7 -> 140000 | D7: 40000 | E7: 5000 | F7: 5000 | G7: 2000 | H7: 0 | I7: 44000 | M7: 10000 | S7: 4000 | W7: =SUM(D7:V7) -> 110000 | Z7: =SUM(W7:Y7) -> 110000 | AA7: 110000 | AB7: 未作成 | AC7: =C7-M7 -> 130000 | AD7: 120000 | AE7: =AD7-Z7 -> 10000 | AF7: 45703
A8: 6A | C8: ='R6.11'!AC8 -> 0 | W8: =SUM(D8:V8) -> 0 | Z8: =SUM(W8:Y8) -> 0 | AB8: 未作成 | AC8: =C8-M8 -> 0
A9: 6B | C9: ='R6.11'!AC9 -> 0 | W9: =SUM(D9:V9) -> 0 | Z9: =SUM(W9:Y9) -> 0 | AA9: 通常請求 | AB9: 未作成 | AC9: =C9-M9 -> 0
A10: 6C | C10: ='R6.11'!AC10 -> 0 | W10: =SUM(D10:V10) -> 0 | Z10: =SUM(W10:Y10) -> 0 | AA10: 通常請求 | AB10: 未作成 | AC10: =C10-M10 -> 0
A11: 6D | C11: ='R6.11'!AC11 -> 0 | W11: =SUM(D11:V11) -> 0 | Z11: =SUM(W11:Y11) -> 0 | AB11: 未作成 | AC11: =C11-M11 -> 0
A12: 6E | C12: ='R6.11'!AC12 -> 0 | W12: =SUM(D12:V12) -> 0 | Z12: =SUM(W12:Y12) -> 0 | AA12: 通常請求 | AB12: 未作成 | AC12: =C12-M12 -> 0
C13: ='R6.11'!AC13 -> 0 | W13: =SUM(D13:V13) -> 0 | Z13: =SUM(W13:Y13) -> 0 | AB13: 未作成 | AC13: =C13-M13 -> 0
C14: ='R6.11'!AC14 -> 0 | W14: =SUM(D14:V14) -> 0 | Z14: =SUM(W14:Y14) -> 0 | AC14: =C14-M14 -> 0
