Workbook

Sheet 利用者
A1: 居室 | B1: 利用者名 | C1: 請求摘要 | D1: 対象期間
A2: 108 | B2: 杉田誠一 | C2: 家賃 | D2: 来月分
A3: 206 | B3: 林郁子 | C3: 管理費 | D3: 来月分
A4: 210 | B4: 西中照彦 | C4: 共益費 | D4: 来月分
A5: 211✕ | B5: 鈴木信子 | C5: 水道料金 | D5: 来月分
A6: 212 | B6: 長谷部融子 | C6: 定額光熱費 | D6: 来月分
A7: 303 | B7: 畑㞍真一 | C7: 食事 | D7: 当月分
A8: 310 | B8: 三代正治 | C8: 調整額 | D8: 当月分
A9: 401 | C9: オムツ | D9: 当月分
A10: 402 | B10: 鈴木信子 | C10: 日用品 | D10: 当月分
A11: 403 | B11: 上村春子 | C11: 分割支払い | D11: 当月分
A12: 405 | B12: 河田晃晁 | C12: 事務手数料 | D12: 当月分
A13: 406 | C13: サポート費 | D13: 当月分
A14: 407 | B14: 北村繁弘 | C14: その他 | D14: 当月分
A15: 408 | C15: デイサービス | D15: 当月分
A16: 415 | B16: 金坂孝信 | C16: 福祉用具 | D16: 前月分
A17: 601 | B17: 榎本裕子 | C17: しろくま薬局 | D17: 前月分
A18: 608 | B18: 西川太 | C18: 往診診療費 | D18: 前月分
A19: 703 | B19: 斧義也
A20: 715 | B20: 日川敬達
A21: 716 | B21: 内田克政
A25: 210✕ | B25: 北村繁弘
A108: 210✕ | B108: 北村繁弘
A109: 211✕ | B109: 鈴木信子

Sheet すまい請求書
A1: ええすまい御請求書 | M1: R7.8から使用可能
A2: {=VLOOKUP(F$4,INDIRECT(M$2&"!A3:U109"),2,FALSE)} -> 内田克政 | E2: 様 | H2: 発行日： | J2: 46056 | M2: R8.1
M3: 家賃 | N3: 2 | O3: 当月 | P3: 1 | Q3: 前月 | R3: 12
A4: パシフィック塚本（ええすまい） | F4: 716 | G4: 号室 | H4: 株式会社AA 代表取締役 大石佐智子
M5: ※分割払いの管理
A6: ご請求金額 | C6: =I34 -> 81800 | H6: 大阪市西淀川区柏里2-9-3-102
A9: 内 容 | C9: 単 価 | E9: 数量 | G9: 小計 | I9: 備考
A10: {=INDIRECT(M$2&"!D2")} -> 家賃 | C10: {=VLOOKUP(F$4,INDIRECT(M$2&"!A3:Y109"),4,FALSE)} -> 40000 | E10: 1か月 | G10: =C10 -> 40000 | I10: =N3 -> 2
A11: {=INDIRECT(M$2&"!E2")} -> 管理費 | C11: {=VLOOKUP(F$4,INDIRECT(M$2&"!A3:Y109"),5,FALSE)} -> 5000 | E11: 1か月 | G11: =C11 -> 5000 | I11: =N3 -> 2
A12: {=INDIRECT(M$2&"!F2")} -> 共益費 | C12: {=VLOOKUP(F$4,INDIRECT(M$2&"!A3:Y109"),6,FALSE)} -> 5000 | E12: 1か月 | G12: =C12 -> 5000 | I12: =N3 -> 2
A13: {=INDIRECT(M$2&"!G2")} -> 水道料金 | C13: {=VLOOKUP(F$4,INDIRECT(M$2&"!A3:Y109"),7,FALSE)} -> 2000 | E13: 1か月 | G13: =C13 -> 2000 | I13: =N3 -> 2
A14: {=INDIRECT(M$2&"!H2")} -> 定額光熱費 | C14: {=VLOOKUP(F$4,INDIRECT(M$2&"!A3:Y109"),8,FALSE)} -> 10000 | E14: 1か月 | G14: =C14 -> 10000 | I14: =N3 -> 2
A15: {=INDIRECT(M$2&"!I2")} -> 食事 | C15: {=VLOOKUP(F$4,INDIRECT(M$2&"!A3:Y109"),9,FALSE)} -> 19800 | E15: 1か月 | G15: =C15 -> 19800 | I15: =P3 -> 1
A16: {=INDIRECT(M$2&"!J2")} -> 調整額 | C16: {=VLOOKUP(F$4,INDIRECT(M$2&"!A3:Y109"),10,FALSE)} | E16: 1か月 | G16: =C16 | I16: =P3 -> 1
A17: {=INDIRECT(M$2&"!K2")} -> オムツ | C17: {=VLOOKUP(F$4,INDIRECT(M$2&"!A3:Y109"),11,FALSE)} | E17: 1か月 | G17: =C17 | I17: =P3 -> 1
A18: {=INDIRECT(M$2&"!L2")} -> 日用品 | C18: {=VLOOKUP(F$4,INDIRECT(M$2&"!A3:Y109"),12,FALSE)} | E18: 1か月 | G18: =C18 | I18: =P3 -> 1
A19: {=INDIRECT(M$2&"!M2")} -> 分割支払い | C19: {=VLOOKUP(F$4,INDIRECT(M$2&"!A3:Y109"),13,FALSE)} | E19: 1か月 | G19: =C19 | I19: =P3 -> 1
A20: {=INDIRECT(M$2&"!N2")} -> 事務手数料 | C20: {=VLOOKUP(F$4,INDIRECT(M$2&"!A3:Y109"),14,FALSE)} | E20: 1か月 | G20: =C20 | I20: =P3 -> 1
A21: {=INDIRECT(M$2&"!O2")} -> デイサービス | C21: {=VLOOKUP(F$4,INDIRECT(M$2&"!A3:Y109"),15,FALSE)} | E21: 1か月 | G21: =C21 | I21: =R3 -> 12
A22: {=INDIRECT(M$2&"!P2")} -> 福祉用具 | C22: {=VLOOKUP(F$4,INDIRECT(M$2&"!A3:Y109"),16,FALSE)} | E22: 1か月 | G22: =C22 | I22: =R3 -> 12
A23: {=INDIRECT(M$2&"!Q2")} -> しろくま薬局 | C23: {=VLOOKUP(F$4,INDIRECT(M$2&"!A3:Y109"),17,FALSE)} | E23: 1か月 | G23: =C23 | I23: =R3 -> 12
A24: {=INDIRECT(M$2&"!R2")} -> 往診診療費 | C24: {=VLOOKUP(F$4,INDIRECT(M$2&"!A3:Y109"),18,FALSE)} | E24: 1か月 | G24: =C24 | I24: =R3 -> 12
A25: {=INDIRECT(M$2&"!S2")} -> サポート費 | C25: {=VLOOKUP(F$4,INDIRECT(M$2&"!A3:Y109"),19,FALSE)} | E25: 1か月 | G25: =C25 | I25: =R3 -> 12
A26: {=INDIRECT(M$2&"!T2")} -> その他 | C26: {=VLOOKUP(F$4,INDIRECT(M$2&"!A3:Y109"),20,FALSE)} | E26: 1か月 | G26: =C26 | I26: =R3 -> 12
A27: {=INDIRECT(M$2&"!U2")} | C27: {=VLOOKUP(F$4,INDIRECT(M$2&"!A3:Y109"),21,FALSE)} | E27: 1か月 | G27: =C27
A28: {=INDIRECT(M$2&"!V2")} | C28: {=VLOOKUP(F$4,INDIRECT(M$2&"!A3:Y109"),22,FALSE)} | G28: =C28
A29: ご請求額合計 | G29: =SUM(G10:H28) -> 81800
A30: ※家賃、共益費、管理費、光熱費は消費税不要
A32: 8%対象 合計 | C32: 0 | G32: 消費税（８％） | I32: 0
A33: 10％対象 合計 | C33: 0 | G33: 消費税（10％） | I33: 0
G34: 税込合計 | I34: =G29 -> 81800

Sheet すまい領収書
B1: 領 収 書
E3: 受領日 | G3: 46058
B4: ='すまい請求書'!A2 -> 内田克政 | D4: 様
C6: ='すまい請求書'!C6 -> 81800
B7: 但し 家賃、共益費、管理費、水道代、自費分として
C8: 上記の金額正に受領いたしました
C9: 株式会社AA
C10: 〒555-0022
C11: 大阪市西淀川区柏里2-9-3-102
C12: TEL・FAX 06-4400-2901

Sheet すまい領収書 のコピー
B1: 領 収 書
E3: 受領日 | G3: 46015
B4: 奥谷 國治 | D4: 様
C6: 86000
B7: 但し 家賃、固定光熱費、共益費、管理費、自費分として
C8: 上記の金額正に受領いたしました
C9: 株式会社AA
C10: 〒555-0022
C11: 大阪市西淀川区柏里2-9-3-102
C12: TEL・FAX 06-4400-2901

Sheet 合算請求書
A1: ご利用金額のお知らせ
A2: {=VLOOKUP(F$4,INDIRECT(M$2&"!A3:U109"),2,FALSE)} -> 上村春子 | E2: 様 | F2: 発行日： | H2: 46055 | M2: R8.1
A4: パシフィック塚本（ええすまい） | F4: 403 | G4: 号室
B7: 合計金額 | D7: =SUM(C10:C12) -> 108913
A9: 内 容 | C9: 請求金額 | E9: お支払期限 | G9: 備考
A10: ええすまい | C10: {=VLOOKUP(F$4,INDIRECT(M$2&"!A3:Y109"),23,FALSE)} -> 83772 | E10: =H2+20 -> 46075 | G10: 請求書別紙
A11: ええかいご | C11: {=VLOOKUP(F$4,INDIRECT(M$2&"!A3:Y109"),24,FALSE)} -> 25141 | E11: =H2+20 -> 46075 | G11: 請求書別紙
A12: ええかんご | C12: {=VLOOKUP(F$4,INDIRECT(M$2&"!A3:Y109"),25,FALSE)} | E12: =H2+20 -> 46075 | G12: 請求書別紙
A14: お支払につきましては下記口座へお願いいたします。
A15: 振込手数料につきましてはお客様ご負担にてお願い申し上げます。
A17: 振込先
A18: 銀行名： | C18: 住信ＳＢＩネット銀行（金融機関コード0038）
A19: 支店名： | C19: 法人第一支店（支店コード106）
A20: 口座番号： | C20: 普通 2555848
A21: 口座名義： | C21: 株式会社AA
C22: カ）エーエー

Sheet R8.2
A1: 46081 | C1: 請求 | D1: D | E1: E | F1: F | G1: G | H1: H | I1: I | J1: J | K1: K | L1: L | M1: M | N1: N | O1: O | P1: P | Q1: Q | R1: R | S1: S | T1: T | U1: U | V1: V | W1: W | X1: X | Y1: Y | Z1: Z | AA1: AA | AB1: AB
A2: 居室 | B2: 利用者名 | C2: 分納残 | D2: 家賃 | E2: 管理費 | F2: 共益費 | G2: 水道料金 | H2: 定額光熱費 | I2: 食事 | J2: 調整額 | K2: オムツ | L2: 日用品 | M2: 分割支払い | N2: 事務手数料 | O2: デイサービス | P2: 福祉用具 | Q2: しろくま薬局 | R2: 往診診療費 | S2: サポート費 | T2: その他 | W2: 計 | X2: 一部負担(介護) | Y2: 一部負担(看護) | Z2: 合計 | AA2: 備考 | AB2: 請求書 | AC2: 分割残高
A3: 108 | B3: 杉田誠一 | C3: 185667 | D3: 40000 | E3: 5000 | F3: 5000 | G3: 2000 | H3: 10000 | W3: =SUM(D3:V3) -> 62000 | Z3: =SUM(W3:Y3) -> 62000 | AA3: 80000 | AB3: 未作成 | AC3: =C3-M3 -> 185667
A4: 206 | B4: 林郁子 | D4: 40000 | E4: 5000 | F4: 5000 | G4: 2000 | H4: 10000 | W4: =SUM(D4:V4) -> 62000 | Z4: =SUM(W4:Y4) -> 62000 | AA4: 通常請求 | AB4: 未作成 | AC4: =C4-M4 -> 0
A5: 210 | B5: 西中照彦 | C5: 130000 | D5: 0 | E5: 0 | F5: 0 | G5: 0 | H5: 0 | W5: =SUM(D5:V5) -> 0 | Z5: =SUM(W5:Y5) -> 0 | AA5: 9○+初期1 | AB5: 未作成 | AC5: =C5-M5 -> 130000
A6: 211 | W6: =SUM(D6:V6) -> 0 | Z6: =SUM(W6:Y6) -> 0 | AB6: 未作成 | AC6: =C6-M6 -> 0
A7: 212 | B7: 長谷部融子 | D7: 40000 | E7: 5000 | F7: 5000 | G7: 2000 | H7: 10000 | W7: =SUM(D7:V7) -> 62000 | Z7: =SUM(W7:Y7) -> 62000 | AA7: 通常請求 | AB7: 未作成 | AC7: =C7-M7 -> 0
A8: 303 | B8: 畑㞍真一 | W8: =SUM(D8:V8) -> 0 | Z8: =SUM(W8:Y8) -> 0 | AB8: 未作成 | AC8: =C8-M8 -> 0
A9: 310 | B9: 三代正治
A10: 401 | W10: =SUM(D10:V10) -> 0 | Z10: =SUM(W10:Y10) -> 0 | AB10: 未作成 | AC10: =C10-M10 -> 0
A11: 402 | B11: 鈴木信子 | D11: 40000 | E11: 5000 | F11: 5000 | G11: 2000 | H11: 10000 | W11: =SUM(D11:V11) -> 62000 | Z11: =SUM(W11:Y11) -> 62000 | AA11: 105000 | AB11: 未作成 | AC11: =C11-M11 -> 0
A12: 403 | B12: 上村春子 | C12: 100000 | D12: 40000 | E12: 5000 | F12: 5000 | G12: 2000 | H12: 10000 | W12: =SUM(D12:V12) -> 62000 | Z12: =SUM(W12:Y12) -> 62000 | AA12: 10○+初期1万 | AB12: 未作成 | AC12: =C12-M12 -> 100000 | AD12: 入院中一旦請求停止
A13: 405 | B13: 河田晃晁 | D13: 40000 | E13: 5000 | F13: 5000 | G13: 2000 | W13: =SUM(D13:V13) -> 52000 | Z13: =SUM(W13:Y13) -> 52000 | AB13: 未作成 | AC13: =C13-M13 -> 0
A14: 406 | W14: =SUM(D14:V14) -> 0 | Z14: =SUM(W14:Y14) -> 0 | AB14: 未作成 | AC14: =C14-M14 -> 0
A15: 407 | B15: 北村繁弘 | D15: 40000 | E15: 5000 | F15: 5000 | G15: 2000 | H15: 10000 | W15: =SUM(D15:V15) -> 62000 | Z15: =SUM(W15:Y15) -> 62000 | AA15: 100000 | AB15: 未作成 | AC15: =C15-M15 -> 0
A16: 408 | W16: =SUM(D16:V16) -> 0 | Z16: =SUM(W16:Y16) -> 0 | AB16: 未作成 | AC16: =C16-M16 -> 0
A17: 415 | B17: 金坂孝信 | C17: 128000 | D17: 40000 | E17: 5000 | F17: 5000 | G17: 2000 | H17: 0 | W17: =SUM(D17:V17) -> 52000 | Z17: =SUM(W17:Y17) -> 52000 | AB17: 未作成 | AC17: =C17-M17 -> 128000
A18: 601 | B18: 榎本裕子 | C18: 134000 | D18: 40000 | E18: 5000 | F18: 5000 | G18: 2000 | H18: 10000 | W18: =SUM(D18:V18) -> 62000 | Z18: =SUM(W18:Y18) -> 62000 | AA18: 100000 | AB18: 未作成 | AC18: =C18-M18 -> 134000
A19: 608 | D19: 0 | E19: 0 | F19: 0 | G19: 0 | H19: 0 | W19: =SUM(D19:V19) -> 0 | Z19: =SUM(W19:Y19) -> 0 | AA19: 62000 | AB19: 未作成 | AC19: =C19-M19 -> 0
A20: 703 | B20: 斧義也 | D20: 40000 | E20: 5000 | F20: 5000 | G20: 2000 | H20: 10000 | W20: =SUM(D20:V20) -> 62000 | Z20: =SUM(W20:Y20) -> 62000 | AA20: 80000 | AB20: 未作成 | AC20: =C20-M20 -> 0
A21: 715 | B21: 日川敬達 | D21: 40000 | E21: 5000 | F21: 5000 | G21: 2000 | H21: 10000 | W21: =SUM(D21:V21) -> 62000 | Z21: =SUM(W21:Y21) -> 62000 | AA21: 116000 | AB21: 未作成 | AC21: =C21-M21 -> 0
A22: 716 | B22: 内田克政 | D22: 40000 | E22: 5000 | F22: 5000 | G22: 2000 | H22: 10000 | W22: =SUM(D22:V22) -> 62000 | Z22: =SUM(W22:Y22) -> 62000 | AA22: 通常請求 | AB22: 未作成 | AC22: =C22-M22 -> 0
A23: ='利用者'!A30 | B23: ='利用者'!B30 | W23: =SUM(D23:V23) -> 0 | Z23: =SUM(W23:Y23) -> 0 | AB23: 未作成 | AC23: =C23-M23 -> 0
A24: ='利用者'!A31 | B24: ='利用者'!B31 | W24: =SUM(D24:V24) -> 0 | Z24: =SUM(W24:Y24) -> 0 | AB24: 未作成 | AC24: =C24-M24 -> 0
A25: ='利用者'!A32 | B25: ='利用者'!B32 | W25: =SUM(D25:V25) -> 0 | Z25: =SUM(W25:Y25) -> 0 | AB25: 未作成 | AC25: =C25-M25 -> 0
A26: ='利用者'!A33 | B26: ='利用者'!B33 | W26: =SUM(D26:V26) -> 0 | Z26: =SUM(W26:Y26) -> 0 | AB26: 未作成 | AC26: =C26-M26 -> 0
A27: ='利用者'!A34 | B27: ='利用者'!B34 | W27: =SUM(D27:V27) -> 0 | Z27: =SUM(W27:Y27) -> 0 | AB27: 未作成 | AC27: =C27-M27 -> 0
A28: ='利用者'!A35 | B28: ='利用者'!B35 | W28: =SUM(D28:V28) -> 0 | Z28: =SUM(W28:Y28) -> 0 | AB28: 未作成 | AC28: =C28-M28 -> 0
A29: ='利用者'!A36 | B29: ='利用者'!B36 | W29: =SUM(D29:V29) -> 0 | Z29: =SUM(W29:Y29) -> 0 | AB29: 未作成 | AC29: =C29-M29 -> 0
A30: ='利用者'!A37 | B30: ='利用者'!B37 | W30: =SUM(D30:V30) -> 0 | Z30: =SUM(W30:Y30) -> 0 | AB30: 未作成 | AC30: =C30-M30 -> 0
A31: ='利用者'!A38 | B31: ='利用者'!B38 | W31: =SUM(D31:V31) -> 0 | Z31: =SUM(W31:Y31) -> 0 | AB31: 未作成 | AC31: =C31-M31 -> 0
A32: ='利用者'!A39 | B32: ='利用者'!B39 | W32: =SUM(D32:V32) -> 0 | Z32: =SUM(W32:Y32) -> 0 | AB32: 未作成 | AC32: =C32-M32 -> 0
A33: ='利用者'!A40 | B33: ='利用者'!B40 | W33: =SUM(D33:V33) -> 0 | Z33: =SUM(W33:Y33) -> 0 | AB33: 未作成 | AC33: =C33-M33 -> 0
A34: ='利用者'!A41 | B34: ='利用者'!B41 | W34: =SUM(D34:V34) -> 0 | Z34: =SUM(W34:Y34) -> 0 | AB34: 未作成 | AC34: =C34-M34 -> 0
... A109: ='利用者'!A116 | B109: ='利用者'!B116 | W109: =SUM(D109:V109) -> 0 | Z109: =SUM(W109:Y109) -> 0 | AB109: 未作成 | AC109: =C109-M109 -> 0
W110: =SUM(D110:V110) -> 0 | Z110: =SUM(W110:Y110) -> 0 | AB110: 未作成 | AC110: =C110-M110 -> 0
A111: 合計 | D111: =SUM(D3:D110) -> 480000 | E111: =SUM(E3:E110) -> 60000 | F111: =SUM(F3:F110) -> 60000 | G111: =SUM(G3:G110) -> 24000 | H111: =SUM(H3:H110) -> 100000 | I111: =SUM(I3:I110) -> 0 | J111: =SUM(J3:J110) -> 0 | K111: =SUM(K3:K110) -> 0 | ... Y111: =SUM(Y3:Y110) -> 0 | Z111: =SUM(W111:Y111) -> 724000

Sheet R8.1
A1: 46053 | C1: 請求 | D1: D | E1: E | F1: F | G1: G | H1: H | I1: I | J1: J | K1: K | L1: L | M1: M | N1: N | O1: O | P1: P | Q1: Q | R1: R | S1: S | T1: T | U1: U | V1: V | W1: W | X1: X | Y1: Y | Z1: Z | AA1: AA | AB1: AB
A2: 居室 | B2: 利用者名 | C2: 分納残 | D2: 家賃 | E2: 管理費 | F2: 共益費 | G2: 水道料金 | H2: 定額光熱費 | I2: 食事 | J2: 調整額 | K2: オムツ | L2: 日用品 | M2: 分割支払い | N2: 事務手数料 | O2: デイサービス | P2: 福祉用具 | Q2: しろくま薬局 | R2: 往診診療費 | S2: サポート費 | T2: その他 | W2: 計 | X2: 一部負担(介護) | Y2: 一部負担(看護) | Z2: 合計 | AA2: 備考 | AB2: 請求書 | AC2: 分割残高
A3: 108 | B3: 杉田誠一 | C3: 185667 | D3: 40000 | E3: 5000 | F3: 5000 | G3: 2000 | H3: 10000 | I3: 44330 | J3: -90109 | K3: 3751 | L3: 2263 | O3: 10108 | Q3: 17408 | W3: =SUM(D3:V3) -> 49751 | X3: 30249 | Z3: =SUM(W3:Y3) -> 80000 | AA3: 80000 | AB3: 未作成 | AC3: =C3-M3 -> 185667
A4: 206 | B4: 林郁子 | D4: 40000 | E4: 5000 | F4: 5000 | G4: 2000 | H4: 10000 | I4: 44330 | Q4: 2468 | W4: =SUM(D4:V4) -> 108798 | X4: 23896 | Y4: 2500 | Z4: =SUM(W4:Y4) -> 135194 | AA4: 通常請求 | AB4: 未作成 | AC4: =C4-M4 -> 0
A5: 210 | B5: 西中照彦 | C5: 130000 | D5: 0 | E5: 0 | F5: 0 | G5: 0 | H5: 0 | M5: 10000 | W5: =SUM(D5:V5) -> 10000 | Z5: =SUM(W5:Y5) -> 10000 | AA5: 9○+初期1 | AB5: 未作成 | AC5: =C5-M5 -> 120000
A6: 211 | W6: =SUM(D6:V6) -> 0 | Z6: =SUM(W6:Y6) -> 0 | AB6: 未作成 | AC6: =C6-M6 -> 0
A7: 212 | B7: 長谷部融子 | D7: 40000 | E7: 5000 | F7: 5000 | G7: 2000 | H7: 10000 | I7: 39380 | K7: 11253 | L7: 2263 | Q7: 7148 | W7: =SUM(D7:V7) -> 122044 | X7: 28693 | Z7: =SUM(W7:Y7) -> 150737 | AA7: 通常請求 | AB7: 未作成 | AC7: =C7-M7 -> 0
A8: 303 | Q8: 59072 | W8: =SUM(D8:V8) -> 59072 | Z8: =SUM(W8:Y8) -> 59072 | AB8: 未作成 | AC8: =C8-M8 -> 0
A9: 401 | W9: =SUM(D9:V9) -> 0 | Z9: =SUM(W9:Y9) -> 0 | AB9: 未作成 | AC9: =C9-M9 -> 0
A10: 402 | B10: 鈴木信子 | D10: 40000 | E10: 5000 | F10: 5000 | G10: 2000 | H10: 10000 | I10: 44330 | J10: -53912 | K10: 16895 | L10: 2263 | O10: 8440 | Q10: 4038 | W10: =SUM(D10:V10) -> 84054 | X10: 20946 | Z10: =SUM(W10:Y10) -> 105000 | AA10: 105000 | AB10: 未作成 | AC10: =C10-M10 -> 0
A11: 403 | B11: 上村春子 | C11: 100000 | D11: 40000 | E11: 5000 | F11: 5000 | G11: 2000 | H11: 10000 | K11: =11253-1452 -> 9801 | L11: =2263-292 -> 1971 | M11: 10000 | W11: =SUM(D11:V11) -> 83772 | X11: 25141 | Z11: =SUM(W11:Y11) -> 108913 | AA11: 10○+初期1万 | AB11: 未作成 | AC11: =C11-M11 -> 90000 | AD11: 入院中一旦請求停止
A12: 405 | B12: 河田晃晁 | D12: 40000 | E12: 5000 | F12: 5000 | G12: 2000 | I12: 44330 | W12: =SUM(D12:V12) -> 96330 | X12: 0 | Z12: =SUM(W12:Y12) -> 96330 | AB12: 未作成 | AC12: =C12-M12 -> 0
A13: 406 | W13: =SUM(D13:V13) -> 0 | Z13: =SUM(W13:Y13) -> 0 | AB13: 未作成 | AC13: =C13-M13 -> 0
A14: 407 | B14: 北村繁弘 | D14: 40000 | E14: 5000 | F14: 5000 | G14: 2000 | H14: 10000 | I14: 39930 | J14: -49888 | K14: 7502 | L14: 2263 | Q14: 8928 | W14: =SUM(D14:V14) -> 70735 | X14: 24265 | Y14: 5000 | Z14: =SUM(W14:Y14) -> 100000 | AA14: 100000 | AB14: 未作成 | AC14: =C14-M14 -> 0
A15: 408 | W15: =SUM(D15:V15) -> 0 | Z15: =SUM(W15:Y15) -> 0 | AB15: 未作成 | AC15: =C15-M15 -> 0
A16: 415 | B16: 金坂孝信 | C16: 128000 | D16: 40000 | E16: 5000 | F16: 5000 | G16: 2000 | H16: 0 | M16: 5000 | W16: =SUM(D16:V16) -> 57000 | Z16: =SUM(W16:Y16) -> 57000 | AB16: 未作成 | AC16: =C16-M16 -> 123000
A17: 601 | B17: 榎本裕子 | C17: 134000 | D17: 40000 | E17: 5000 | F17: 5000 | G17: 2000 | H17: 10000 | I17: 42130 | J17: -66911 | K17: 7502 | L17: 4495 | O17: 10017 | Q17: 5468 | W17: =SUM(D17:V17) -> 64701 | X17: 35299 | Z17: =SUM(W17:Y17) -> 100000 | AA17: 100000 | AB17: 未作成 | AC17: =C17-M17 -> 134000
A18: 608 | D18: 0 | E18: 0 | F18: 0 | G18: 0 | H18: 0 | W18: =SUM(D18:V18) -> 0 | Z18: =SUM(W18:Y18) -> 0 | AA18: 62000 | AB18: 未作成 | AC18: =C18-M18 -> 0
A19: 703 | B19: 斧義也 | D19: 40000 | E19: 5000 | F19: 5000 | G19: 2000 | H19: 10000 | I19: 44330 | J19: -110783 | K19: 28148 | L19: 4495 | O19: 14371 | Q19: 9338 | W19: =SUM(D19:V19) -> 51899 | X19: 23101 | Y19: 5000 | Z19: =SUM(W19:Y19) -> 80000 | AA19: 80000 | AB19: 未作成 | AC19: =C19-M19 -> 0
A20: 715 | B20: 日川敬達 | D20: 40000 | E20: 5000 | F20: 5000 | G20: 2000 | H20: 10000 | I20: 44330 | W20: =SUM(D20:V20) -> 106330 | Z20: =SUM(W20:Y20) -> 106330 | AA20: 116000 | AB20: 未作成 | AC20: =C20-M20 -> 0
A21: 716 | B21: 内田克政 | D21: 40000 | E21: 5000 | F21: 5000 | G21: 2000 | H21: 10000 | I21: 19800 | W21: =SUM(D21:V21) -> 81800 | Z21: =SUM(W21:Y21) -> 81800 | AA21: 通常請求 | AB21: 未作成 | AC21: =C21-M21 -> 0
A22: ='利用者'!A30 | B22: ='利用者'!B30 | W22: =SUM(D22:V22) -> 0 | Z22: =SUM(W22:Y22) -> 0 | AB22: 未作成 | AC22: =C22-M22 -> 0
A23: ='利用者'!A31 | B23: ='利用者'!B31 | W23: =SUM(D23:V23) -> 0 | Z23: =SUM(W23:Y23) -> 0 | AB23: 未作成 | AC23: =C23-M23 -> 0
A24: ='利用者'!A32 | B24: ='利用者'!B32 | W24: =SUM(D24:V24) -> 0 | Z24: =SUM(W24:Y24) -> 0 | AB24: 未作成 | AC24: =C24-M24 -> 0
A25: ='利用者'!A33 | B25: ='利用者'!B33 | W25: =SUM(D25:V25) -> 0 | Z25: =SUM(W25:Y25) -> 0 | AB25: 未作成 | AC25: =C25-M25 -> 0
A26: ='利用者'!A34 | B26: ='利用者'!B34 | W26: =SUM(D26:V26) -> 0 | Z26: =SUM(W26:Y26) -> 0 | AB26: 未作成 | AC26: =C26-M26 -> 0
A27: ='利用者'!A35 | B27: ='利用者'!B35 | W27: =SUM(D27:V27) -> 0 | Z27: =SUM(W27:Y27) -> 0 | AB27: 未作成 | AC27: =C27-M27 -> 0
A28: ='利用者'!A36 | B28: ='利用者'!B36 | W28: =SUM(D28:V28) -> 0 | Z28: =SUM(W28:Y28) -> 0 | AB28: 未作成 | AC28: =C28-M28 -> 0
A29: ='利用者'!A37 | B29: ='利用者'!B37 | W29: =SUM(D29:V29) -> 0 | Z29: =SUM(W29:Y29) -> 0 | AB29: 未作成 | AC29: =C29-M29 -> 0
A30: ='利用者'!A38 | B30: ='利用者'!B38 | W30: =SUM(D30:V30) -> 0 | Z30: =SUM(W30:Y30) -> 0 | AB30: 未作成 | AC30: =C30-M30 -> 0
A31: ='利用者'!A39 | B31: ='利用者'!B39 | W31: =SUM(D31:V31) -> 0 | Z31: =SUM(W31:Y31) -> 0 | AB31: 未作成 | AC31: =C31-M31 -> 0
A32: ='利用者'!A40 | B32: ='利用者'!B40 | W32: =SUM(D32:V32) -> 0 | Z32: =SUM(W32:Y32) -> 0 | AB32: 未作成 | AC32: =C32-M32 -> 0
A33: ='利用者'!A41 | B33: ='利用者'!B41 | W33: =SUM(D33:V33) -> 0 | Z33: =SUM(W33:Y33) -> 0 | AB33: 未作成 | AC33: =C33-M33 -> 0
... A108: ='利用者'!A116 | B108: ='利用者'!B116 | W108: =SUM(D108:V108) -> 0 | Z108: =SUM(W108:Y108) -> 0 | AB108: 未作成 | AC108: =C108-M108 -> 0
W109: =SUM(D109:V109) -> 0 | Z109: =SUM(W109:Y109) -> 0 | AB109: 未作成 | AC109: =C109-M109 -> 0
A110: 合計 | D110: =SUM(D3:D109) -> 480000 | E110: =SUM(E3:E109) -> 60000 | F110: =SUM(F3:F109) -> 60000 | G110: =SUM(G3:G109) -> 24000 | H110: =SUM(H3:H109) -> 100000 | I110: =SUM(I3:I109) -> 407220 | J110: =SUM(J3:J109) -> -371603 | K110: =SUM(K3:K109) -> 84852 | ... Y110: =SUM(Y3:Y109) -> 12500 | Z110: =SUM(W110:Y110) -> 1270376

Sheet R7.12
A1: 46022 | C1: 請求 | D1: D | E1: E | F1: F | G1: G | H1: H | I1: I | J1: J | K1: K | L1: L | M1: M | N1: N | O1: O | P1: P | Q1: Q | R1: R | S1: S | T1: T | U1: U | V1: V | W1: W | X1: X | Y1: Y | Z1: Z | AA1: AA | AB1: AB
A2: 居室 | B2: 利用者名 | C2: 分納残 | D2: 家賃 | E2: 管理費 | F2: 共益費 | G2: 水道料金 | H2: 定額光熱費 | I2: 食事 | J2: 調整額 | K2: オムツ | L2: 日用品 | M2: 分割支払い | N2: 事務手数料 | O2: デイサービス | P2: 福祉用具 | Q2: しろくま薬局 | R2: 往診診療費 | S2: サポート費 | T2: その他 | W2: 計 | X2: 一部負担(介護) | Y2: 一部負担(看護) | Z2: 合計 | AA2: 備考 | AB2: 請求書 | AC2: 分割残高
A3: 108 | B3: 杉田誠一 | C3: 185667 | D3: 40000 | E3: 5000 | F3: 5000 | G3: 2000 | H3: 10000 | I3: 44330 | J3: -89656 | K3: 3751 | L3: 2263 | O3: 9042 | Q3: 12772 | W3: =SUM(D3:V3) -> 44502 | X3: 30498 | Y3: 5000 | Z3: =SUM(W3:Y3) -> 80000 | AA3: 80000 | AB3: 未作成 | AC3: =C3-M3 -> 185667
A4: 206 | B4: 林郁子 | D4: 40000 | E4: 5000 | F4: 5000 | G4: 2000 | H4: 10000 | I4: 44330 | Q4: 2932 | W4: =SUM(D4:V4) -> 109262 | X4: 22869 | Y4: 2500 | Z4: =SUM(W4:Y4) -> 134631 | AA4: 通常請求 | AB4: 未作成 | AC4: =C4-M4 -> 0
A5: 210 | B5: 西中照彦 | C5: 140000 | D5: 0 | E5: 0 | F5: 0 | G5: 0 | H5: 0 | M5: 10000 | Q5: 3882 | W5: =SUM(D5:V5) -> 13882 | Z5: =SUM(W5:Y5) -> 13882 | AA5: 9○+初期1 | AB5: 未作成 | AC5: =C5-M5 -> 130000
A6: 211 | W6: =SUM(D6:V6) -> 0 | Z6: =SUM(W6:Y6) -> 0 | AB6: 未作成 | AC6: =C6-M6 -> 0
A7: 212 | B7: 長谷部融子 | D7: 40000 | E7: 5000 | F7: 5000 | G7: 2000 | H7: 10000 | I7: 39380 | K7: 11253 | L7: 2263 | Q7: 7622 | W7: =SUM(D7:V7) -> 122518 | X7: 33605 | Z7: =SUM(W7:Y7) -> 156123 | AA7: 通常請求 | AB7: 未作成 | AC7: =C7-M7 -> 0
A8: 303 | B8: 金澤喜乎 | W8: =SUM(D8:V8) -> 0 | Z8: =SUM(W8:Y8) -> 0 | AB8: 未作成 | AC8: =C8-M8 -> 0
A9: 401 | W9: =SUM(D9:V9) -> 0 | Z9: =SUM(W9:Y9) -> 0 | AB9: 未作成 | AC9: =C9-M9 -> 0
A10: 402 | B10: 鈴木信子 | D10: 40000 | E10: 5000 | F10: 5000 | G10: 2000 | H10: 10000 | I10: 44330 | J10: -51973 | K10: 16895 | L10: 2263 | O10: 6596 | Q10: 4162 | W10: =SUM(D10:V10) -> 84273 | X10: 20727 | Z10: =SUM(W10:Y10) -> 105000 | AA10: 105000 | AB10: 未作成 | AC10: =C10-M10 -> 0
A11: 403 | B11: 上村春子 | C11: 110000 | D11: 40000 | E11: 5000 | F11: 5000 | G11: 2000 | H11: 10000 | K11: 11253 | L11: 2263 | M11: 10000 | W11: =SUM(D11:V11) -> 85516 | Z11: =SUM(W11:Y11) -> 85516 | AA11: 10○+初期1万 | AB11: 未作成 | AC11: =C11-M11 -> 100000 | AD11: 入院中一旦請求停止
A12: 405 | B12: 河田晃晁 | D12: 40000 | E12: 5000 | F12: 5000 | G12: 2000 | I12: 44330 | W12: =SUM(D12:V12) -> 96330 | Z12: =SUM(W12:Y12) -> 96330 | AB12: 未作成 | AC12: =C12-M12 -> 0
A13: 406 | W13: =SUM(D13:V13) -> 0 | Z13: =SUM(W13:Y13) -> 0 | AB13: 未作成 | AC13: =C13-M13 -> 0
A14: 407 | B14: 北村繁弘 | D14: 40000 | E14: 5000 | F14: 5000 | G14: 2000 | H14: 10000 | I14: 39930 | J14: -120573 | K14: 7502 | L14: 2263 | Q14: 28878 | W14: =SUM(D14:V14) -> 20000 | X14: 24290 | Y14: 55710 | Z14: =SUM(W14:Y14) -> 100000 | AA14: 100000 | AB14: 未作成 | AC14: =C14-M14 -> 0
A15: 408 | W15: =SUM(D15:V15) -> 0 | Z15: =SUM(W15:Y15) -> 0 | AB15: 未作成 | AC15: =C15-M15 -> 0
A16: 415 | B16: 金坂孝信 | C16: 133000 | D16: 40000 | E16: 5000 | F16: 5000 | G16: 2000 | H16: 0 | M16: 5000 | W16: =SUM(D16:V16) -> 57000 | Z16: =SUM(W16:Y16) -> 57000 | AB16: 未作成 | AC16: =C16-M16 -> 128000
A17: 601 | B17: 榎本裕子 | C17: 134000 | D17: 40000 | E17: 5000 | F17: 5000 | G17: 2000 | H17: 10000 | I17: 41580 | J17: -64229 | K17: 7502 | L17: 4495 | O17: 8013 | Q17: 5262 | W17: =SUM(D17:V17) -> 64623 | X17: 35377 | Z17: =SUM(W17:Y17) -> 100000 | AA17: 100000 | AB17: 未作成 | AC17: =C17-M17 -> 134000
A18: 608 | B18: 西川太 | D18: 0 | E18: 0 | F18: 0 | G18: 0 | H18: 0 | W18: =SUM(D18:V18) -> 0 | Z18: =SUM(W18:Y18) -> 0 | AA18: 62000 | AB18: 未作成 | AC18: =C18-M18 -> 0
A19: 703 | B19: 斧義也 | D19: 40000 | E19: 5000 | F19: 5000 | G19: 2000 | H19: 10000 | I19: 44330 | J19: -108551 | K19: 28148 | L19: 4495 | O19: 13305 | Q19: 8722 | W19: =SUM(D19:V19) -> 52449 | X19: 22551 | Y19: 5000 | Z19: =SUM(W19:Y19) -> 80000 | AA19: 80000 | AB19: 未作成 | AC19: =C19-M19 -> 0
A20: 715 | B20: 日川敬達 | D20: 40000 | E20: 5000 | F20: 5000 | G20: 2000 | H20: 10000 | I20: 44330 | L20: 2263 | W20: =SUM(D20:V20) -> 108593 | Z20: =SUM(W20:Y20) -> 108593 | AA20: 116000 | AB20: 未作成 | AC20: =C20-M20 -> 0
A21: 716 | B21: 内田克政 | D21: 40000 | E21: 5000 | F21: 5000 | G21: 2000 | H21: 10000 | I21: 32450 | W21: =SUM(D21:V21) -> 94450 | Z21: =SUM(W21:Y21) -> 94450 | AA21: 通常請求 | AB21: 未作成 | AC21: =C21-M21 -> 0
A22: ='利用者'!A30 | B22: ='利用者'!B30 | W22: =SUM(D22:V22) -> 0 | Z22: =SUM(W22:Y22) -> 0 | AB22: 未作成 | AC22: =C22-M22 -> 0
A23: ='利用者'!A31 | B23: ='利用者'!B31 | W23: =SUM(D23:V23) -> 0 | Z23: =SUM(W23:Y23) -> 0 | AB23: 未作成 | AC23: =C23-M23 -> 0
A24: ='利用者'!A32 | B24: ='利用者'!B32 | W24: =SUM(D24:V24) -> 0 | Z24: =SUM(W24:Y24) -> 0 | AB24: 未作成 | AC24: =C24-M24 -> 0
A25: ='利用者'!A33 | B25: ='利用者'!B33 | W25: =SUM(D25:V25) -> 0 | Z25: =SUM(W25:Y25) -> 0 | AB25: 未作成 | AC25: =C25-M25 -> 0
A26: ='利用者'!A34 | B26: ='利用者'!B34 | W26: =SUM(D26:V26) -> 0 | Z26: =SUM(W26:Y26) -> 0 | AB26: 未作成 | AC26: =C26-M26 -> 0
A27: ='利用者'!A35 | B27: ='利用者'!B35 | W27: =SUM(D27:V27) -> 0 | Z27: =SUM(W27:Y27) -> 0 | AB27: 未作成 | AC27: =C27-M27 -> 0
A28: ='利用者'!A36 | B28: ='利用者'!B36 | W28: =SUM(D28:V28) -> 0 | Z28: =SUM(W28:Y28) -> 0 | AB28: 未作成 | AC28: =C28-M28 -> 0
A29: ='利用者'!A37 | B29: ='利用者'!B37 | W29: =SUM(D29:V29) -> 0 | Z29: =SUM(W29:Y29) -> 0 | AB29: 未作成 | AC29: =C29-M29 -> 0
A30: ='利用者'!A38 | B30: ='利用者'!B38 | W30: =SUM(D30:V30) -> 0 | Z30: =SUM(W30:Y30) -> 0 | AB30: 未作成 | AC30: =C30-M30 -> 0
A31: ='利用者'!A39 | B31: ='利用者'!B39 | W31: =SUM(D31:V31) -> 0 | Z31: =SUM(W31:Y31) -> 0 | AB31: 未作成 | AC31: =C31-M31 -> 0
A32: ='利用者'!A40 | B32: ='利用者'!B40 | W32: =SUM(D32:V32) -> 0 | Z32: =SUM(W32:Y32) -> 0 | AB32: 未作成 | AC32: =C32-M32 -> 0
A33: ='利用者'!A41 | B33: ='利用者'!B41 | W33: =SUM(D33:V33) -> 0 | Z33: =SUM(W33:Y33) -> 0 | AB33: 未作成 | AC33: =C33-M33 -> 0
... A108: ='利用者'!A116 | B108: ='利用者'!B116 | W108: =SUM(D108:V108) -> 0 | Z108: =SUM(W108:Y108) -> 0 | AB108: 未作成 | AC108: =C108-M108 -> 0
W109: =SUM(D109:V109) -> 0 | Z109: =SUM(W109:Y109) -> 0 | AB109: 未作成 | AC109: =C109-M109 -> 0
A110: 合計 | D110: =SUM(D3:D109) -> 480000 | E110: =SUM(E3:E109) -> 60000 | F110: =SUM(F3:F109) -> 60000 | G110: =SUM(G3:G109) -> 24000 | H110: =SUM(H3:H109) -> 100000 | I110: =SUM(I3:I109) -> 419320 | J110: =SUM(J3:J109) -> -434982 | K110: =SUM(K3:K109) -> 86304 | ... Y110: =SUM(Y3:Y109) -> 68210 | Z110: =SUM(W110:Y110) -> 1211525

Sheet R7.11
A1: 45991 | C1: 請求 | D1: D | E1: E | F1: F | G1: G | H1: H | I1: I | J1: J | K1: K | L1: L | M1: M | N1: N | O1: O | P1: P | Q1: Q | R1: R | S1: S | T1: T | U1: U | V1: V | W1: W | X1: X | Y1: Y | Z1: Z | AA1: AA | AB1: AB
A2: 居室 | B2: 利用者名 | C2: 分納残 | D2: 家賃 | E2: 管理費 | F2: 共益費 | G2: 水道料金 | H2: 定額光熱費 | I2: 食事 | J2: 調整額 | K2: オムツ | L2: 日用品 | M2: 分割支払い | N2: 事務手数料 | O2: デイサービス | P2: 福祉用具 | Q2: しろくま薬局 | R2: 往診診療費 | S2: サポート費 | T2: その他 | W2: 計 | X2: 一部負担(介護) | Y2: 一部負担(看護) | Z2: 合計 | AA2: 備考 | AB2: 請求書 | AC2: 分割残高
A3: 108 | B3: 杉田誠一 | C3: 185667 | D3: 40000 | E3: 5000 | F3: 5000 | G3: 2000 | H3: 10000 | I3: 42900 | J3: -91950 | K3: 3630 | L3: 2190 | O3: 10084 | Q3: 15946 | W3: =SUM(D3:V3) -> 44800 | X3: 30200 | Y3: 5000 | Z3: =SUM(W3:Y3) -> 80000 | AA3: 80000 | AB3: 未作成 | AC3: =C3-M3 -> 185667
A4: 206 | B4: 林郁子 | D4: 40000 | E4: 5000 | F4: 5000 | G4: 2000 | H4: 10000 | I4: 42900 | Q4: 5476 | W4: =SUM(D4:V4) -> 110376 | X4: 23921 | Y4: 2500 | Z4: =SUM(W4:Y4) -> 136797 | AA4: 100000 | AB4: 未作成 | AC4: =C4-M4 -> 0
A5: 210 | B5: 西中照彦 | C5: 150000 | D5: 0 | E5: 0 | F5: 0 | G5: 0 | H5: 10000 | I5: 24310 | M5: 10000 | W5: =SUM(D5:V5) -> 44310 | X5: 0 | Z5: =SUM(W5:Y5) -> 44310 | AA5: 9○+初期1 | AB5: 未作成 | AC5: =C5-M5 -> 140000
A6: 211 | W6: =SUM(D6:V6) -> 0 | Z6: =SUM(W6:Y6) -> 0 | AB6: 未作成 | AC6: =C6-M6 -> 0
A7: 212 | B7: 長谷部融子 | D7: 40000 | E7: 5000 | F7: 5000 | G7: 2000 | H7: 10000 | I7: 40700 | K7: 10890 | L7: 2190 | Q7: 8722 | W7: =SUM(D7:V7) -> 124502 | X7: 34054 | Z7: =SUM(W7:Y7) -> 158556 | AA7: 通常請求 | AB7: 未作成 | AC7: =C7-M7 -> 0
A8: 303 | B8: 金澤喜乎 | D8: 40000 | E8: 5000 | F8: 5000 | G8: 2000 | H8: 10000 | W8: =SUM(D8:V8) -> 62000 | Z8: =SUM(W8:Y8) -> 62000 | AA8: 12万程度 | AB8: 未作成 | AC8: =C8-M8 -> 0
A9: 401 | W9: =SUM(D9:V9) -> 0 | Z9: =SUM(W9:Y9) -> 0 | AB9: 未作成 | AC9: =C9-M9 -> 0
A10: 402 | B10: 鈴木信子 | D10: 40000 | E10: 5000 | F10: 5000 | G10: 2000 | H10: 10000 | I10: 42900 | J10: -52648 | K10: 16350 | L10: 2190 | O10: 7517 | Q10: 4892 | W10: =SUM(D10:V10) -> 83201 | X10: 21799 | Z10: =SUM(W10:Y10) -> 105000 | AA10: 105000 | AB10: 未作成 | AC10: =C10-M10 -> 0
A11: 403 | B11: 上村春子 | C11: 120000 | D11: 40000 | E11: 5000 | F11: 5000 | G11: 2000 | H11: 10000 | J11: -72000 | M11: 10000 | W11: =SUM(D11:V11) -> 0 | Z11: =SUM(W11:Y11) -> 0 | AA11: 10○+初期1万 | AB11: 未作成 | AC11: =C11-M11 -> 110000 | AD11: 入院中一旦請求停止
A12: 405 | B12: 河田晃晁 | D12: 40000 | E12: 5000 | F12: 5000 | G12: 2000 | I12: 42900 | W12: =SUM(D12:V12) -> 94900 | X12: 14534 | Z12: =SUM(W12:Y12) -> 109434 | AB12: 未作成 | AC12: =C12-M12 -> 0
A13: 406 | W13: =SUM(D13:V13) -> 0 | Z13: =SUM(W13:Y13) -> 0 | AB13: 未作成 | AC13: =C13-M13 -> 0
A14: 407 | B14: 北村繁弘 | D14: 40000 | E14: 5000 | F14: 5000 | G14: 2000 | H14: 10000 | I14: 37950 | J14: -34911 | K14: 7260 | L14: 2190 | W14: =SUM(D14:V14) -> 74489 | X14: 25511 | Z14: =SUM(W14:Y14) -> 100000 | AA14: 100000 | AB14: 未作成 | AC14: =C14-M14 -> 0
A15: 408 | W15: =SUM(D15:V15) -> 0 | Z15: =SUM(W15:Y15) -> 0 | AB15: 未作成 | AC15: =C15-M15 -> 0
W16: =SUM(D16:V16) -> 0 | Z16: =SUM(W16:Y16) -> 0 | AB16: 未作成 | AC16: =C16-M16 -> 0
A17: 601 | B17: 榎本裕子 | C17: 134000 | D17: 40000 | E17: 5000 | F17: 5000 | G17: 2000 | H17: 10000 | I17: 40700 | J17: -62811 | K17: 7260 | L17: 4350 | O17: 8013 | Q17: 4592 | W17: =SUM(D17:V17) -> 64104 | X17: 35896 | Z17: =SUM(W17:Y17) -> 100000 | AA17: 100000 | AB17: 未作成 | AC17: =C17-M17 -> 134000
A18: 608 | B18: 西川太 | D18: 40000 | E18: 5000 | F18: 5000 | G18: 2000 | H18: 10000 | W18: =SUM(D18:V18) -> 62000 | X18: 0 | Z18: =SUM(W18:Y18) -> 62000 | AA18: 62000 | AB18: 未作成 | AC18: =C18-M18 -> 0
A19: 703 | B19: 斧義也 | D19: 40000 | E19: 5000 | F19: 5000 | G19: 2000 | H19: 10000 | I19: 42900 | J19: -112450 | K19: 27240 | L19: 4350 | O19: 13305 | Q19: 14136 | W19: =SUM(D19:V19) -> 51481 | X19: 23519 | Y19: 5000 | Z19: =SUM(W19:Y19) -> 80000 | AA19: 80000 | AB19: 未作成 | AC19: =C19-M19 -> 0
A20: 715 | B20: 日川敬達 | D20: 40000 | E20: 5000 | F20: 5000 | G20: 2000 | H20: 10000 | I20: 42900 | L20: 2190 | Q20: 50 | W20: =SUM(D20:V20) -> 107140 | X20: 0 | Z20: =SUM(W20:Y20) -> 107140 | AA20: 116000 | AB20: 未作成 | AC20: =C20-M20 -> 0
A21: 716 | B21: 内田克政 | D21: 40000 | E21: 5000 | F21: 5000 | G21: 2000 | H21: 0 | W21: =SUM(D21:V21) -> 52000 | X21: 0 | Z21: =SUM(W21:Y21) -> 52000 | AA21: 通常請求 | AB21: 未作成 | AC21: =C21-M21 -> 0
A22: ='利用者'!A30 | B22: ='利用者'!B30 | W22: =SUM(D22:V22) -> 0 | Z22: =SUM(W22:Y22) -> 0 | AB22: 未作成 | AC22: =C22-M22 -> 0
A23: ='利用者'!A31 | B23: ='利用者'!B31 | W23: =SUM(D23:V23) -> 0 | Z23: =SUM(W23:Y23) -> 0 | AB23: 未作成 | AC23: =C23-M23 -> 0
A24: ='利用者'!A32 | B24: ='利用者'!B32 | W24: =SUM(D24:V24) -> 0 | Z24: =SUM(W24:Y24) -> 0 | AB24: 未作成 | AC24: =C24-M24 -> 0
A25: ='利用者'!A33 | B25: ='利用者'!B33 | W25: =SUM(D25:V25) -> 0 | Z25: =SUM(W25:Y25) -> 0 | AB25: 未作成 | AC25: =C25-M25 -> 0
A26: ='利用者'!A34 | B26: ='利用者'!B34 | W26: =SUM(D26:V26) -> 0 | Z26: =SUM(W26:Y26) -> 0 | AB26: 未作成 | AC26: =C26-M26 -> 0
A27: ='利用者'!A35 | B27: ='利用者'!B35 | W27: =SUM(D27:V27) -> 0 | Z27: =SUM(W27:Y27) -> 0 | AB27: 未作成 | AC27: =C27-M27 -> 0
A28: ='利用者'!A36 | B28: ='利用者'!B36 | W28: =SUM(D28:V28) -> 0 | Z28: =SUM(W28:Y28) -> 0 | AB28: 未作成 | AC28: =C28-M28 -> 0
A29: ='利用者'!A37 | B29: ='利用者'!B37 | W29: =SUM(D29:V29) -> 0 | Z29: =SUM(W29:Y29) -> 0 | AB29: 未作成 | AC29: =C29-M29 -> 0
A30: ='利用者'!A38 | B30: ='利用者'!B38 | W30: =SUM(D30:V30) -> 0 | Z30: =SUM(W30:Y30) -> 0 | AB30: 未作成 | AC30: =C30-M30 -> 0
A31: ='利用者'!A39 | B31: ='利用者'!B39 | W31: =SUM(D31:V31) -> 0 | Z31: =SUM(W31:Y31) -> 0 | AB31: 未作成 | AC31: =C31-M31 -> 0
A32: ='利用者'!A40 | B32: ='利用者'!B40 | W32: =SUM(D32:V32) -> 0 | Z32: =SUM(W32:Y32) -> 0 | AB32: 未作成 | AC32: =C32-M32 -> 0
A33: ='利用者'!A41 | B33: ='利用者'!B41 | W33: =SUM(D33:V33) -> 0 | Z33: =SUM(W33:Y33) -> 0 | AB33: 未作成 | AC33: =C33-M33 -> 0
... A108: ='利用者'!A116 | B108: ='利用者'!B116 | W108: =SUM(D108:V108) -> 0 | Z108: =SUM(W108:Y108) -> 0 | AB108: 未作成 | AC108: =C108-M108 -> 0
W109: =SUM(D109:V109) -> 0 | Z109: =SUM(W109:Y109) -> 0 | AB109: 未作成 | AC109: =C109-M109 -> 0
A110: 合計 | D110: =SUM(D3:D109) -> 520000 | E110: =SUM(E3:E109) -> 65000 | F110: =SUM(F3:F109) -> 65000 | G110: =SUM(G3:G109) -> 26000 | H110: =SUM(H3:H109) -> 120000 | I110: =SUM(I3:I109) -> 401060 | J110: =SUM(J3:J109) -> -426770 | K110: =SUM(K3:K109) -> 72630 | ... Y110: =SUM(Y3:Y109) -> 12500 | Z110: =SUM(W110:Y110) -> 1197237

Sheet R7.10
A1: 45961 | C1: 請求 | D1: D | E1: E | F1: F | G1: G | H1: H | I1: I | J1: J | K1: K | L1: L | M1: M | N1: N | O1: O | P1: P | Q1: Q | R1: R | S1: S | T1: T | U1: U | V1: V | W1: W | X1: X | Y1: Y | Z1: Z | AA1: AA | AB1: AB
A2: 居室 | B2: 利用者名 | C2: 分納残 | D2: 家賃 | E2: 管理費 | F2: 共益費 | G2: 水道料金 | H2: 定額光熱費 | I2: 食事 | J2: 調整額 | K2: オムツ | L2: 日用品 | M2: 分割支払い | N2: 事務手数料 | O2: デイサービス | P2: 福祉用具 | Q2: しろくま薬局 | R2: 往診診療費 | S2: サポート費 | T2: その他 | W2: 計 | X2: 一部負担(介護) | Y2: 一部負担(看護) | Z2: 合計 | AA2: 備考 | AB2: 請求書 | AC2: 分割残高
A3: 108 | B3: 杉田誠一 | C3: 185667 | D3: 40000 | E3: 5000 | F3: 5000 | G3: 2000 | H3: 10000 | I3: 44330 | J3: -94422 | K3: 3751 | L3: 2263 | Q3: 11580 | W3: =SUM(D3:V3) -> 29502 | X3: 30498 | Y3: =5000+5000+5000+5000 -> 20000 | Z3: =SUM(W3:Y3) -> 80000 | AA3: 80000 | AB3: 未作成 | AC3: =C3-M3 -> 185667
A4: 206 | B4: 林郁子 | D4: 40000 | E4: 5000 | F4: 5000 | G4: 2000 | H4: 10000 | I4: 44330 | J4: -34631 | K4: 0 | L4: 0 | Q4: 2932 | W4: =SUM(D4:V4) -> 74631 | X4: 22869 | Y4: 2500 | Z4: =SUM(W4:Y4) -> 100000 | AA4: 100000 | AB4: 未作成 | AC4: =C4-M4 -> 0
A5: 210 | B5: 西中照彦 | C5: 160000 | D5: 40000 | E5: 5000 | F5: 5000 | G5: 2000 | H5: 10000 | I5: 13970 | J5: 0 | M5: 10000 | W5: =SUM(D5:V5) -> 85970 | X5: 0 | Z5: =SUM(W5:Y5) -> 85970 | AA5: 9○+初期1 | AB5: 未作成 | AC5: =C5-M5 -> 150000
A6: 211 | W6: =SUM(D6:V6) -> 0 | Z6: =SUM(W6:Y6) -> 0 | AB6: 未作成 | AC6: =C6-M6 -> 0
A7: 212 | B7: 長谷部融子 | D7: 40000 | E7: 5000 | F7: 5000 | G7: 2000 | H7: 10000 | I7: 41580 | J7: 0 | K7: 11253 | L7: 2263 | Q7: 6692 | W7: =SUM(D7:V7) -> 123788 | X7: 33484 | Y7: =18000+18000+18000 -> 54000 | Z7: =SUM(W7:Y7) -> 211272 | AA7: 通常請求 | AB7: 未作成 | AC7: =C7-M7 -> 0
A8: 303 | B8: 金澤喜乎 | D8: 40000 | E8: 5000 | F8: 5000 | G8: 2000 | H8: 10000 | I8: 0 | J8: 0 | K8: 0 | L8: 0 | Q8: 4556 | W8: =SUM(D8:V8) -> 66556 | X8: 19792 | Y8: 5060 | Z8: =SUM(W8:Y8) -> 91408 | AA8: 12万程度 | AB8: 未作成 | AC8: =C8-M8 -> 0
A9: 401 | W9: =SUM(D9:V9) -> 0 | Z9: =SUM(W9:Y9) -> 0 | AB9: 未作成 | AC9: =C9-M9 -> 0
A10: 402 | B10: 鈴木信子 | D10: 40000 | E10: 5000 | F10: 5000 | G10: 2000 | H10: 10000 | I10: 44330 | J10: -44431 | K10: 16895 | L10: 2263 | Q10: 4792 | W10: =SUM(D10:V10) -> 85849 | X10: 19151 | Z10: =SUM(W10:Y10) -> 105000 | AA10: 105000 | AB10: 未作成 | AC10: =C10-M10 -> 0
A11: 403 | B11: 上村春子 | C11: 130000 | D11: 40000 | E11: 5000 | F11: 5000 | G11: 2000 | H11: 10000 | I11: 0 | J11: -90403 | K11: 0 | L11: 0 | M11: 10000 | W11: =SUM(D11:V11) -> -18403 | X11: 18403 | Z11: =SUM(W11:Y11) -> 0 | AA11: 10○+初期1万 | AB11: 未作成 | AC11: =C11-M11 -> 120000 | AD11: 入院中一旦請求停止
A12: 405 | B12: 河田晃晁 | D12: 40000 | E12: 5000 | F12: 5000 | G12: 2000 | I12: 26290 | J12: 0 | W12: =SUM(D12:V12) -> 78290 | X12: 0 | Z12: =SUM(W12:Y12) -> 78290 | AB12: 未作成 | AC12: =C12-M12 -> 0
A13: 406 | W13: =SUM(D13:V13) -> 0 | Z13: =SUM(W13:Y13) -> 0 | AB13: 未作成 | AC13: =C13-M13 -> 0
A14: 407 | B14: 北村繁弘 | D14: 40000 | E14: 5000 | F14: 5000 | G14: 2000 | H14: 10000 | I14: 39380 | J14: -36608 | K14: 7502 | L14: 2263 | W14: =SUM(D14:V14) -> 74537 | X14: 25463 | Z14: =SUM(W14:Y14) -> 100000 | AA14: 100000 | AB14: 未作成 | AC14: =C14-M14 -> 0
A15: 408 | W15: =SUM(D15:V15) -> 0 | Z15: =SUM(W15:Y15) -> 0 | AB15: 未作成 | AC15: =C15-M15 -> 0
W16: =SUM(D16:V16) -> 0 | Z16: =SUM(W16:Y16) -> 0 | AB16: 未作成 | AC16: =C16-M16 -> 0
A17: 601 | B17: 榎本裕子 | C17: 134000 | D17: 40000 | E17: 5000 | F17: 5000 | G17: 2000 | H17: 10000 | I17: 42130 | J17: -64928 | K17: 7502 | L17: 4495 | O17: 10017 | Q17: 4382 | W17: =SUM(D17:V17) -> 65598 | X17: 34402 | Z17: =SUM(W17:Y17) -> 100000 | AA17: 100000 | AB17: 未作成 | AC17: =C17-M17 -> 134000
A18: 608 | B18: 西川太 | D18: 40000 | E18: 5000 | F18: 5000 | G18: 2000 | H18: 10000 | I18: 0 | W18: =SUM(D18:V18) -> 62000 | X18: 0 | Z18: =SUM(W18:Y18) -> 62000 | AA18: 62000 | AB18: 未作成 | AC18: =C18-M18 -> 0
A19: 703 | B19: 斧義也 | D19: 40000 | E19: 5000 | F19: 5000 | G19: 2000 | H19: 10000 | I19: 44330 | J19: -111485 | K19: 28148 | L19: 4495 | Q19: 9792 | W19: =SUM(D19:V19) -> 37280 | X19: 24720 | Y19: 18000 | Z19: =SUM(W19:Y19) -> 80000 | AA19: 80000 | AB19: 未作成 | AC19: =C19-M19 -> 0
A20: 715 | B20: 日川敬達 | D20: 40000 | E20: 5000 | F20: 5000 | G20: 2000 | H20: 10000 | I20: 44330 | K20: 0 | L20: 0 | W20: =SUM(D20:V20) -> 106330 | X20: 0 | Z20: =SUM(W20:Y20) -> 106330 | AA20: 116000 | AB20: 未作成 | AC20: =C20-M20 -> 0
A21: 716 | B21: 内田克政 | D21: 40000 | E21: 5000 | F21: 5000 | G21: 2000 | H21: 0 | I21: 0 | K21: 0 | L21: 0 | W21: =SUM(D21:V21) -> 52000 | X21: 0 | Z21: =SUM(W21:Y21) -> 52000 | AA21: 通常請求 | AB21: 未作成 | AC21: =C21-M21 -> 0
A22: ='利用者'!A30 | B22: ='利用者'!B30 | W22: =SUM(D22:V22) -> 0 | Z22: =SUM(W22:Y22) -> 0 | AB22: 未作成 | AC22: =C22-M22 -> 0
A23: ='利用者'!A31 | B23: ='利用者'!B31 | W23: =SUM(D23:V23) -> 0 | Z23: =SUM(W23:Y23) -> 0 | AB23: 未作成 | AC23: =C23-M23 -> 0
A24: ='利用者'!A32 | B24: ='利用者'!B32 | W24: =SUM(D24:V24) -> 0 | Z24: =SUM(W24:Y24) -> 0 | AB24: 未作成 | AC24: =C24-M24 -> 0
A25: ='利用者'!A33 | B25: ='利用者'!B33 | W25: =SUM(D25:V25) -> 0 | Z25: =SUM(W25:Y25) -> 0 | AB25: 未作成 | AC25: =C25-M25 -> 0
A26: ='利用者'!A34 | B26: ='利用者'!B34 | W26: =SUM(D26:V26) -> 0 | Z26: =SUM(W26:Y26) -> 0 | AB26: 未作成 | AC26: =C26-M26 -> 0
A27: ='利用者'!A35 | B27: ='利用者'!B35 | W27: =SUM(D27:V27) -> 0 | Z27: =SUM(W27:Y27) -> 0 | AB27: 未作成 | AC27: =C27-M27 -> 0
A28: ='利用者'!A36 | B28: ='利用者'!B36 | W28: =SUM(D28:V28) -> 0 | Z28: =SUM(W28:Y28) -> 0 | AB28: 未作成 | AC28: =C28-M28 -> 0
A29: ='利用者'!A37 | B29: ='利用者'!B37 | W29: =SUM(D29:V29) -> 0 | Z29: =SUM(W29:Y29) -> 0 | AB29: 未作成 | AC29: =C29-M29 -> 0
A30: ='利用者'!A38 | B30: ='利用者'!B38 | W30: =SUM(D30:V30) -> 0 | Z30: =SUM(W30:Y30) -> 0 | AB30: 未作成 | AC30: =C30-M30 -> 0
A31: ='利用者'!A39 | B31: ='利用者'!B39 | W31: =SUM(D31:V31) -> 0 | Z31: =SUM(W31:Y31) -> 0 | AB31: 未作成 | AC31: =C31-M31 -> 0
A32: ='利用者'!A40 | B32: ='利用者'!B40 | W32: =SUM(D32:V32) -> 0 | Z32: =SUM(W32:Y32) -> 0 | AB32: 未作成 | AC32: =C32-M32 -> 0
A33: ='利用者'!A41 | B33: ='利用者'!B41 | W33: =SUM(D33:V33) -> 0 | Z33: =SUM(W33:Y33) -> 0 | AB33: 未作成 | AC33: =C33-M33 -> 0
... A108: ='利用者'!A116 | B108: ='利用者'!B116 | W108: =SUM(D108:V108) -> 0 | Z108: =SUM(W108:Y108) -> 0 | AB108: 未作成 | AC108: =C108-M108 -> 0
W109: =SUM(D109:V109) -> 0 | Z109: =SUM(W109:Y109) -> 0 | AB109: 未作成 | AC109: =C109-M109 -> 0
A110: 合計 | D110: =SUM(D3:D109) -> 560000 | E110: =SUM(E3:E109) -> 70000 | F110: =SUM(F3:F109) -> 70000 | G110: =SUM(G3:G109) -> 28000 | H110: =SUM(H3:H109) -> 120000 | I110: =SUM(I3:I109) -> 385000 | J110: =SUM(J3:J109) -> -476908 | K110: =SUM(K3:K109) -> 75051 | ... Y110: =SUM(Y3:Y109) -> 99560 | Z110: =SUM(W110:Y110) -> 1252270

Sheet R7.9
A1: 45930 | C1: 請求 | D1: D | E1: E | F1: F | G1: G | H1: H | I1: I | J1: J | K1: K | L1: L | M1: M | N1: N | O1: O | P1: P | Q1: Q | R1: R | S1: S | T1: T | U1: U | V1: V | W1: W | X1: X | Y1: Y | Z1: Z | AA1: AA | AB1: AB
A2: 居室 | B2: 利用者名 | C2: 分納残 | D2: 家賃 | E2: 管理費 | F2: 共益費 | G2: 水道料金 | H2: 定額光熱費 | I2: 食事 | J2: 調整額 | K2: オムツ | L2: 日用品 | M2: 分割支払い | N2: 事務手数料 | O2: デイサービス | P2: 福祉用具 | Q2: しろくま薬局 | R2: 往診診療費 | S2: サポート費 | T2: その他 | W2: 計 | X2: 一部負担(介護) | Y2: 一部負担(看護) | Z2: 合計 | AA2: 備考 | AB2: 請求書 | AC2: 分割残高
A3: 108 | B3: 杉田誠一 | C3: 185667 | D3: 40000 | E3: 5000 | F3: 5000 | G3: 2000 | H3: 10000 | I3: 42900 | J3: -66847 | K3: 3630 | L3: 2190 | Q3: 8832 | W3: =SUM(D3:V3) -> 52705 | X3: 27295 | Z3: =SUM(W3:Y3) -> 80000 | AA3: 80000 | AB3: 発行済 | AC3: =C3-M3 -> 185667
A4: 206 | B4: 林郁子 | D4: 40000 | E4: 5000 | F4: 5000 | G4: 2000 | H4: 10000 | I4: 42900 | J4: -28337 | K4: 0 | L4: 0 | W4: =SUM(D4:V4) -> 76563 | X4: 20937 | Y4: 2500 | Z4: =SUM(W4:Y4) -> 100000 | AA4: 100000 | AB4: 発行済 | AC4: =C4-M4 -> 0
A5: 210 | W5: =SUM(D5:V5) -> 0 | Z5: =SUM(W5:Y5) -> 0 | AB5: 未作成 | AC5: =C5-M5 -> 0
A6: 211 | W6: =SUM(D6:V6) -> 0 | Z6: =SUM(W6:Y6) -> 0 | AB6: 未作成 | AC6: =C6-M6 -> 0
A7: 212 | B7: 長谷部融子 | D7: 40000 | E7: 5000 | F7: 5000 | G7: 2000 | H7: 10000 | I7: 40700 | K7: 10890 | L7: 2190 | Q7: 10842 | W7: =SUM(D7:V7) -> 126622 | X7: 33906 | Z7: =SUM(W7:Y7) -> 160528 | AA7: 通常請求 | AB7: 発行済 | AC7: =C7-M7 -> 0
A8: 303 | B8: 金澤喜乎 | D8: 40000 | E8: 5000 | F8: 5000 | G8: 2000 | H8: 10000 | I8: 27610 | K8: 4356 | L8: 1314 | W8: =SUM(D8:V8) -> 95280 | X8: 30064 | Y8: 7650 | Z8: =SUM(W8:Y8) -> 132994 | AA8: 12万程度 | AB8: 発行済 | AC8: =C8-M8 -> 0
A9: 401 | W9: =SUM(D9:V9) -> 0 | Z9: =SUM(W9:Y9) -> 0 | AB9: 未作成 | AC9: =C9-M9 -> 0
A10: 402 | B10: 鈴木信子 | D10: 40000 | E10: 5000 | F10: 5000 | G10: 2000 | H10: 10000 | I10: 42900 | J10: -41283 | K10: 16350 | L10: 2190 | Q10: 3712 | W10: =SUM(D10:V10) -> 85869 | X10: 19131 | Z10: =SUM(W10:Y10) -> 105000 | AA10: 105000 | AB10: 発行済 | AC10: =C10-M10 -> 0
A11: 403 | B11: 上村春子 | C11: 140000 | D11: 40000 | E11: 5000 | F11: 5000 | G11: 2000 | H11: 10000 | I11: 13530 | J11: -49230 | K11: 7260 | L11: 1460 | M11: 10000 | Q11: 11568 | W11: =SUM(D11:V11) -> 56588 | X11: 41282 | Y11: 12130 | Z11: =SUM(W11:Y11) -> 110000 | AA11: 10○+初期1万 | AB11: 発行済 | AC11: =C11-M11 -> 130000
A12: 405 | W12: =SUM(D12:V12) -> 0 | Z12: =SUM(W12:Y12) -> 0 | AB12: 未作成 | AC12: =C12-M12 -> 0
A13: 406 | W13: =SUM(D13:V13) -> 0 | Z13: =SUM(W13:Y13) -> 0 | AB13: 未作成 | AC13: =C13-M13 -> 0
A14: 407 | B14: 北村繁弘 | D14: 40000 | E14: 5000 | F14: 5000 | G14: 2000 | H14: 10000 | I14: 38500 | J14: -39217 | K14: 7260 | L14: 2190 | W14: =SUM(D14:V14) -> 70733 | X14: 29267 | Z14: =SUM(W14:Y14) -> 100000 | AA14: 100000 | AB14: 発行済 | AC14: =C14-M14 -> 0
A15: 408 | W15: =SUM(D15:V15) -> 0 | Z15: =SUM(W15:Y15) -> 0 | AB15: 未作成 | AC15: =C15-M15 -> 0
W16: =SUM(D16:V16) -> 0 | Z16: =SUM(W16:Y16) -> 0 | AB16: 未作成 | AC16: =C16-M16 -> 0
A17: 601 | B17: 榎本裕子 | C17: 134000 | D17: 40000 | E17: 5000 | F17: 5000 | G17: 2000 | H17: 10000 | I17: 40150 | J17: -54465 | K17: 7260 | L17: 4350 | Q17: 4132 | W17: =SUM(D17:V17) -> 63427 | X17: 36573 | Z17: =SUM(W17:Y17) -> 100000 | AA17: 100000 | AB17: 発行済 | AC17: =C17-M17 -> 134000
W18: =SUM(D18:V18) -> 0 | Z18: =SUM(W18:Y18) -> 0 | AB18: 未作成 | AC18: =C18-M18 -> 0
A19: 703 | B19: 斧義也 | D19: 40000 | E19: 5000 | F19: 5000 | G19: 2000 | H19: 10000 | I19: 42900 | J19: -66385 | K19: 27240 | L19: 4350 | W19: =SUM(D19:V19) -> 70105 | X19: 24895 | Y19: 5000 | Z19: =SUM(W19:Y19) -> 100000 | AA19: 100000 | AB19: 発行済 | AC19: =C19-M19 -> 0
A20: 715 | B20: 日川敬達 | D20: 40000 | E20: 5000 | F20: 5000 | G20: 2000 | H20: 10000 | I20: 42900 | K20: 0 | L20: 2190 | W20: =SUM(D20:V20) -> 107090 | Z20: =SUM(W20:Y20) -> 107090 | AA20: 116000 | AB20: 発行済 | AC20: =C20-M20 -> 0
A21: 716 | B21: 内田克政 | D21: 40000 | E21: 5000 | F21: 5000 | G21: 2000 | H21: 11778 | I21: 18700 | K21: 0 | L21: 0 | T21: 500 | W21: =SUM(D21:V21) -> 82978 | Z21: =SUM(W21:Y21) -> 82978 | AA21: 通常請求 | AB21: 発行済 | AC21: =C21-M21 -> 0
A22: ='利用者'!A30 | B22: ='利用者'!B30 | W22: =SUM(D22:V22) -> 0 | Z22: =SUM(W22:Y22) -> 0 | AB22: 未作成 | AC22: =C22-M22 -> 0
A23: ='利用者'!A31 | B23: ='利用者'!B31 | W23: =SUM(D23:V23) -> 0 | Z23: =SUM(W23:Y23) -> 0 | AB23: 未作成 | AC23: =C23-M23 -> 0
A24: ='利用者'!A32 | B24: ='利用者'!B32 | W24: =SUM(D24:V24) -> 0 | Z24: =SUM(W24:Y24) -> 0 | AB24: 未作成 | AC24: =C24-M24 -> 0
A25: ='利用者'!A33 | B25: ='利用者'!B33 | W25: =SUM(D25:V25) -> 0 | Z25: =SUM(W25:Y25) -> 0 | AB25: 未作成 | AC25: =C25-M25 -> 0
A26: ='利用者'!A34 | B26: ='利用者'!B34 | W26: =SUM(D26:V26) -> 0 | Z26: =SUM(W26:Y26) -> 0 | AB26: 未作成 | AC26: =C26-M26 -> 0
A27: ='利用者'!A35 | B27: ='利用者'!B35 | W27: =SUM(D27:V27) -> 0 | Z27: =SUM(W27:Y27) -> 0 | AB27: 未作成 | AC27: =C27-M27 -> 0
A28: ='利用者'!A36 | B28: ='利用者'!B36 | W28: =SUM(D28:V28) -> 0 | Z28: =SUM(W28:Y28) -> 0 | AB28: 未作成 | AC28: =C28-M28 -> 0
A29: ='利用者'!A37 | B29: ='利用者'!B37 | W29: =SUM(D29:V29) -> 0 | Z29: =SUM(W29:Y29) -> 0 | AB29: 未作成 | AC29: =C29-M29 -> 0
A30: ='利用者'!A38 | B30: ='利用者'!B38 | W30: =SUM(D30:V30) -> 0 | Z30: =SUM(W30:Y30) -> 0 | AB30: 未作成 | AC30: =C30-M30 -> 0
A31: ='利用者'!A39 | B31: ='利用者'!B39 | W31: =SUM(D31:V31) -> 0 | Z31: =SUM(W31:Y31) -> 0 | AB31: 未作成 | AC31: =C31-M31 -> 0
A32: ='利用者'!A40 | B32: ='利用者'!B40 | W32: =SUM(D32:V32) -> 0 | Z32: =SUM(W32:Y32) -> 0 | AB32: 未作成 | AC32: =C32-M32 -> 0
A33: ='利用者'!A41 | B33: ='利用者'!B41 | W33: =SUM(D33:V33) -> 0 | Z33: =SUM(W33:Y33) -> 0 | AB33: 未作成 | AC33: =C33-M33 -> 0
... A108: ='利用者'!A116 | B108: ='利用者'!B116 | W108: =SUM(D108:V108) -> 0 | Z108: =SUM(W108:Y108) -> 0 | AB108: 未作成 | AC108: =C108-M108 -> 0
W109: =SUM(D109:V109) -> 0 | Z109: =SUM(W109:Y109) -> 0 | AB109: 未作成 | AC109: =C109-M109 -> 0
A110: 合計 | D110: =SUM(D3:D109) -> 440000 | E110: =SUM(E3:E109) -> 55000 | F110: =SUM(F3:F109) -> 55000 | G110: =SUM(G3:G109) -> 22000 | H110: =SUM(H3:H109) -> 111778 | I110: =SUM(I3:I109) -> 393690 | J110: =SUM(J3:J109) -> -345764 | K110: =SUM(K3:K109) -> 84246 | ... Y110: =SUM(Y3:Y109) -> 27280 | Z110: =SUM(W110:Y110) -> 1178590

Sheet R7.8
A1: 45900 | C1: 請求 | D1: D | E1: E | F1: F | G1: G | H1: H | I1: I | J1: J | K1: K | L1: L | M1: M | N1: N | O1: O | P1: P | Q1: Q | R1: R | S1: S | T1: T | U1: U | V1: V | W1: W | X1: X | Y1: Y | Z1: Z | AA1: AA | AB1: AB
A2: 居室 | B2: 利用者名 | C2: 分納残 | D2: 家賃 | E2: 管理費 | F2: 共益費 | G2: 水道料金 | H2: 定額光熱費 | I2: 食事 | J2: 調整額 | K2: オムツ | L2: 日用品 | M2: 分割支払い | N2: 事務手数料 | O2: デイサービス | P2: 福祉用具 | Q2: しろくま薬局 | R2: 往診診療費 | S2: サポート費 | T2: その他 | W2: 計 | X2: 一部負担(介護) | Y2: 一部負担(看護) | Z2: 合計 | AA2: 備考 | AB2: 請求書 | AC2: 分割残高
A3: 108 | B3: 杉田誠一 | C3: 185667 | D3: 40000 | E3: 5000 | F3: 5000 | G3: 2000 | H3: 10000 | I3: 38610 | J3: -68434 | K3: =121*28 -> 3388 | L3: =73*28 -> 2044 | M3: 0 | N3: 0 | O3: 16454 | P3: 0 | Q3: 10202 | R3: 0 | S3: 0 | T3: 0 | W3: =SUM(D3:V3) -> 64264 | X3: 15736 | Y3: 0 | Z3: =SUM(W3:Y3) -> 80000 | AA3: 80000 | AB3: 未作成 | AC3: =C3-M3 -> 185667
A4: 206 | B4: 林郁子 | C4: 0 | D4: 40000 | E4: 5000 | F4: 5000 | G4: 2000 | H4: 10000 | I4: 44330 | J4: -33748 | K4: 0 | L4: 0 | M4: 0 | N4: 0 | O4: 4200 | P4: 0 | Q4: 3452 | R4: 0 | S4: 0 | T4: 0 | W4: =SUM(D4:V4) -> 80234 | X4: 17266 | Y4: 2500 | Z4: =SUM(W4:Y4) -> 100000 | AA4: 100000 | AB4: 未作成 | AC4: =C4-M4 -> 0
A5: 210 | B5: 北村繁弘 | C5: 0 | D5: 40000 | E5: 5000 | F5: 5000 | G5: 2000 | H5: 10000 | I5: 40480 | J5: -48084 | K5: =242*31 -> 7502 | L5: =73*31 -> 2263 | M5: 0 | N5: 0 | O5: 0 | P5: 0 | Q5: 5702 | R5: 0 | S5: 0 | T5: 0 | W5: =SUM(D5:V5) -> 69863 | X5: 30137 | Y5: 0 | Z5: =SUM(W5:Y5) -> 100000 | AA5: 100000 | AB5: 未作成 | AC5: =C5-M5 -> 0
A6: 211 | B6: 鈴木信子 | C6: 0 | D6: 40000 | E6: 5000 | F6: 5000 | G6: 2000 | H6: 10000 | I6: 44330 | J6: -53881 | K6: =545*31 -> 16895 | L6: =73*31 -> 2263 | M6: 0 | N6: 0 | O6: 8346 | P6: 0 | Q6: 4052 | R6: 0 | S6: 0 | T6: 0 | W6: =SUM(D6:V6) -> 84005 | X6: 20995 | Y6: 0 | Z6: =SUM(W6:Y6) -> 105000 | AA6: 105000 | AB6: 未作成 | AC6: =C6-M6 -> 0
A7: 212 | B7: 長谷部融子 | C7: 0 | D7: 40000 | E7: 5000 | F7: 5000 | G7: 2000 | H7: 10000 | I7: 42130 | K7: =363*31 -> 11253 | L7: =73*31 -> 2263 | M7: 0 | N7: 1500 | O7: 6274 | P7: 0 | Q7: 10912 | R7: 0 | S7: 0 | T7: 0 | W7: =SUM(D7:V7) -> 136332 | X7: 34042 | Y7: =31530+32150+26600 -> 90280 | Z7: =SUM(W7:Y7) -> 260654 | AA7: 通常請求 | AB7: 未作成 | AC7: =C7-M7 -> 0
A8: 303 | B8: 金澤喜乎 | C8: 0 | D8: 40000 | E8: 5000 | F8: 5000 | G8: 2000 | H8: 10000 | I8: 44330 | J8: -33179 | K8: =242*31 -> 7502 | L8: =73*31 -> 2263 | M8: 0 | N8: 1500 | O8: 0 | P8: 0 | R8: 0 | S8: 0 | T8: 0 | W8: =SUM(D8:V8) -> 84416 | X8: 29744 | Y8: 5840 | Z8: =SUM(W8:Y8) -> 120000 | AA8: 12万程度 | AB8: 未作成 | AC8: =C8-M8 -> 0
A9: 601 | B9: 榎本裕子 | C9: 144000 | D9: 40000 | E9: 5000 | F9: 5000 | G9: 2000 | H9: 10000 | I9: 42130 | J9: -73372 | K9: =242*31 -> 7502 | L9: =145*31 -> 4495 | M9: 10000 | N9: 0 | O9: 8013 | P9: 0 | Q9: 4232 | R9: 0 | S9: 0 | T9: 0 | W9: =SUM(D9:V9) -> 65000 | X9: 35000 | Y9: 0 | Z9: =SUM(W9:Y9) -> 100000 | AA9: 100000 | AB9: 未作成 | AC9: =C9-M9 -> 134000
D10: 0 | E10: 0 | F10: 0 | G10: 0 | H10: 0 | N10: 0 | O10: 0 | P10: 0 | R10: 0 | S10: 0 | T10: 0 | W10: =SUM(D10:V10) -> 0 | X10: 0 | Y10: 0 | Z10: =SUM(W10:Y10) -> 0 | AB10: 未作成 | AC10: =C10-M10 -> 0
A11: 703 | B11: 斧義也 | C11: 0 | D11: 40000 | E11: 5000 | F11: 5000 | G11: 2000 | H11: 10000 | I11: 44330 | J11: -85367 | K11: =908*31 -> 28148 | L11: =145*31 -> 4495 | M11: 0 | N11: 0 | O11: 14165 | P11: 0 | Q11: 8232 | R11: 0 | S11: 0 | T11: 0 | W11: =SUM(D11:V11) -> 76003 | X11: 23997 | Y11: 0 | Z11: =SUM(W11:Y11) -> 100000 | AA11: 100000 | AB11: 未作成 | AC11: =C11-M11 -> 0
A12: 715 | B12: 日川敬達 | C12: 0 | D12: 40000 | E12: 5000 | F12: 5000 | G12: 2000 | H12: 10000 | I12: 44330 | K12: 0 | L12: =73*31 -> 2263 | M12: 0 | N12: 0 | O12: 0 | P12: 0 | Q12: 50 | R12: 0 | S12: 0 | T12: 0 | W12: =SUM(D12:V12) -> 108643 | X12: 0 | Y12: 0 | Z12: =SUM(W12:Y12) -> 108643 | AA12: 116000 | AB12: 未作成 | AC12: =C12-M12 -> 0
A13: 716 | B13: 内田克政 | C13: 0 | D13: 40000 | E13: 5000 | F13: 5000 | G13: 2000 | H13: 11778 | I13: 15400 | K13: 0 | L13: 0 | M13: 0 | N13: 0 | O13: 0 | P13: 0 | Q13: 0 | R13: 0 | S13: 0 | T13: 500 | W13: =SUM(D13:V13) -> 79678 | X13: 0 | Y13: 0 | Z13: =SUM(W13:Y13) -> 79678 | AA13: 通常請求 | AB13: 未作成 | AC13: =C13-M13 -> 0
W14: =SUM(D14:V14) -> 0 | Z14: =SUM(W14:Y14) -> 0 | AC14: =C14-M14 -> 0
W15: =SUM(D15:V15) -> 0 | Z15: =SUM(W15:Y15) -> 0 | AC15: =C15-M15 -> 0
W16: =SUM(D16:V16) -> 0 | Z16: =SUM(W16:Y16) -> 0 | AC16: =C16-M16 -> 0
W17: =SUM(D17:V17) -> 0 | Z17: =SUM(W17:Y17) -> 0 | AC17: =C17-M17 -> 0
W18: =SUM(D18:V18) -> 0 | Z18: =SUM(W18:Y18) -> 0 | AC18: =C18-M18 -> 0
W19: =SUM(D19:V19) -> 0 | Z19: =SUM(W19:Y19) -> 0 | AC19: =C19-M19 -> 0
W20: =SUM(D20:V20) -> 0 | Z20: =SUM(W20:Y20) -> 0 | AC20: =C20-M20 -> 0
W21: =SUM(D21:V21) -> 0 | Z21: =SUM(W21:Y21) -> 0 | AC21: =C21-M21 -> 0
W22: =SUM(D22:V22) -> 0 | Z22: =SUM(W22:Y22) -> 0 | AC22: =C22-M22 -> 0
W23: =SUM(D23:V23) -> 0 | Z23: =SUM(W23:Y23) -> 0 | AC23: =C23-M23 -> 0
W24: =SUM(D24:V24) -> 0 | Z24: =SUM(W24:Y24) -> 0 | AC24: =C24-M24 -> 0
W25: =SUM(D25:V25) -> 0 | Z25: =SUM(W25:Y25) -> 0 | AC25: =C25-M25 -> 0
... W109: =SUM(D109:V109) -> 0 | Z109: =SUM(W109:Y109) -> 0 | AC109: =C109-M109 -> 0
A110: 合計 | D110: =SUM(D3:D109) -> 400000 | E110: =SUM(E3:E109) -> 50000 | F110: =SUM(F3:F109) -> 50000 | G110: =SUM(G3:G109) -> 20000 | H110: =SUM(H3:H109) -> 101778 | I110: =SUM(I3:I109) -> 400400 | J110: =SUM(J3:J109) -> -396065 | K110: =SUM(K3:K109) -> 82190 | ... Y110: =SUM(Y3:Y109) -> 98620 | Z110: =SUM(W110:Y110) -> 1153975

Sheet R7.7
A1: 45869 | C1: 請求
A2: 居室 | B2: 利用者名 | C2: 分割金額 | D2: 家賃 | E2: 管理費 | F2: 共益費 | G2: 水道料金 | H2: 定額光熱費 | I2: 食事 | J2: オムツ | K2: 日用品 | L2: 福祉用具 | M2: 介護一部負担 | N2: 介護保険料 | O2: 健康保険料 | P2: 分割支払い | Q2: サポート費 | R2: 事務手数料 | S2: 外部利用 | T2: 一部負担 | U2: その他 | V2: 合計 | W2: 備考 | X2: 請求書
A3: 108 | B3: 杉田誠一 | D3: 40000 | E3: 5000 | F3: 5000 | G3: 2000 | H3: 0 | I3: 0 | J3: 0 | K3: 0 | L3: 0 | M3: 0 | N3: 0 | O3: 0 | P3: 0 | Q3: 0 | R3: 0 | S3: 0 | T3: 51387 | U3: -23387 | V3: =SUM(D3:U3) -> 80000 | W3: 80000 | X3: 発行済
A4: 206 | B4: 林郁子 | D4: 40000 | E4: 5000 | F4: 5000 | G4: 2000 | H4: 0 | I4: 31035 | J4: 0 | K4: 0 | L4: 0 | M4: 0 | N4: 0 | O4: 0 | P4: 0 | Q4: 0 | R4: 0 | S4: 0 | T4: 16965 | U4: 0 | V4: =SUM(D4:U4) -> 100000 | W4: 100000 | X4: 発行済
A5: 210 | B5: 北村繁弘 | D5: 40000 | E5: 5000 | F5: 5000 | G5: 2000 | H5: 0 | I5: 17702 | J5: 0 | K5: 0 | L5: 0 | M5: 0 | N5: 0 | O5: 0 | P5: 0 | Q5: 0 | R5: 0 | S5: 0 | T5: 30298 | U5: 0 | V5: =SUM(D5:U5) -> 100000 | W5: 100000 | X5: 発行済
A6: 211 | B6: 鈴木信子 | D6: 40000 | E6: 5000 | F6: 5000 | G6: 2000 | H6: 0 | I6: 35776 | J6: 0 | K6: 0 | L6: 0 | M6: 0 | N6: 0 | O6: 0 | P6: 0 | Q6: 0 | R6: 0 | S6: 0 | T6: 17224 | U6: 0 | V6: =SUM(D6:U6) -> 105000 | W6: 105000 | X6: 発行済
A7: 212 | B7: 長谷部融子 | D7: 40000 | E7: 5000 | F7: 5000 | G7: 2000 | H7: 10000 | I7: 41580 | J7: =363*31 -> 11253 | K7: =73*31 -> 2263 | L7: 0 | M7: 0 | N7: 0 | O7: 0 | P7: 0 | Q7: 0 | R7: 1500 | S7: 18824 | T7: 35285 | V7: =SUM(D7:U7) -> 172705 | W7: 通常請求 | X7: 発行済
A8: 303 | B8: 金澤喜乎 | D8: 40000 | E8: 5000 | F8: 5000 | G8: 2000 | H8: 10000 | I8: 43780 | J8: 0 | K8: 0 | L8: 0 | M8: 0 | N8: 本人支払い | O8: 本人支払い | P8: 0 | Q8: 0 | R8: 1500 | S8: 0 | T8: 29951 | V8: =SUM(D8:U8) -> 137231 | W8: 12万程度 | X8: 発行済
A9: 601 | B9: 榎本裕子 | D9: 40000 | E9: 5000 | F9: 5000 | G9: 2000 | H9: 0 | I9: 3001 | J9: 0 | K9: 0 | L9: 0 | M9: 0 | N9: 0 | O9: 0 | P9: 10000 | Q9: 0 | R9: 0 | S9: 0 | T9: 34999 | U9: 0 | V9: =SUM(D9:U9) -> 100000 | W9: 100000 | X9: 発行済
D10: 0 | E10: 0 | F10: 0 | G10: 0 | H10: 0 | I10: 0 | J10: 0 | K10: 0 | L10: 0 | M10: 0 | N10: 0 | O10: 0 | P10: 0 | Q10: 0 | R10: 0 | S10: 0 | T10: 0 | U10: 0 | V10: =SUM(D10:U10) -> 0 | X10: 未作成
A11: 703 | B11: 斧義也 | D11: 40000 | E11: 5000 | F11: 5000 | G11: 2000 | H11: 0 | I11: 24247 | J11: 0 | K11: 0 | L11: 0 | M11: 0 | N11: 0 | O11: 0 | P11: 0 | Q11: 0 | R11: 0 | S11: 0 | T11: 23753 | U11: 0 | V11: =SUM(D11:U11) -> 100000 | W11: 100000 | X11: 発行済
A12: 715 | B12: 日川敬達 | D12: 40000 | E12: 5000 | F12: 5000 | G12: 2000 | H12: 10000 | I12: 44330 | J12: 0 | K12: 0 | L12: 0 | M12: 0 | N12: 0 | O12: 0 | P12: 0 | Q12: 9670 | R12: 0 | S12: 0 | T12: 0 | U12: 0 | V12: =SUM(D12:U12) -> 116000 | W12: 116000 | X12: 発行済
A13: 716 | B13: 内田克政 | D13: 40000 | E13: 5000 | F13: 5000 | G13: 2000 | H13: 0 | I13: 0 | J13: 0 | K13: 0 | L13: 0 | M13: 0 | N13: 0 | O13: 0 | P13: 0 | Q13: 0 | R13: 0 | S13: 0 | T13: 0 | U13: 500 | V13: =SUM(D13:U13) -> 52500 | W13: 通常請求 | X13: 発行済
A14: 合計 | D14: =SUM(D3:D13) -> 400000 | E14: =SUM(E3:E13) -> 50000 | F14: =SUM(F3:F13) -> 50000 | G14: =SUM(G3:G13) -> 20000 | H14: =SUM(H3:H13) -> 30000 | I14: =SUM(I3:I13) -> 241451 | J14: =SUM(J3:J13) -> 11253 | K14: =SUM(K3:K13) -> 2263 | ... U14: =SUM(U3:U13) -> -22887 | V14: =SUM(D14:U14) -> 1063436

Sheet R7.6
A1: 45838 | C1: 請求
A2: 居室 | B2: 利用者名 | C2: 未納金額 | D2: 家賃 | E2: 管理費 | F2: 共益費 | G2: 水道料金 | H2: 定額光熱費 | I2: 食事 | J2: オムツ | K2: 日用品 | L2: 福祉用具 | M2: 介護一部負担 | N2: 介護保険料 | O2: 健康保険料 | P2: 分割支払い | Q2: サポート費 | R2: 事務手数料 | S2: 外部利用 | T2: その他 | U2: 合計 | V2: 備考 | W2: 入金額 | X2: 入金日 | Y2: 差引額
A3: 108 | B3: 杉田誠一 | D3: 40000 | E3: 5000 | F3: 5000 | G3: 2000 | H3: 0 | I3: 28000 | J3: 0 | K3: 0 | L3: 0 | M3: 0 | N3: 0 | O3: 0 | P3: 0 | Q3: 0 | R3: 0 | S3: 0 | T3: 0 | U3: =SUM(D3:T3) -> 80000 | V3: 80000
A4: 206 | B4: 林郁子 | D4: 40000 | E4: 5000 | F4: 5000 | G4: 2000 | H4: 0 | I4: 40150 | J4: 0 | K4: 0 | L4: 0 | M4: 0 | N4: 0 | O4: 0 | P4: 0 | Q4: 7850 | R4: 0 | S4: 0 | T4: 0 | U4: =SUM(D4:T4) -> 100000 | V4: 100000
A5: 210 | B5: 北村繁弘 | D5: 40000 | E5: 5000 | F5: 5000 | G5: 2000 | H5: 0 | I5: 42900 | J5: 0 | K5: 0 | L5: 0 | M5: 0 | N5: 0 | O5: 0 | P5: 0 | Q5: 5100 | R5: 0 | S5: 0 | T5: 0 | U5: =SUM(D5:T5) -> 100000 | V5: 100000
A6: 211 | B6: 鈴木信子 | D6: 40000 | E6: 5000 | F6: 5000 | G6: 2000 | H6: 0 | I6: 42900 | J6: 0 | K6: 0 | L6: 0 | M6: 0 | N6: 0 | O6: 0 | P6: 0 | Q6: =105000-94900 -> 10100 | R6: 0 | S6: 0 | T6: 0 | U6: =SUM(D6:T6) -> 105000 | V6: 105000
A7: 212 | B7: 長谷部融子 | D7: 40000 | E7: 5000 | F7: 5000 | G7: 2000 | H7: 10000 | I7: 40700 | J7: =363*30 -> 10890 | K7: =73*30 -> 2190 | L7: 0 | M7: 0 | N7: 0 | O7: 0 | P7: 0 | Q7: 0 | R7: 1500 | S7: 0 | U7: =SUM(D7:T7) -> 117280 | V7: 通常請求
A8: 303 | B8: 金澤喜乎 | D8: 40000 | E8: 5000 | F8: 5000 | G8: 2000 | H8: 10000 | I8: 42900 | J8: =242*30 -> 7260 | K8: =73*30 -> 2190 | L8: 0 | M8: 0 | N8: 本人支払い | O8: 本人支払い | P8: 0 | Q8: 0 | R8: 1500 | U8: =SUM(D8:T8) -> 115850 | V8: 100000
A9: 403 | B9: 榎本裕子 | D9: 40000 | E9: 5000 | F9: 5000 | G9: 2000 | H9: 0 | I9: 38000 | J9: 0 | K9: 0 | L9: 0 | M9: 0 | N9: 0 | O9: 0 | P9: 10000 | Q9: 0 | R9: 0 | S9: 0 | T9: 0 | U9: =SUM(D9:T9) -> 100000 | V9: 100000
D10: 0 | E10: 0 | F10: 0 | G10: 0 | H10: 0 | I10: 0 | J10: 0 | K10: 0 | L10: 0 | M10: 0 | N10: 0 | O10: 0 | P10: 0 | Q10: 0 | R10: 0 | U10: =SUM(D10:T10) -> 0
A11: 703 | B11: 斧義也 | D11: 40000 | E11: 5000 | F11: 5000 | G11: 2000 | H11: 0 | I11: 42900 | J11: 0 | K11: 0 | L11: 0 | M11: 0 | N11: 0 | O11: 0 | P11: 0 | Q11: 5100 | R11: 0 | S11: 0 | T11: 0 | U11: =SUM(D11:T11) -> 100000 | V11: 100000
A12: 715 | B12: 日川敬達 | D12: 40000 | E12: 5000 | F12: 5000 | G12: 2000 | H12: 10000 | I12: 42900 | J12: 0 | K12: 0 | L12: 0 | M12: 0 | N12: 0 | O12: 0 | P12: 0 | Q12: 11100 | R12: 0 | S12: 0 | T12: 0 | U12: =SUM(D12:T12) -> 116000 | V12: 116000
A13: 716 | B13: 内田克政 | D13: 40000 | E13: 5000 | F13: 5000 | G13: 2000 | H13: 0 | I13: 0 | J13: 0 | K13: 0 | L13: 0 | M13: 0 | N13: 0 | O13: 0 | P13: 0 | Q13: 0 | R13: 0 | S13: 0 | T13: 500 | U13: =SUM(D13:T13) -> 52500 | V13: 通常請求
D14: 0 | E14: 0 | F14: 0 | G14: 0 | H14: 0 | I14: 0 | J14: 0 | K14: 0 | L14: 0 | M14: 0 | N14: 0 | O14: 0 | P14: 0 | Q14: 0 | R14: 0 | S14: 0 | U14: =SUM(D14:T14) -> 0
D15: 0 | E15: 0 | F15: 0 | G15: 0 | H15: 0 | I15: 0 | J15: 0 | K15: 0 | L15: 0 | M15: 0 | N15: 0 | O15: 0 | P15: 0 | Q15: 0 | R15: 0 | S15: 0 | U15: =SUM(D15:T15) -> 0
A16: 2A | D16: 0 | E16: 0 | F16: 0 | G16: 0 | H16: 0 | I16: 0 | J16: 0 | K16: 0 | L16: 0 | M16: 0 | N16: 0 | O16: 0 | P16: 0 | Q16: 0 | R16: 0 | S16: 0 | U16: =SUM(D16:T16) -> 0
A17: 2B | B17: 笠岡康志 | D17: 40000 | E17: 5000 | F17: 5000 | G17: 2000 | H17: 10000 | I17: 16500 | J17: 0 | K17: 0 | L17: 0 | M17: 0 | N17: 0 | O17: 0 | P17: 6250 | Q17: 0 | R17: 0 | U17: =SUM(D17:T17) -> 84750 | V17: 通常請求
A18: 2E | B18: 藤本敏博 | D18: 40000 | E18: 5000 | F18: 5000 | G18: 2000 | H18: 0 | I18: 33550 | J18: 0 | K18: 0 | L18: 0 | M18: 0 | N18: 0 | O18: 0 | P18: 10000 | Q18: 14450 | S18: 0 | U18: =SUM(D18:T18) -> 110000 | V18: 110000
A19: 5B | B19: 中込和人 | D19: 40000 | E19: 5000 | F19: 5000 | G19: 2000 | H19: 10000 | I19: 0 | J19: 0 | K19: =73*30 -> 2190 | L19: 0 | M19: 0 | N19: 0 | O19: 0 | P19: 0 | Q19: 0 | R19: 1500 | S19: 0 | U19: =SUM(D19:T19) -> 65690 | V19: 通常請求
A20: 5C | B20: 上田清江 | D20: 40000 | E20: 5000 | F20: 5000 | G20: 2000 | H20: 0 | I20: 40700 | J20: 0 | K20: 0 | L20: 0 | M20: 0 | N20: 0 | O20: 0 | P20: 10000 | Q20: 7300 | R20: 0 | S20: 0 | U20: =SUM(D20:T20) -> 110000 | V20: 110000
A21: 6A | D21: 0 | E21: 0 | F21: 0 | G21: 0 | H21: 0 | I21: 0 | J21: 0 | K21: 0 | L21: 0 | M21: 0 | N21: 0 | O21: 0 | P21: 0 | Q21: 0 | R21: 0 | S21: 0 | U21: =SUM(D21:T21) -> 0
A22: 6B | B22: 小山美由紀 | D22: 40000 | E22: 5000 | F22: 5000 | G22: 2000 | H22: 0 | I22: 16500 | J22: 0 | K22: 0 | L22: 0 | M22: 0 | N22: 0 | O22: 0 | P22: 0 | Q22: 19670 | R22: 0 | S22: 0 | U22: =SUM(D22:T22) -> 88170 | V22: 通常請求
A23: 6C | B23: 宮本浩行 | D23: 40000 | E23: 5000 | F23: 5000 | G23: 2000 | H23: 0 | I23: 42900 | J23: 0 | K23: 0 | L23: 0 | M23: 0 | N23: 0 | O23: 0 | P23: 20000 | Q23: 0 | R23: 0 | S23: 0 | U23: =SUM(D23:T23) -> 114900 | V23: 通常請求
A24: 6D | D24: 0 | E24: 0 | F24: 0 | G24: 0 | H24: 0 | I24: 0 | J24: 0 | K24: 0 | L24: 0 | M24: 0 | N24: 0 | O24: 0 | P24: 0 | Q24: 0 | R24: 0 | S24: 0 | U24: =SUM(D24:T24) -> 0
A25: 6E | B25: 岡村三男 | D25: 40000 | E25: 5000 | F25: 5000 | G25: 2000 | H25: 10000 | I25: 0 | J25: =242*22 -> 5324 | K25: 0 | L25: 0 | M25: 0 | N25: 本人支払い | O25: 本人支払い | P25: 0 | Q25: 0 | R25: 1500 | S25: 0 | T25: 14000 | U25: =SUM(D25:T25) -> 82824 | V25: 通常請求
D26: 0 | E26: 0 | F26: 0 | G26: 0 | H26: 0 | I26: 0 | J26: 0 | K26: 0 | L26: 0 | M26: 0 | N26: 0 | O26: 0 | P26: 0 | Q26: 0 | R26: 0 | S26: 0 | U26: =SUM(D26:T26) -> 0
A27: 合計 | D27: =SUM(D3:D26) -> 680000 | E27: =SUM(E3:E26) -> 85000 | F27: =SUM(F3:F26) -> 85000 | G27: =SUM(G3:G26) -> 34000 | H27: =SUM(H3:H26) -> 60000 | I27: =SUM(I3:I26) -> 511500 | J27: =SUM(J3:J26) -> 23474 | K27: =SUM(K3:K26) -> 6570 | ... T27: =SUM(T3:T26) -> 14500 | U27: =SUM(D27:T27) -> 1642964

Sheet R7.5
A1: 45808 | C1: 請求
A2: 居室 | B2: 利用者名 | C2: 未納金額 | D2: 家賃 | E2: 管理費 | F2: 共益費 | G2: 水道料金 | H2: 定額光熱費 | I2: 食事 | J2: オムツ | K2: 日用品 | L2: 福祉用具 | M2: 介護一部負担 | N2: 介護保険料 | O2: 健康保険料 | P2: 分割支払い | Q2: サポート費 | R2: 事務手数料 | S2: 外部利用 | T2: その他 | U2: 合計 | V2: 備考 | W2: 国保連 月請求分
A3: 108 | B3: 杉田誠一 | D3: 40000 | E3: 5000 | F3: 5000 | G3: 2000 | H3: 0 | I3: 28000 | J3: 0 | K3: 0 | L3: 0 | M3: 0 | N3: 0 | O3: 0 | P3: 0 | Q3: 0 | R3: 0 | S3: 0 | U3: =SUM(D3:T3) -> 80000 | V3: 80000
A4: 206 | B4: 林郁子 | D4: 40000 | E4: 5000 | F4: 5000 | G4: 2000 | H4: 0 | I4: 41580 | J4: 0 | K4: 0 | L4: 0 | M4: 0 | N4: 0 | O4: 0 | P4: 0 | Q4: 6420 | R4: 0 | S4: 0 | U4: =SUM(D4:T4) -> 100000 | V4: 100000
A5: 210 | B5: 北村繁弘 | D5: 40000 | E5: 5000 | F5: 5000 | G5: 2000 | H5: 0 | I5: 44330 | J5: 0 | K5: 0 | L5: 0 | M5: 0 | N5: 0 | O5: 0 | P5: 0 | Q5: 3670 | R5: 0 | S5: 0 | U5: =SUM(D5:T5) -> 100000 | V5: 100000
A6: 211 | B6: 鈴木信子 | D6: 40000 | E6: 5000 | F6: 5000 | G6: 2000 | H6: 0 | I6: 44330 | J6: 0 | K6: 0 | L6: 0 | M6: 0 | N6: 0 | O6: 0 | P6: 0 | Q6: 8670 | R6: 0 | S6: 0 | U6: =SUM(D6:T6) -> 105000 | V6: 105000
A7: 212 | B7: 長谷部融子 | D7: 40000 | E7: 5000 | F7: 5000 | G7: 2000 | H7: 10000 | I7: 42130 | J7: 11253 | K7: 2263 | L7: 0 | M7: 0 | N7: 0 | O7: 0 | P7: 0 | Q7: 0 | R7: 1500 | S7: 0 | U7: =SUM(D7:T7) -> 119146 | V7: 通常請求
A8: 303 | B8: 金澤喜乎 | D8: 40000 | E8: 5000 | F8: 5000 | G8: 2000 | H8: 10000 | I8: 43450 | J8: 7502 | K8: 2263 | L8: 0 | M8: 0 | N8: 本人支払い | O8: 本人支払い | P8: 0 | Q8: 0 | R8: 1500 | U8: =SUM(D8:T8) -> 116715 | V8: 100000
A9: 403 | B9: 榎本裕子 | D9: 40000 | E9: 5000 | F9: 5000 | G9: 2000 | H9: 0 | I9: 38000 | J9: 0 | K9: 0 | L9: 0 | M9: 0 | N9: 0 | O9: 0 | P9: 10000 | R9: 0 | S9: 0 | U9: =SUM(D9:T9) -> 100000 | V9: 100000
D10: 0 | E10: 0 | F10: 0 | G10: 0 | H10: 0 | I10: 0 | J10: 0 | K10: 0 | L10: 0 | M10: 0 | N10: 0 | O10: 0 | P10: 0 | Q10: 0 | R10: 0 | U10: =SUM(D10:T10) -> 0
A11: 703 | B11: 斧義也 | D11: 40000 | E11: 5000 | F11: 5000 | G11: 2000 | H11: 0 | I11: 44330 | J11: 0 | K11: 0 | L11: 0 | M11: 0 | N11: 0 | O11: 0 | P11: 0 | Q11: 3670 | R11: 0 | S11: 0 | U11: =SUM(D11:T11) -> 100000 | V11: 100000
A12: 715 | B12: 日川敬達 | D12: 40000 | E12: 5000 | F12: 5000 | G12: 2000 | H12: 10000 | I12: 44330 | J12: 0 | K12: 0 | L12: 0 | M12: 0 | N12: 0 | O12: 0 | P12: 0 | Q12: 9670 | R12: 0 | S12: 0 | U12: =SUM(D12:T12) -> 116000 | V12: 116000
A13: 716 | B13: 内田克政 | D13: 40000 | E13: 5000 | F13: 5000 | G13: 2000 | H13: 0 | I13: 12100 | J13: 0 | K13: 0 | L13: 0 | M13: 0 | N13: 0 | O13: 0 | P13: 0 | Q13: 0 | R13: 0 | S13: 0 | T13: 500 | U13: =SUM(D13:T13) -> 64600 | V13: 通常請求
D14: 0 | E14: 0 | F14: 0 | G14: 0 | H14: 0 | I14: 0 | J14: 0 | K14: 0 | L14: 0 | M14: 0 | N14: 0 | O14: 0 | P14: 0 | Q14: 0 | R14: 0 | S14: 0 | U14: =SUM(D14:T14) -> 0
D15: 0 | E15: 0 | F15: 0 | G15: 0 | H15: 0 | I15: 0 | J15: 0 | K15: 0 | L15: 0 | M15: 0 | N15: 0 | O15: 0 | P15: 0 | Q15: 0 | R15: 0 | S15: 0 | U15: =SUM(D15:T15) -> 0
A16: 2A | D16: 0 | E16: 0 | F16: 0 | G16: 0 | H16: 0 | I16: 0 | J16: 0 | K16: 0 | L16: 0 | M16: 0 | N16: 0 | O16: 0 | P16: 0 | Q16: 0 | R16: 0 | S16: 0 | U16: =SUM(D16:T16) -> 0
